Workbook
Name data_dude: Database!$J$53:$J$62
Name data_dudr: Database!$N$53:$N$62
Name data_dudrc: Database!$L$53:$L$62
Name data_duds: Database!$M$53:$M$62
Name data_dudv: Database!$K$53:$K$62
Name data_dur: Database!$I$53:$I$62
Name data_ffiff: Database!$B$53:$B$62
Name data_ffiffft: Database!$C$53:$C$62
Name data_maxipr: Database!$E$53:$E$62
Name data_maxipu: Database!$F$53:$F$62
Name data_maxsir: Database!$G$53:$G$62
Name data_maxsiu: Database!$H$53:$H$62
Name data_piada: Database!$E$23:$E$24
Name data_pigen: Database!$E$19:$E$20
Name data_prjtyp: Database!$E$7:$E$9
Name data_ptsdrp: Database!$F$67:$F$70
Name data_ptslkpnts: Database!$F$90:$F$118
Name data_ptslkpr: Database!$E$90:$E$118
Name data_ptslkpt: Database!$B$90:$B$118
Name data_ptspr: Database!$B$67:$B$70
Name data_toilet: Database!$F$35:$F$38
Name data_unitan: Database!$I$12:$I$13
Name data_unitfhr: Database!$G$12:$G$13
Name data_unitfwr: Database!$H$12:$H$13
Name data_unittyp: Database!$E$12:$E$13
Name data_unitvol: Database!$F$12:$F$13
Name data_urinal: Database!$H$35:$H$37
Name inputsflow_dfr: 'Inputs Fixture Fittings'!$J$261:$J$374
Name inputsflow_dur: 'Inputs Fixture Fittings'!$H$261:$H$374
Name inputsflow_gn: 'Inputs Fixture Fittings'!$B$261:$B$374
Name inputsflow_id: 'Inputs Fixture Fittings'!$D$261:$D$374
Name inputsflow_no: 'Inputs Fixture Fittings'!$A$261:$A$374
Name inputsflow_paw: 'Inputs Fixture Fittings'!$K$261:$K$374
Name inputsflow_prcocc: 'Inputs Fixture Fittings'!$L$261:$L$374
Name inputsflow_tduot: 'Inputs Fixture Fittings'!$T$261:$T$374
Name inputsflow_typ: 'Inputs Fixture Fittings'!$E$261:$E$374
Name inputsflow_updot: 'Inputs Fixture Fittings'!$R$261:$R$374
Name inputsflush_dfr: 'Inputs Fixture Fittings'!$J$138:$J$251
Name inputsflush_fam: 'Inputs Fixture Fittings'!$E$138:$E$251
Name inputsflush_gn: 'Inputs Fixture Fittings'!$B$138:$B$251
Name inputsflush_id: 'Inputs Fixture Fittings'!$D$138:$D$251
Name inputsflush_no: 'Inputs Fixture Fittings'!$A$138:$A$251
Name inputsflush_paw: 'Inputs Fixture Fittings'!$K$138:$K$251
Name inputsflush_prcocc: 'Inputs Fixture Fittings'!$L$138:$L$251
Name inputsflush_tduot: 'Inputs Fixture Fittings'!$T$138:$T$251
Name inputsflush_typ: 'Inputs Fixture Fittings'!$G$138:$G$251
Name inputsflush_updot: 'Inputs Fixture Fittings'!$R$138:$R$251
Name inputsgrp_ada: 'Inputs Fixture Fittings'!$G$16:$G$129
Name inputsgrp_an: 'Inputs Fixture Fittings'!$I$16:$I$129
Name inputsgrp_def: 'Inputs Fixture Fittings'!$D$16:$D$129
Name inputsgrp_deff: 'Inputs Fixture Fittings'!$F$16:$F$129
Name inputsgrp_defm: 'Inputs Fixture Fittings'!$E$16:$E$129
Name inputsgrp_gn: 'Inputs Fixture Fittings'!$B$16:$B$129
Name inputsgrp_no: 'Inputs Fixture Fittings'!$A$16:$A$129
Name inputsgrp_otefte: 'Inputs Fixture Fittings'!$J$16:$J$129
Name inputsgrp_otot: 'Inputs Fixture Fittings'!$O$16:$O$129
Name inputsgrp_otrc: 'Inputs Fixture Fittings'!$L$16:$L$129
Name inputsgrp_otres: 'Inputs Fixture Fittings'!$N$16:$N$129
Name inputsgrp_otstud: 'Inputs Fixture Fittings'!$M$16:$M$129
Name inputsgrp_otv: 'Inputs Fixture Fittings'!$K$16:$K$129

Sheet Revision History
A1: Draft Calculator Revision History | H1: TASKS
A3: Date | B3: Party | C3: Tab Edited | D3: Field Edited | E3: Description | F3: Related TASK No. | H3: No. | I3: Date Complete | J3: Tab Edited | K3: Source File
A4: 45881 | B4: WSP | C4: ALL | D4: ALL | E4: Templatized | F4: NA | H4: 1 | J4: Make sure to create named fields (Formulas > Name Manager) and use formulas using named field values (note be sure to delete unused names from the template document)
A5: 45911 | B5: WSP | C5: ALL | D5: ALL | E5: Draft completed | F5: NA | H5: 2 | J5: Make sure all credit calculation requirements are included
H6: 3 | J6: Make sure formulas work, values correct, validation included where needed (i.e. positive numbers only, etc.)
H7: 4 | J7: Make sure labels are correct (including make explicit where inputs are required or optional)
H8: 5 | J8: QC Cell Formatting (see internal style guide)
H9: 6 | J9: Add Notes where needed
H10: 7 | J10: Add summary "Point calculation" tab
H11: 8 | J11: Update instructions tab
H12: 9 | J12: Add flags as needed (i.e. for CFCs, IDC BDC >700 GWP)
H13: 10 | J13: Allow Add rows without macros, include instructions (NOTE prior calculator drafts have used Groups, welcome other recommendations)
H14: 11 | J14: Update formatting per USGBC (including If required create named fields; If guidance says use tables, convert to tables)
H15: 12 | J15: Spell Check
H16: 13 | J16: Final Lock Settings and QC

Sheet Internal Style Guide
B2: Internal Style Guide
B4: TEMP LOCK PASSWORD | E4: LEEDv5
B5: Workbook Structure | E5: Inputs Tab: User input AND final summary values only, can have some automatic input cells IF important for user data, can have multiple inputs tabs if needed
E6: Logic Tab: Calculations for values needed for LEED Performance, no user input, will be hidden from users
E7: Database Tab: Constants, values for logic calculations, points, limit to static values no formulas where possible, will be hidden from users
E8: Summary Tab: Points, values needed for LEED performance (see Reference Guide Documentation requirements for what needs to be included)
E9: Note calculators must use Formula > Name Manager to name fields and cells that are used for calculations or pulled into other cells. Recommend developing full calculator structure and initial formulas before naming fields and updating formulas.
B10: General Sheet Formating | E10: Turn-off view gridlines
E11: Columns to left and right of boarder to be Width of 3.5 (42 pxl)
E12: Rows above and below boarder to be Height of 20 (34 pxl)
B13: Sheet Background Fill | E13: #F7F8F6; fill up to row 300, 600, or 900 as needed; fill up to column Z
B14: Instructions + Summary Background Fill | E14: #FFFFFF
B15: Title Fill | E15: IP | F15: #952713
E16: LT | F16: #B87400
E17: SS | F17: #536426
E18: WE | F18: #006570
E19: EA | F19: #C75127
E20: MR | F20: #7C4901
E21: EQ | F21: #684659
E22: PR | F22: #7E8AA2
B23: Title Format | E23: Use downloadable PNG logo w and maintain aspect ratio in all cases. Logo must never be more than 1 inch (72 pixels) wide.
E24: Suggest standard header height of 90.0 (150 pxl) with an increase to 95.0 (160 pxl) prerequisite and credit combo.
E25: Note naming convention (see below for example):
F26: USGBC Calculator || LEED for Building Operations and Maintenance [14 point font, bold] LEED v5 EAp4: Fundamental Refigerant Management [12 point font, bold] LEED v5 EAc3: Enhanced Refrigerant Management Performance [12 point font, bold] SHEET NAME (I.E. INPUTS, LOGIC, DATABASE, SUMMARY) [12 point font, bold]
B27: Cell Outline | E27: Automatic, Default Weight
B28: Standard Row Width | E28: 18.0 (30 pxls)
B29: Text Alignment | D29: Subheadings | E29: Center justified, Vertical Center
D30: Text | E30: Left justified, Vertical Center
D31: Numbers | E31: Right justified, Vertical Center
B32: Number Formatting | D32: 1000 | E32: CONFIRM WHICH DATA USES THIS FORMAT
D33: 1.1 | E33: CONFIRM WHICH DATA USES THIS FORMAT
D34: 0.011 | E34: CONFIRM WHICH DATA USES THIS FORMAT
B35: Font | D35: Headings | E35: Arial 11 Bold UPPERCASE
D36: Subheading | E36: Arial 10 Bold
D37: Text | E37: Arial 10
E38: HEADING | F38: FILL HEX #353434, TEXT HEX # F7F8F6
E39: Subheading | F39: FILL FOR SUBHEADING CELLS HEX #B6B7B8 CENTER ALL HEADERS
E40: Manual input | F40: FILL FOR USER INPUT CELLS HEX #000000
E41: Auto input | F41: FILL FOR AUTOMATIC CELLS HEX #F2F2F2
E42: Calculation | F42: FILL FOR AUTOMATIC CELLS HEX #D9D9D9 Database and logic only
...

Sheet Instructions
B2: LEED v5 Fixture and Fittings Water Use Calculator LEED for Building Design and Construction | Interior Design and Construction Instructions
C5: CREDIT INSTRUCTIONS
D7: LEED v5 BD+C WEp2 | ID+C WEp1: Minimum Water Efficiency | Minimum Fixture and Fittings Option 2 Performance Path LEED v5 BD+C WEc2 | ID+C WEc2: Enhanced Water Efficiency | Option 2 Fixtures and Fittings
D8: ▪ | E8: This calculator serves as a Baseline and Design Water Consumption for Fixtures and Fittings model for compliance with WEp2: Minimum Water Efficiency, Option 2. Performance Path – Calculated Reduction and WEc2: Enhanced Water Efficiency, Option 2. Fixtures and Fittings – Calculated Reduction.
D9: ▪ | E9: Teams pursuing points under WEc2: Enhanced Water Efficiency should consider Option 2. Performance Path – Calculated Reduction to show prerequisite compliance. Using the performance-based approach, teams can maximize water conservation across all applicable fixtures and fittings within the project boundary.
D10: ▪ | E10: Teams must determine the project’s baseline water consumption. The baseline flush and flow rates must use values from the LEED Reference Guide, representing the maximum allowed flush and flow rates.
D11: ▪ | E11: The design case must use designed values that represent the fixtures and fittings installed in the project. For projects that have dual flush toilets, use the full-flush volume in the design case calculations. Do not use the weighted average.
D12: ▪ | E12: The total number of uses for each fixture and fitting remains the same in the baseline and design case calculations.
D13: ▪ | E13: Total annual consumption depends on project-specific data, including fitting and fixture types, flush and flow rates, the number of full-time equivalents and visitors, annual days of operation, and gender ratios. This data must remain consistent across all LEED BD+C: New Construction and LEED BD+C: Core and Shell credits to maintain the integrity of the submission.
D14: ▪ | E14: Teams must prove a reduction of 20% from the baseline water use for the fixtures and fittings located within the LEED project boundary to meet the minimum prerequisite requirements.
D15: ▪ | E15: For WEc2 credit calculations, projects must include the fixtures and fittings necessary to meet the occupants’ needs, whether they will be installed as part of the project’s scope of work or not. Include at a minimum all necessary restroom fixtures (toilets, urinals, and lavatories) to meet the project occupants’ needs, and showers when seeking LT Credit Transportation Demand Management. Upload a separate calculator for the credit, as applicable.
D16: ▪ | E16: Teams should always prioritize water efficiency first in the prerequisite to reduce consumption and demand before applying alternative water solutions in the credit. For any seasonally dependent sources, such as rainwater, calculations must reflect annual, seasonal totals to confirm the available quantity of the alternative water source.
E17: ▪ | F17: If the alternative water is used for multiple applications in the project – for example, flush fixtures, irrigation, and/or process water – or is shared by multiple buildings, teams must provide supply and demand calculations to confirm the available quantity of alternative water and demonstrate that a sufficient quantity is available to meet the demands of all uses. Monthly supply and demand calculations are typically provided for seasonally dependent sources of alternative water, such as harvested rainwater, and for projects with seasonal occupancy variations, such as schools.
E18: ▪ | F18: Alternative water sources include on-site reclaimed water, off-site supplied reclaimed wastewater, graywater, rainwater, stormwater, treated seawater, condensate, nuisance water, treated blowdown from process water, reject water from reverse osmosis, and other recycled water sources.
E19: ▪ | F19: Potable water sources include municipally supplied potable water, well water, groundwater, and water from naturally occurring surface bodies of water (such as streams, lakes, or rivers), even if not treated to potable drinking water standards.
C22: INPUT INSTRUCTIONS
E24: User input cell formatting.
E25: Automatic input cell formatting.
E26: Calculation cell formatting.
C28: All input cells are required unless otherwise noted.
C30: 1 | D30: Input general information for the project, including project type and units.
C32: 2 | D32: Input Group names, types, and functions.
D33: ▪ | E33: Fill in values from the top of the list. Do not leave blank rows above filled rows.
D34: ▪ | E34: Projects with extremely complex occupancy and/or fixture usage patterns (such as where different types of occupants have different annual days of operation and use fixtures with differing flush and flow rates within the building) may create a separate Group to represent the usage for complex scenarios.
E35: Required fields for each category:
E36: ▪ | F36: Group Name. Used to define group and allow for separate user groups when identifying fixture and fittings design. If there is only one occupancy group, only one Group Name needs to be input.
E37: ▪ | F37: Gender Mix | Default/Non-default. Default: Select if the default gender mix is half male and half female. Non-Default: Select if the project is specifically designed for an alternative gender ratio or the project is expected to have alternative gender usage rates for the life of the building.
E38: ▪ | F38: Gender Mix | Non-default Male. Only required if Non-default selected above. Must be a positive percentage.
E39: ▪ | F39: Gender Mix | Non-default Female. Only required if Non-default selected above. Must be a positive percentage.
E40: ▪ | F40: Contains ADA / Gender-Neutral Restrooms. If the project includes separate gender neutral and/or ADA restrooms without urinals, the LEED default assumption is that 5% of male occupants and 5% of female occupants use these restrooms. Enter 95% into the percent of males expected to use restrooms with urinals below. Alternately, the project team can estimate this percentage based on the project's restroom layout/anticipated usage patterns or weighted fixture counts.
E41: ▪ | F41: Percent of Males Expected to Use Restrooms with Urinals. To determine the percent of males expected to use restrooms with urinals, check the project floor plans to determine whether urinals are present in all male restrooms and in all gender-neutral/ADA restrooms. Enter 100% if all male and gender-neutral/ADA restrooms have urinals. Enter 0% if the project contains no urinals. If the project includes separate all-gender/ADA restrooms without urinals, enter the default value of 95%, or a project-specific estimate based on the project's restroom layout and anticipated usage patterns or weighted fixture counts.
E42: ▪ | F42: Annual Days of Operation. Enter the number of days of operation for each group. Must be consistent with the building’s operating schedule and occupancy patterns. Must be a positive whole number.
F43: ▪ K–12 schools that close on weekends, holidays, and for eight weeks of school vacation, may assume 195 days of operation.
E44: ▪ | F44: Occupancy Type. Include the daily average number of building occupants by type for each group. Values are only needed if project includes the occupancy type. Note at least one occupancy type must be included. Values must be a positive whole number. Fill in for the following occupancy types.
F45: ▪ Employees (FTE)
F46: ▪ Visitors
F47: ▪ Retail Customers
F48: ▪ Students (K-12)
F49: ▪ Residential
F50: Note: Residential occupants include dormitory, apartment, condo residents, overnight hotel guests, medical inpatients, prisoners, and any other people who use the building for sleeping accommodations.
...

Sheet Inputs Fixture Fittings
B2: LEED v5 Fixture and Fittings Water Use Calculator LEED for Building Design and Construction | Interior Design and Construction Inputs Fixture and Fittings
B4: STEP 1: GENERAL INFORMATION
B6: Project Type
B8: Unit of Measurement
B11: STEP 2: GROUP NAMES AND TYPES
B13: Click + to the left to add additional rows. Click - to the left to collapse (content will be saved).
B14: Group Name | D14: Gender Mix | G14: Contains ADA / Gender-Neutral Restrooms | H14: Percent of Males Expected to Use Restrooms with Urinals | I14: Annual Days of Operation | J14: Occupancy Type
D15: Default or Non-Default | E15: Non-Default Male | F15: Non-Default Female | J15: Employees (FTE) | K15: Vistors | L15: Retail Customers | M15: Students (K-12) | N15: Residential | O15: Other (Specify)
A16: 1
A17: 2
A18: 3
A19: 4
A20: 5
A21: 6
A22: 7
A23: 8
A24: 9
A25: 10 | P25: Click + to left for additional rows
A26: 11
A27: 12
A28: 13
A29: 14
A30: 15
A31: 16
A32: 17
A33: 18
A34: 19
A35: 20
A36: 21
A37: 22
... A45: 30
P46: Click + to left for additional rows
A47: 31
A48: 32
A49: 33
A50: 34
A51: 35
A52: 36
A53: 37
A54: 38
...

Sheet Logic
B2: LEED v5 Fixture and Fittings Water Use Calculator LEED for Building Design and Construction | Interior Design and Construction Logic
B4: LOGIC 1: GENERAL INFORMATION
B6: Project Type | G6: =IFERROR(IF(inputspi_pt<>"",inputspi_pt,""),"")
B8: Unit of Measurement | G8: =IFERROR(IF(inputspi_units<>"",inputspi_units,""),"")
B11: LOGIC 2: GROUP PROJECT AND OCCUPANCY INFORMATION
B13: Click + to the left to add additional rows. Click - to the left to collapse (content will be saved).
B14: Group Name | D14: Contains ADA / Gender-Neutral Restrooms | E14: Percent of Males Expected to Use Restrooms with Urinals | F14: Annual Days of Operation | G14: Employees (FTE) | J14: Visitors | M14: Retail Customers | P14: Students (K-12) | S14: Residential | V14: Other (Specify)
G15: Total | H15: Male | I15: Female | J15: Total | K15: Male | L15: Female | M15: Total | N15: Male | O15: Female | P15: Total | Q15: Male | R15: Female | S15: Total | T15: Male | U15: Female | V15: Total | W15: Male | X15: Female
A16: 1 | B16: =IFERROR(IF(INDEX(inputsgrp_gn,MATCH(Logic!$A16,inputsgrp_no,0))<>"",INDEX(inputsgrp_gn,MATCH(Logic!$A16,inputsgrp_no,0)),""),"") | D16: =IFERROR(IF(INDEX(inputsgrp_ada,MATCH(Logic!$A16,inputsgrp_no,0))<>"",INDEX(inputsgrp_ada,MATCH(Logic!$A16,inputsgrp_no,0)),""),"") | E16: =IFERROR(IF(INDEX(inputsgrp_urinal,MATCH(Logic!$A16,inputsgrp_no,0))<>"",INDEX(inputsgrp_urinal,MATCH(Logic!$A16,inputsgrp_no,0)),""),"") | F16: =IFERROR(IF(INDEX(inputsgrp_an,MATCH(Logic!$A16,inputsgrp_no,0))<>"",INDEX(inputsgrp_an,MATCH(Logic!$A16,inputsgrp_no,0)),""),"") | G16: =IFERROR(IF(INDEX(inputsgrp_otefte,MATCH(Logic!$A16,inputsgrp_no,0))<>"",INDEX(inputsgrp_otefte,MATCH(Logic!$A16,inputsgrp_no,0)),""),"") | H16: =IF($G16<>"",IFERROR(IF('Inputs Fixture Fittings'!$D16<>"Default",'Inputs Fixture Fittings'!$E16*$G16,0.5*$G16),0),"") | I16: =IF($G16<>"",IFERROR(IF('Inputs Fixture Fittings'!$D16<>"Default",'Inputs Fixture Fittings'!$F16*$G16,0.5*$G16),0),"") | J16: =IFERROR(IF(INDEX(inputsgrp_otv,MATCH(Logic!$A16,inputsgrp_no,0))<>"",INDEX(inputsgrp_otv,MATCH(Logic!$A16,inputsgrp_no,0)),""),"") | K16: =IF($J16<>"",IFERROR(IF('Inputs Fixture Fittings'!$D16<>"Default",'Inputs Fixture Fittings'!$E16*$J16,0.5*$J16),0),"") | L16: =IF($J16<>"",IFERROR(IF('Inputs Fixture Fittings'!$D16<>"Default",'Inputs Fixture Fittings'!$F16*$J16,0.5*$J16),0),"") | M16: =IFERROR(IF(INDEX(inputsgrp_otrc,MATCH(Logic!$A16,inputsgrp_no,0))<>"",INDEX(inputsgrp_otrc,MATCH(Logic!$A16,inputsgrp_no,0)),""),"") | N16: =IF($M16<>"",IFERROR(IF('Inputs Fixture Fittings'!$D16<>"Default",'Inputs Fixture Fittings'!$E16*$M16,0.5*$M16),0),"") | O16: =IF($M16<>"",IFERROR(IF('Inputs Fixture Fittings'!$D16<>"Default",'Inputs Fixture Fittings'!$F16*$M16,0.5*$M16),0),"") | P16: =IFERROR(IF(INDEX(inputsgrp_otstud,MATCH(Logic!$A16,inputsgrp_no,0))<>"",INDEX(inputsgrp_otstud,MATCH(Logic!$A16,inputsgrp_no,0)),""),"") | Q16: =IF($P16<>"",IFERROR(IF('Inputs Fixture Fittings'!$D16<>"Default",'Inputs Fixture Fittings'!$E16*$P16,0.5*$P16),0),"") | R16: =IF($P16<>"",IFERROR(IF('Inputs Fixture Fittings'!$D16<>"Default",'Inputs Fixture Fittings'!$F16*$P16,0.5*$P16),0),"") | S16: =IFERROR(IF(INDEX(inputsgrp_otres,MATCH(Logic!$A16,inputsgrp_no,0))<>"",INDEX(inputsgrp_otres,MATCH(Logic!$A16,inputsgrp_no,0)),""),"") | T16: =IF($S16<>"",IFERROR(IF('Inputs Fixture Fittings'!$D16<>"Default",'Inputs Fixture Fittings'!$E16*$S16,0.5*$S16),0),"") | U16: =IF($S16<>"",IFERROR(IF('Inputs Fixture Fittings'!$D16<>"Default",'Inputs Fixture Fittings'!$F16*$S16,0.5*$S16),0),"") | V16: =IFERROR(IF(INDEX(inputsgrp_otot,MATCH(Logic!$A16,inputsgrp_no,0))<>"",INDEX(inputsgrp_otot,MATCH(Logic!$A16,inputsgrp_no,0)),""),"") | W16: =IF($V16<>"",IFERROR(IF('Inputs Fixture Fittings'!$D16<>"Default",'Inputs Fixture Fittings'!$E16*$V16,0.5*$V16),0),"") | X16: =IF($V16<>"",IFERROR(IF('Inputs Fixture Fittings'!$D16<>"Default",'Inputs Fixture Fittings'!$F16*$V16,0.5*$V16),0),"")
A17: 2 | B17: =IFERROR(IF(INDEX(inputsgrp_gn,MATCH(Logic!$A17,inputsgrp_no,0))<>"",INDEX(inputsgrp_gn,MATCH(Logic!$A17,inputsgrp_no,0)),""),"") | D17: =IFERROR(IF(INDEX(inputsgrp_ada,MATCH(Logic!$A17,inputsgrp_no,0))<>"",INDEX(inputsgrp_ada,MATCH(Logic!$A17,inputsgrp_no,0)),""),"") | E17: =IFERROR(IF(INDEX(inputsgrp_urinal,MATCH(Logic!$A17,inputsgrp_no,0))<>"",INDEX(inputsgrp_urinal,MATCH(Logic!$A17,inputsgrp_no,0)),""),"") | F17: =IFERROR(IF(INDEX(inputsgrp_an,MATCH(Logic!$A17,inputsgrp_no,0))<>"",INDEX(inputsgrp_an,MATCH(Logic!$A17,inputsgrp_no,0)),""),"") | G17: =IFERROR(IF(INDEX(inputsgrp_otefte,MATCH(Logic!$A17,inputsgrp_no,0))<>"",INDEX(inputsgrp_otefte,MATCH(Logic!$A17,inputsgrp_no,0)),""),"") | H17: =IF($G17<>"",IFERROR(IF('Inputs Fixture Fittings'!$D17<>"Default",'Inputs Fixture Fittings'!$E17*$G17,0.5*$G17),0),"") | I17: =IF($G17<>"",IFERROR(IF('Inputs Fixture Fittings'!$D17<>"Default",'Inputs Fixture Fittings'!$F17*$G17,0.5*$G17),0),"") | J17: =IFERROR(IF(INDEX(inputsgrp_otv,MATCH(Logic!$A17,inputsgrp_no,0))<>"",INDEX(inputsgrp_otv,MATCH(Logic!$A17,inputsgrp_no,0)),""),"") | K17: =IF($J17<>"",IFERROR(IF('Inputs Fixture Fittings'!$D17<>"Default",'Inputs Fixture Fittings'!$E17*$J17,0.5*$J17),0),"") | L17: =IF($J17<>"",IFERROR(IF('Inputs Fixture Fittings'!$D17<>"Default",'Inputs Fixture Fittings'!$F17*$J17,0.5*$J17),0),"") | M17: =IFERROR(IF(INDEX(inputsgrp_otrc,MATCH(Logic!$A17,inputsgrp_no,0))<>"",INDEX(inputsgrp_otrc,MATCH(Logic!$A17,inputsgrp_no,0)),""),"") | N17: =IF($M17<>"",IFERROR(IF('Inputs Fixture Fittings'!$D17<>"Default",'Inputs Fixture Fittings'!$E17*$M17,0.5*$M17),0),"") | O17: =IF($M17<>"",IFERROR(IF('Inputs Fixture Fittings'!$D17<>"Default",'Inputs Fixture Fittings'!$F17*$M17,0.5*$M17),0),"") | P17: =IFERROR(IF(INDEX(inputsgrp_otstud,MATCH(Logic!$A17,inputsgrp_no,0))<>"",INDEX(inputsgrp_otstud,MATCH(Logic!$A17,inputsgrp_no,0)),""),"") | Q17: =IF($P17<>"",IFERROR(IF('Inputs Fixture Fittings'!$D17<>"Default",'Inputs Fixture Fittings'!$E17*$P17,0.5*$P17),0),"") | R17: =IF($P17<>"",IFERROR(IF('Inputs Fixture Fittings'!$D17<>"Default",'Inputs Fixture Fittings'!$F17*$P17,0.5*$P17),0),"") | S17: =IFERROR(IF(INDEX(inputsgrp_otres,MATCH(Logic!$A17,inputsgrp_no,0))<>"",INDEX(inputsgrp_otres,MATCH(Logic!$A17,inputsgrp_no,0)),""),"") | T17: =IF($S17<>"",IFERROR(IF('Inputs Fixture Fittings'!$D17<>"Default",'Inputs Fixture Fittings'!$E17*$S17,0.5*$S17),0),"") | U17: =IF($S17<>"",IFERROR(IF('Inputs Fixture Fittings'!$D17<>"Default",'Inputs Fixture Fittings'!$F17*$S17,0.5*$S17),0),"") | V17: =IFERROR(IF(INDEX(inputsgrp_otot,MATCH(Logic!$A17,inputsgrp_no,0))<>"",INDEX(inputsgrp_otot,MATCH(Logic!$A17,inputsgrp_no,0)),""),"") | W17: =IF($V17<>"",IFERROR(IF('Inputs Fixture Fittings'!$D17<>"Default",'Inputs Fixture Fittings'!$E17*$V17,0.5*$V17),0),"") | X17: =IF($V17<>"",IFERROR(IF('Inputs Fixture Fittings'!$D17<>"Default",'Inputs Fixture Fittings'!$F17*$V17,0.5*$V17),0),"")
A18: 3 | B18: =IFERROR(IF(INDEX(inputsgrp_gn,MATCH(Logic!$A18,inputsgrp_no,0))<>"",INDEX(inputsgrp_gn,MATCH(Logic!$A18,inputsgrp_no,0)),""),"") | D18: =IFERROR(IF(INDEX(inputsgrp_ada,MATCH(Logic!$A18,inputsgrp_no,0))<>"",INDEX(inputsgrp_ada,MATCH(Logic!$A18,inputsgrp_no,0)),""),"") | E18: =IFERROR(IF(INDEX(inputsgrp_urinal,MATCH(Logic!$A18,inputsgrp_no,0))<>"",INDEX(inputsgrp_urinal,MATCH(Logic!$A18,inputsgrp_no,0)),""),"") | F18: =IFERROR(IF(INDEX(inputsgrp_an,MATCH(Logic!$A18,inputsgrp_no,0))<>"",INDEX(inputsgrp_an,MATCH(Logic!$A18,inputsgrp_no,0)),""),"") | G18: =IFERROR(IF(INDEX(inputsgrp_otefte,MATCH(Logic!$A18,inputsgrp_no,0))<>"",INDEX(inputsgrp_otefte,MATCH(Logic!$A18,inputsgrp_no,0)),""),"") | H18: =IF($G18<>"",IFERROR(IF('Inputs Fixture Fittings'!$D18<>"Default",'Inputs Fixture Fittings'!$E18*$G18,0.5*$G18),0),"") | I18: =IF($G18<>"",IFERROR(IF('Inputs Fixture Fittings'!$D18<>"Default",'Inputs Fixture Fittings'!$F18*$G18,0.5*$G18),0),"") | J18: =IFERROR(IF(INDEX(inputsgrp_otv,MATCH(Logic!$A18,inputsgrp_no,0))<>"",INDEX(inputsgrp_otv,MATCH(Logic!$A18,inputsgrp_no,0)),""),"") | K18: =IF($J18<>"",IFERROR(IF('Inputs Fixture Fittings'!$D18<>"Default",'Inputs Fixture Fittings'!$E18*$J18,0.5*$J18),0),"") | L18: =IF($J18<>"",IFERROR(IF('Inputs Fixture Fittings'!$D18<>"Default",'Inputs Fixture Fittings'!$F18*$J18,0.5*$J18),0),"") | M18: =IFERROR(IF(INDEX(inputsgrp_otrc,MATCH(Logic!$A18,inputsgrp_no,0))<>"",INDEX(inputsgrp_otrc,MATCH(Logic!$A18,inputsgrp_no,0)),""),"") | N18: =IF($M18<>"",IFERROR(IF('Inputs Fixture Fittings'!$D18<>"Default",'Inputs Fixture Fittings'!$E18*$M18,0.5*$M18),0),"") | O18: =IF($M18<>"",IFERROR(IF('Inputs Fixture Fittings'!$D18<>"Default",'Inputs Fixture Fittings'!$F18*$M18,0.5*$M18),0),"") | P18: =IFERROR(IF(INDEX(inputsgrp_otstud,MATCH(Logic!$A18,inputsgrp_no,0))<>"",INDEX(inputsgrp_otstud,MATCH(Logic!$A18,inputsgrp_no,0)),""),"") | Q18: =IF($P18<>"",IFERROR(IF('Inputs Fixture Fittings'!$D18<>"Default",'Inputs Fixture Fittings'!$E18*$P18,0.5*$P18),0),"") | R18: =IF($P18<>"",IFERROR(IF('Inputs Fixture Fittings'!$D18<>"Default",'Inputs Fixture Fittings'!$F18*$P18,0.5*$P18),0),"") | S18: =IFERROR(IF(INDEX(inputsgrp_otres,MATCH(Logic!$A18,inputsgrp_no,0))<>"",INDEX(inputsgrp_otres,MATCH(Logic!$A18,inputsgrp_no,0)),""),"") | T18: =IF($S18<>"",IFERROR(IF('Inputs Fixture Fittings'!$D18<>"Default",'Inputs Fixture Fittings'!$E18*$S18,0.5*$S18),0),"") | U18: =IF($S18<>"",IFERROR(IF('Inputs Fixture Fittings'!$D18<>"Default",'Inputs Fixture Fittings'!$F18*$S18,0.5*$S18),0),"") | V18: =IFERROR(IF(INDEX(inputsgrp_otot,MATCH(Logic!$A18,inputsgrp_no,0))<>"",INDEX(inputsgrp_otot,MATCH(Logic!$A18,inputsgrp_no,0)),""),"") | W18: =IF($V18<>"",IFERROR(IF('Inputs Fixture Fittings'!$D18<>"Default",'Inputs Fixture Fittings'!$E18*$V18,0.5*$V18),0),"") | X18: =IF($V18<>"",IFERROR(IF('Inputs Fixture Fittings'!$D18<>"Default",'Inputs Fixture Fittings'!$F18*$V18,0.5*$V18),0),"")
A19: 4 | B19: =IFERROR(IF(INDEX(inputsgrp_gn,MATCH(Logic!$A19,inputsgrp_no,0))<>"",INDEX(inputsgrp_gn,MATCH(Logic!$A19,inputsgrp_no,0)),""),"") | D19: =IFERROR(IF(INDEX(inputsgrp_ada,MATCH(Logic!$A19,inputsgrp_no,0))<>"",INDEX(inputsgrp_ada,MATCH(Logic!$A19,inputsgrp_no,0)),""),"") | E19: =IFERROR(IF(INDEX(inputsgrp_urinal,MATCH(Logic!$A19,inputsgrp_no,0))<>"",INDEX(inputsgrp_urinal,MATCH(Logic!$A19,inputsgrp_no,0)),""),"") | F19: =IFERROR(IF(INDEX(inputsgrp_an,MATCH(Logic!$A19,inputsgrp_no,0))<>"",INDEX(inputsgrp_an,MATCH(Logic!$A19,inputsgrp_no,0)),""),"") | G19: =IFERROR(IF(INDEX(inputsgrp_otefte,MATCH(Logic!$A19,inputsgrp_no,0))<>"",INDEX(inputsgrp_otefte,MATCH(Logic!$A19,inputsgrp_no,0)),""),"") | H19: =IF($G19<>"",IFERROR(IF('Inputs Fixture Fittings'!$D19<>"Default",'Inputs Fixture Fittings'!$E19*$G19,0.5*$G19),0),"") | I19: =IF($G19<>"",IFERROR(IF('Inputs Fixture Fittings'!$D19<>"Default",'Inputs Fixture Fittings'!$F19*$G19,0.5*$G19),0),"") | J19: =IFERROR(IF(INDEX(inputsgrp_otv,MATCH(Logic!$A19,inputsgrp_no,0))<>"",INDEX(inputsgrp_otv,MATCH(Logic!$A19,inputsgrp_no,0)),""),"") | K19: =IF($J19<>"",IFERROR(IF('Inputs Fixture Fittings'!$D19<>"Default",'Inputs Fixture Fittings'!$E19*$J19,0.5*$J19),0),"") | L19: =IF($J19<>"",IFERROR(IF('Inputs Fixture Fittings'!$D19<>"Default",'Inputs Fixture Fittings'!$F19*$J19,0.5*$J19),0),"") | M19: =IFERROR(IF(INDEX(inputsgrp_otrc,MATCH(Logic!$A19,inputsgrp_no,0))<>"",INDEX(inputsgrp_otrc,MATCH(Logic!$A19,inputsgrp_no,0)),""),"") | N19: =IF($M19<>"",IFERROR(IF('Inputs Fixture Fittings'!$D19<>"Default",'Inputs Fixture Fittings'!$E19*$M19,0.5*$M19),0),"") | O19: =IF($M19<>"",IFERROR(IF('Inputs Fixture Fittings'!$D19<>"Default",'Inputs Fixture Fittings'!$F19*$M19,0.5*$M19),0),"") | P19: =IFERROR(IF(INDEX(inputsgrp_otstud,MATCH(Logic!$A19,inputsgrp_no,0))<>"",INDEX(inputsgrp_otstud,MATCH(Logic!$A19,inputsgrp_no,0)),""),"") | Q19: =IF($P19<>"",IFERROR(IF('Inputs Fixture Fittings'!$D19<>"Default",'Inputs Fixture Fittings'!$E19*$P19,0.5*$P19),0),"") | R19: =IF($P19<>"",IFERROR(IF('Inputs Fixture Fittings'!$D19<>"Default",'Inputs Fixture Fittings'!$F19*$P19,0.5*$P19),0),"") | S19: =IFERROR(IF(INDEX(inputsgrp_otres,MATCH(Logic!$A19,inputsgrp_no,0))<>"",INDEX(inputsgrp_otres,MATCH(Logic!$A19,inputsgrp_no,0)),""),"") | T19: =IF($S19<>"",IFERROR(IF('Inputs Fixture Fittings'!$D19<>"Default",'Inputs Fixture Fittings'!$E19*$S19,0.5*$S19),0),"") | U19: =IF($S19<>"",IFERROR(IF('Inputs Fixture Fittings'!$D19<>"Default",'Inputs Fixture Fittings'!$F19*$S19,0.5*$S19),0),"") | V19: =IFERROR(IF(INDEX(inputsgrp_otot,MATCH(Logic!$A19,inputsgrp_no,0))<>"",INDEX(inputsgrp_otot,MATCH(Logic!$A19,inputsgrp_no,0)),""),"") | W19: =IF($V19<>"",IFERROR(IF('Inputs Fixture Fittings'!$D19<>"Default",'Inputs Fixture Fittings'!$E19*$V19,0.5*$V19),0),"") | X19: =IF($V19<>"",IFERROR(IF('Inputs Fixture Fittings'!$D19<>"Default",'Inputs Fixture Fittings'!$F19*$V19,0.5*$V19),0),"")
A20: 5 | B20: =IFERROR(IF(INDEX(inputsgrp_gn,MATCH(Logic!$A20,inputsgrp_no,0))<>"",INDEX(inputsgrp_gn,MATCH(Logic!$A20,inputsgrp_no,0)),""),"") | D20: =IFERROR(IF(INDEX(inputsgrp_ada,MATCH(Logic!$A20,inputsgrp_no,0))<>"",INDEX(inputsgrp_ada,MATCH(Logic!$A20,inputsgrp_no,0)),""),"") | E20: =IFERROR(IF(INDEX(inputsgrp_urinal,MATCH(Logic!$A20,inputsgrp_no,0))<>"",INDEX(inputsgrp_urinal,MATCH(Logic!$A20,inputsgrp_no,0)),""),"") | F20: =IFERROR(IF(INDEX(inputsgrp_an,MATCH(Logic!$A20,inputsgrp_no,0))<>"",INDEX(inputsgrp_an,MATCH(Logic!$A20,inputsgrp_no,0)),""),"") | G20: =IFERROR(IF(INDEX(inputsgrp_otefte,MATCH(Logic!$A20,inputsgrp_no,0))<>"",INDEX(inputsgrp_otefte,MATCH(Logic!$A20,inputsgrp_no,0)),""),"") | H20: =IF($G20<>"",IFERROR(IF('Inputs Fixture Fittings'!$D20<>"Default",'Inputs Fixture Fittings'!$E20*$G20,0.5*$G20),0),"") | I20: =IF($G20<>"",IFERROR(IF('Inputs Fixture Fittings'!$D20<>"Default",'Inputs Fixture Fittings'!$F20*$G20,0.5*$G20),0),"") | J20: =IFERROR(IF(INDEX(inputsgrp_otv,MATCH(Logic!$A20,inputsgrp_no,0))<>"",INDEX(inputsgrp_otv,MATCH(Logic!$A20,inputsgrp_no,0)),""),"") | K20: =IF($J20<>"",IFERROR(IF('Inputs Fixture Fittings'!$D20<>"Default",'Inputs Fixture Fittings'!$E20*$J20,0.5*$J20),0),"") | L20: =IF($J20<>"",IFERROR(IF('Inputs Fixture Fittings'!$D20<>"Default",'Inputs Fixture Fittings'!$F20*$J20,0.5*$J20),0),"") | M20: =IFERROR(IF(INDEX(inputsgrp_otrc,MATCH(Logic!$A20,inputsgrp_no,0))<>"",INDEX(inputsgrp_otrc,MATCH(Logic!$A20,inputsgrp_no,0)),""),"") | N20: =IF($M20<>"",IFERROR(IF('Inputs Fixture Fittings'!$D20<>"Default",'Inputs Fixture Fittings'!$E20*$M20,0.5*$M20),0),"") | O20: =IF($M20<>"",IFERROR(IF('Inputs Fixture Fittings'!$D20<>"Default",'Inputs Fixture Fittings'!$F20*$M20,0.5*$M20),0),"") | P20: =IFERROR(IF(INDEX(inputsgrp_otstud,MATCH(Logic!$A20,inputsgrp_no,0))<>"",INDEX(inputsgrp_otstud,MATCH(Logic!$A20,inputsgrp_no,0)),""),"") | Q20: =IF($P20<>"",IFERROR(IF('Inputs Fixture Fittings'!$D20<>"Default",'Inputs Fixture Fittings'!$E20*$P20,0.5*$P20),0),"") | R20: =IF($P20<>"",IFERROR(IF('Inputs Fixture Fittings'!$D20<>"Default",'Inputs Fixture Fittings'!$F20*$P20,0.5*$P20),0),"") | S20: =IFERROR(IF(INDEX(inputsgrp_otres,MATCH(Logic!$A20,inputsgrp_no,0))<>"",INDEX(inputsgrp_otres,MATCH(Logic!$A20,inputsgrp_no,0)),""),"") | T20: =IF($S20<>"",IFERROR(IF('Inputs Fixture Fittings'!$D20<>"Default",'Inputs Fixture Fittings'!$E20*$S20,0.5*$S20),0),"") | U20: =IF($S20<>"",IFERROR(IF('Inputs Fixture Fittings'!$D20<>"Default",'Inputs Fixture Fittings'!$F20*$S20,0.5*$S20),0),"") | V20: =IFERROR(IF(INDEX(inputsgrp_otot,MATCH(Logic!$A20,inputsgrp_no,0))<>"",INDEX(inputsgrp_otot,MATCH(Logic!$A20,inputsgrp_no,0)),""),"") | W20: =IF($V20<>"",IFERROR(IF('Inputs Fixture Fittings'!$D20<>"Default",'Inputs Fixture Fittings'!$E20*$V20,0.5*$V20),0),"") | X20: =IF($V20<>"",IFERROR(IF('Inputs Fixture Fittings'!$D20<>"Default",'Inputs Fixture Fittings'!$F20*$V20,0.5*$V20),0),"")
A21: 6 | B21: =IFERROR(IF(INDEX(inputsgrp_gn,MATCH(Logic!$A21,inputsgrp_no,0))<>"",INDEX(inputsgrp_gn,MATCH(Logic!$A21,inputsgrp_no,0)),""),"") | D21: =IFERROR(IF(INDEX(inputsgrp_ada,MATCH(Logic!$A21,inputsgrp_no,0))<>"",INDEX(inputsgrp_ada,MATCH(Logic!$A21,inputsgrp_no,0)),""),"") | E21: =IFERROR(IF(INDEX(inputsgrp_urinal,MATCH(Logic!$A21,inputsgrp_no,0))<>"",INDEX(inputsgrp_urinal,MATCH(Logic!$A21,inputsgrp_no,0)),""),"") | F21: =IFERROR(IF(INDEX(inputsgrp_an,MATCH(Logic!$A21,inputsgrp_no,0))<>"",INDEX(inputsgrp_an,MATCH(Logic!$A21,inputsgrp_no,0)),""),"") | G21: =IFERROR(IF(INDEX(inputsgrp_otefte,MATCH(Logic!$A21,inputsgrp_no,0))<>"",INDEX(inputsgrp_otefte,MATCH(Logic!$A21,inputsgrp_no,0)),""),"") | H21: =IF($G21<>"",IFERROR(IF('Inputs Fixture Fittings'!$D21<>"Default",'Inputs Fixture Fittings'!$E21*$G21,0.5*$G21),0),"") | I21: =IF($G21<>"",IFERROR(IF('Inputs Fixture Fittings'!$D21<>"Default",'Inputs Fixture Fittings'!$F21*$G21,0.5*$G21),0),"") | J21: =IFERROR(IF(INDEX(inputsgrp_otv,MATCH(Logic!$A21,inputsgrp_no,0))<>"",INDEX(inputsgrp_otv,MATCH(Logic!$A21,inputsgrp_no,0)),""),"") | K21: =IF($J21<>"",IFERROR(IF('Inputs Fixture Fittings'!$D21<>"Default",'Inputs Fixture Fittings'!$E21*$J21,0.5*$J21),0),"") | L21: =IF($J21<>"",IFERROR(IF('Inputs Fixture Fittings'!$D21<>"Default",'Inputs Fixture Fittings'!$F21*$J21,0.5*$J21),0),"") | M21: =IFERROR(IF(INDEX(inputsgrp_otrc,MATCH(Logic!$A21,inputsgrp_no,0))<>"",INDEX(inputsgrp_otrc,MATCH(Logic!$A21,inputsgrp_no,0)),""),"") | N21: =IF($M21<>"",IFERROR(IF('Inputs Fixture Fittings'!$D21<>"Default",'Inputs Fixture Fittings'!$E21*$M21,0.5*$M21),0),"") | O21: =IF($M21<>"",IFERROR(IF('Inputs Fixture Fittings'!$D21<>"Default",'Inputs Fixture Fittings'!$F21*$M21,0.5*$M21),0),"") | P21: =IFERROR(IF(INDEX(inputsgrp_otstud,MATCH(Logic!$A21,inputsgrp_no,0))<>"",INDEX(inputsgrp_otstud,MATCH(Logic!$A21,inputsgrp_no,0)),""),"") | Q21: =IF($P21<>"",IFERROR(IF('Inputs Fixture Fittings'!$D21<>"Default",'Inputs Fixture Fittings'!$E21*$P21,0.5*$P21),0),"") | R21: =IF($P21<>"",IFERROR(IF('Inputs Fixture Fittings'!$D21<>"Default",'Inputs Fixture Fittings'!$F21*$P21,0.5*$P21),0),"") | S21: =IFERROR(IF(INDEX(inputsgrp_otres,MATCH(Logic!$A21,inputsgrp_no,0))<>"",INDEX(inputsgrp_otres,MATCH(Logic!$A21,inputsgrp_no,0)),""),"") | T21: =IF($S21<>"",IFERROR(IF('Inputs Fixture Fittings'!$D21<>"Default",'Inputs Fixture Fittings'!$E21*$S21,0.5*$S21),0),"") | U21: =IF($S21<>"",IFERROR(IF('Inputs Fixture Fittings'!$D21<>"Default",'Inputs Fixture Fittings'!$F21*$S21,0.5*$S21),0),"") | V21: =IFERROR(IF(INDEX(inputsgrp_otot,MATCH(Logic!$A21,inputsgrp_no,0))<>"",INDEX(inputsgrp_otot,MATCH(Logic!$A21,inputsgrp_no,0)),""),"") | W21: =IF($V21<>"",IFERROR(IF('Inputs Fixture Fittings'!$D21<>"Default",'Inputs Fixture Fittings'!$E21*$V21,0.5*$V21),0),"") | X21: =IF($V21<>"",IFERROR(IF('Inputs Fixture Fittings'!$D21<>"Default",'Inputs Fixture Fittings'!$F21*$V21,0.5*$V21),0),"")
A22: 7 | B22: =IFERROR(IF(INDEX(inputsgrp_gn,MATCH(Logic!$A22,inputsgrp_no,0))<>"",INDEX(inputsgrp_gn,MATCH(Logic!$A22,inputsgrp_no,0)),""),"") | D22: =IFERROR(IF(INDEX(inputsgrp_ada,MATCH(Logic!$A22,inputsgrp_no,0))<>"",INDEX(inputsgrp_ada,MATCH(Logic!$A22,inputsgrp_no,0)),""),"") | E22: =IFERROR(IF(INDEX(inputsgrp_urinal,MATCH(Logic!$A22,inputsgrp_no,0))<>"",INDEX(inputsgrp_urinal,MATCH(Logic!$A22,inputsgrp_no,0)),""),"") | F22: =IFERROR(IF(INDEX(inputsgrp_an,MATCH(Logic!$A22,inputsgrp_no,0))<>"",INDEX(inputsgrp_an,MATCH(Logic!$A22,inputsgrp_no,0)),""),"") | G22: =IFERROR(IF(INDEX(inputsgrp_otefte,MATCH(Logic!$A22,inputsgrp_no,0))<>"",INDEX(inputsgrp_otefte,MATCH(Logic!$A22,inputsgrp_no,0)),""),"") | H22: =IF($G22<>"",IFERROR(IF('Inputs Fixture Fittings'!$D22<>"Default",'Inputs Fixture Fittings'!$E22*$G22,0.5*$G22),0),"") | I22: =IF($G22<>"",IFERROR(IF('Inputs Fixture Fittings'!$D22<>"Default",'Inputs Fixture Fittings'!$F22*$G22,0.5*$G22),0),"") | J22: =IFERROR(IF(INDEX(inputsgrp_otv,MATCH(Logic!$A22,inputsgrp_no,0))<>"",INDEX(inputsgrp_otv,MATCH(Logic!$A22,inputsgrp_no,0)),""),"") | K22: =IF($J22<>"",IFERROR(IF('Inputs Fixture Fittings'!$D22<>"Default",'Inputs Fixture Fittings'!$E22*$J22,0.5*$J22),0),"") | L22: =IF($J22<>"",IFERROR(IF('Inputs Fixture Fittings'!$D22<>"Default",'Inputs Fixture Fittings'!$F22*$J22,0.5*$J22),0),"") | M22: =IFERROR(IF(INDEX(inputsgrp_otrc,MATCH(Logic!$A22,inputsgrp_no,0))<>"",INDEX(inputsgrp_otrc,MATCH(Logic!$A22,inputsgrp_no,0)),""),"") | N22: =IF($M22<>"",IFERROR(IF('Inputs Fixture Fittings'!$D22<>"Default",'Inputs Fixture Fittings'!$E22*$M22,0.5*$M22),0),"") | O22: =IF($M22<>"",IFERROR(IF('Inputs Fixture Fittings'!$D22<>"Default",'Inputs Fixture Fittings'!$F22*$M22,0.5*$M22),0),"") | P22: =IFERROR(IF(INDEX(inputsgrp_otstud,MATCH(Logic!$A22,inputsgrp_no,0))<>"",INDEX(inputsgrp_otstud,MATCH(Logic!$A22,inputsgrp_no,0)),""),"") | Q22: =IF($P22<>"",IFERROR(IF('Inputs Fixture Fittings'!$D22<>"Default",'Inputs Fixture Fittings'!$E22*$P22,0.5*$P22),0),"") | R22: =IF($P22<>"",IFERROR(IF('Inputs Fixture Fittings'!$D22<>"Default",'Inputs Fixture Fittings'!$F22*$P22,0.5*$P22),0),"") | S22: =IFERROR(IF(INDEX(inputsgrp_otres,MATCH(Logic!$A22,inputsgrp_no,0))<>"",INDEX(inputsgrp_otres,MATCH(Logic!$A22,inputsgrp_no,0)),""),"") | T22: =IF($S22<>"",IFERROR(IF('Inputs Fixture Fittings'!$D22<>"Default",'Inputs Fixture Fittings'!$E22*$S22,0.5*$S22),0),"") | U22: =IF($S22<>"",IFERROR(IF('Inputs Fixture Fittings'!$D22<>"Default",'Inputs Fixture Fittings'!$F22*$S22,0.5*$S22),0),"") | V22: =IFERROR(IF(INDEX(inputsgrp_otot,MATCH(Logic!$A22,inputsgrp_no,0))<>"",INDEX(inputsgrp_otot,MATCH(Logic!$A22,inputsgrp_no,0)),""),"") | W22: =IF($V22<>"",IFERROR(IF('Inputs Fixture Fittings'!$D22<>"Default",'Inputs Fixture Fittings'!$E22*$V22,0.5*$V22),0),"") | X22: =IF($V22<>"",IFERROR(IF('Inputs Fixture Fittings'!$D22<>"Default",'Inputs Fixture Fittings'!$F22*$V22,0.5*$V22),0),"")
A23: 8 | B23: =IFERROR(IF(INDEX(inputsgrp_gn,MATCH(Logic!$A23,inputsgrp_no,0))<>"",INDEX(inputsgrp_gn,MATCH(Logic!$A23,inputsgrp_no,0)),""),"") | D23: =IFERROR(IF(INDEX(inputsgrp_ada,MATCH(Logic!$A23,inputsgrp_no,0))<>"",INDEX(inputsgrp_ada,MATCH(Logic!$A23,inputsgrp_no,0)),""),"") | E23: =IFERROR(IF(INDEX(inputsgrp_urinal,MATCH(Logic!$A23,inputsgrp_no,0))<>"",INDEX(inputsgrp_urinal,MATCH(Logic!$A23,inputsgrp_no,0)),""),"") | F23: =IFERROR(IF(INDEX(inputsgrp_an,MATCH(Logic!$A23,inputsgrp_no,0))<>"",INDEX(inputsgrp_an,MATCH(Logic!$A23,inputsgrp_no,0)),""),"") | G23: =IFERROR(IF(INDEX(inputsgrp_otefte,MATCH(Logic!$A23,inputsgrp_no,0))<>"",INDEX(inputsgrp_otefte,MATCH(Logic!$A23,inputsgrp_no,0)),""),"") | H23: =IF($G23<>"",IFERROR(IF('Inputs Fixture Fittings'!$D23<>"Default",'Inputs Fixture Fittings'!$E23*$G23,0.5*$G23),0),"") | I23: =IF($G23<>"",IFERROR(IF('Inputs Fixture Fittings'!$D23<>"Default",'Inputs Fixture Fittings'!$F23*$G23,0.5*$G23),0),"") | J23: =IFERROR(IF(INDEX(inputsgrp_otv,MATCH(Logic!$A23,inputsgrp_no,0))<>"",INDEX(inputsgrp_otv,MATCH(Logic!$A23,inputsgrp_no,0)),""),"") | K23: =IF($J23<>"",IFERROR(IF('Inputs Fixture Fittings'!$D23<>"Default",'Inputs Fixture Fittings'!$E23*$J23,0.5*$J23),0),"") | L23: =IF($J23<>"",IFERROR(IF('Inputs Fixture Fittings'!$D23<>"Default",'Inputs Fixture Fittings'!$F23*$J23,0.5*$J23),0),"") | M23: =IFERROR(IF(INDEX(inputsgrp_otrc,MATCH(Logic!$A23,inputsgrp_no,0))<>"",INDEX(inputsgrp_otrc,MATCH(Logic!$A23,inputsgrp_no,0)),""),"") | N23: =IF($M23<>"",IFERROR(IF('Inputs Fixture Fittings'!$D23<>"Default",'Inputs Fixture Fittings'!$E23*$M23,0.5*$M23),0),"") | O23: =IF($M23<>"",IFERROR(IF('Inputs Fixture Fittings'!$D23<>"Default",'Inputs Fixture Fittings'!$F23*$M23,0.5*$M23),0),"") | P23: =IFERROR(IF(INDEX(inputsgrp_otstud,MATCH(Logic!$A23,inputsgrp_no,0))<>"",INDEX(inputsgrp_otstud,MATCH(Logic!$A23,inputsgrp_no,0)),""),"") | Q23: =IF($P23<>"",IFERROR(IF('Inputs Fixture Fittings'!$D23<>"Default",'Inputs Fixture Fittings'!$E23*$P23,0.5*$P23),0),"") | R23: =IF($P23<>"",IFERROR(IF('Inputs Fixture Fittings'!$D23<>"Default",'Inputs Fixture Fittings'!$F23*$P23,0.5*$P23),0),"") | S23: =IFERROR(IF(INDEX(inputsgrp_otres,MATCH(Logic!$A23,inputsgrp_no,0))<>"",INDEX(inputsgrp_otres,MATCH(Logic!$A23,inputsgrp_no,0)),""),"") | T23: =IF($S23<>"",IFERROR(IF('Inputs Fixture Fittings'!$D23<>"Default",'Inputs Fixture Fittings'!$E23*$S23,0.5*$S23),0),"") | U23: =IF($S23<>"",IFERROR(IF('Inputs Fixture Fittings'!$D23<>"Default",'Inputs Fixture Fittings'!$F23*$S23,0.5*$S23),0),"") | V23: =IFERROR(IF(INDEX(inputsgrp_otot,MATCH(Logic!$A23,inputsgrp_no,0))<>"",INDEX(inputsgrp_otot,MATCH(Logic!$A23,inputsgrp_no,0)),""),"") | W23: =IF($V23<>"",IFERROR(IF('Inputs Fixture Fittings'!$D23<>"Default",'Inputs Fixture Fittings'!$E23*$V23,0.5*$V23),0),"") | X23: =IF($V23<>"",IFERROR(IF('Inputs Fixture Fittings'!$D23<>"Default",'Inputs Fixture Fittings'!$F23*$V23,0.5*$V23),0),"")
A24: 9 | B24: =IFERROR(IF(INDEX(inputsgrp_gn,MATCH(Logic!$A24,inputsgrp_no,0))<>"",INDEX(inputsgrp_gn,MATCH(Logic!$A24,inputsgrp_no,0)),""),"") | D24: =IFERROR(IF(INDEX(inputsgrp_ada,MATCH(Logic!$A24,inputsgrp_no,0))<>"",INDEX(inputsgrp_ada,MATCH(Logic!$A24,inputsgrp_no,0)),""),"") | E24: =IFERROR(IF(INDEX(inputsgrp_urinal,MATCH(Logic!$A24,inputsgrp_no,0))<>"",INDEX(inputsgrp_urinal,MATCH(Logic!$A24,inputsgrp_no,0)),""),"") | F24: =IFERROR(IF(INDEX(inputsgrp_an,MATCH(Logic!$A24,inputsgrp_no,0))<>"",INDEX(inputsgrp_an,MATCH(Logic!$A24,inputsgrp_no,0)),""),"") | G24: =IFERROR(IF(INDEX(inputsgrp_otefte,MATCH(Logic!$A24,inputsgrp_no,0))<>"",INDEX(inputsgrp_otefte,MATCH(Logic!$A24,inputsgrp_no,0)),""),"") | H24: =IF($G24<>"",IFERROR(IF('Inputs Fixture Fittings'!$D24<>"Default",'Inputs Fixture Fittings'!$E24*$G24,0.5*$G24),0),"") | I24: =IF($G24<>"",IFERROR(IF('Inputs Fixture Fittings'!$D24<>"Default",'Inputs Fixture Fittings'!$F24*$G24,0.5*$G24),0),"") | J24: =IFERROR(IF(INDEX(inputsgrp_otv,MATCH(Logic!$A24,inputsgrp_no,0))<>"",INDEX(inputsgrp_otv,MATCH(Logic!$A24,inputsgrp_no,0)),""),"") | K24: =IF($J24<>"",IFERROR(IF('Inputs Fixture Fittings'!$D24<>"Default",'Inputs Fixture Fittings'!$E24*$J24,0.5*$J24),0),"") | L24: =IF($J24<>"",IFERROR(IF('Inputs Fixture Fittings'!$D24<>"Default",'Inputs Fixture Fittings'!$F24*$J24,0.5*$J24),0),"") | M24: =IFERROR(IF(INDEX(inputsgrp_otrc,MATCH(Logic!$A24,inputsgrp_no,0))<>"",INDEX(inputsgrp_otrc,MATCH(Logic!$A24,inputsgrp_no,0)),""),"") | N24: =IF($M24<>"",IFERROR(IF('Inputs Fixture Fittings'!$D24<>"Default",'Inputs Fixture Fittings'!$E24*$M24,0.5*$M24),0),"") | O24: =IF($M24<>"",IFERROR(IF('Inputs Fixture Fittings'!$D24<>"Default",'Inputs Fixture Fittings'!$F24*$M24,0.5*$M24),0),"") | P24: =IFERROR(IF(INDEX(inputsgrp_otstud,MATCH(Logic!$A24,inputsgrp_no,0))<>"",INDEX(inputsgrp_otstud,MATCH(Logic!$A24,inputsgrp_no,0)),""),"") | Q24: =IF($P24<>"",IFERROR(IF('Inputs Fixture Fittings'!$D24<>"Default",'Inputs Fixture Fittings'!$E24*$P24,0.5*$P24),0),"") | R24: =IF($P24<>"",IFERROR(IF('Inputs Fixture Fittings'!$D24<>"Default",'Inputs Fixture Fittings'!$F24*$P24,0.5*$P24),0),"") | S24: =IFERROR(IF(INDEX(inputsgrp_otres,MATCH(Logic!$A24,inputsgrp_no,0))<>"",INDEX(inputsgrp_otres,MATCH(Logic!$A24,inputsgrp_no,0)),""),"") | T24: =IF($S24<>"",IFERROR(IF('Inputs Fixture Fittings'!$D24<>"Default",'Inputs Fixture Fittings'!$E24*$S24,0.5*$S24),0),"") | U24: =IF($S24<>"",IFERROR(IF('Inputs Fixture Fittings'!$D24<>"Default",'Inputs Fixture Fittings'!$F24*$S24,0.5*$S24),0),"") | V24: =IFERROR(IF(INDEX(inputsgrp_otot,MATCH(Logic!$A24,inputsgrp_no,0))<>"",INDEX(inputsgrp_otot,MATCH(Logic!$A24,inputsgrp_no,0)),""),"") | W24: =IF($V24<>"",IFERROR(IF('Inputs Fixture Fittings'!$D24<>"Default",'Inputs Fixture Fittings'!$E24*$V24,0.5*$V24),0),"") | X24: =IF($V24<>"",IFERROR(IF('Inputs Fixture Fittings'!$D24<>"Default",'Inputs Fixture Fittings'!$F24*$V24,0.5*$V24),0),"")
A25: 10 | B25: =IFERROR(IF(INDEX(inputsgrp_gn,MATCH(Logic!$A25,inputsgrp_no,0))<>"",INDEX(inputsgrp_gn,MATCH(Logic!$A25,inputsgrp_no,0)),""),"") | D25: =IFERROR(IF(INDEX(inputsgrp_ada,MATCH(Logic!$A25,inputsgrp_no,0))<>"",INDEX(inputsgrp_ada,MATCH(Logic!$A25,inputsgrp_no,0)),""),"") | E25: =IFERROR(IF(INDEX(inputsgrp_urinal,MATCH(Logic!$A25,inputsgrp_no,0))<>"",INDEX(inputsgrp_urinal,MATCH(Logic!$A25,inputsgrp_no,0)),""),"") | F25: =IFERROR(IF(INDEX(inputsgrp_an,MATCH(Logic!$A25,inputsgrp_no,0))<>"",INDEX(inputsgrp_an,MATCH(Logic!$A25,inputsgrp_no,0)),""),"") | G25: =IFERROR(IF(INDEX(inputsgrp_otefte,MATCH(Logic!$A25,inputsgrp_no,0))<>"",INDEX(inputsgrp_otefte,MATCH(Logic!$A25,inputsgrp_no,0)),""),"") | H25: =IF($G25<>"",IFERROR(IF('Inputs Fixture Fittings'!$D25<>"Default",'Inputs Fixture Fittings'!$E25*$G25,0.5*$G25),0),"") | I25: =IF($G25<>"",IFERROR(IF('Inputs Fixture Fittings'!$D25<>"Default",'Inputs Fixture Fittings'!$F25*$G25,0.5*$G25),0),"") | J25: =IFERROR(IF(INDEX(inputsgrp_otv,MATCH(Logic!$A25,inputsgrp_no,0))<>"",INDEX(inputsgrp_otv,MATCH(Logic!$A25,inputsgrp_no,0)),""),"") | K25: =IF($J25<>"",IFERROR(IF('Inputs Fixture Fittings'!$D25<>"Default",'Inputs Fixture Fittings'!$E25*$J25,0.5*$J25),0),"") | L25: =IF($J25<>"",IFERROR(IF('Inputs Fixture Fittings'!$D25<>"Default",'Inputs Fixture Fittings'!$F25*$J25,0.5*$J25),0),"") | M25: =IFERROR(IF(INDEX(inputsgrp_otrc,MATCH(Logic!$A25,inputsgrp_no,0))<>"",INDEX(inputsgrp_otrc,MATCH(Logic!$A25,inputsgrp_no,0)),""),"") | N25: =IF($M25<>"",IFERROR(IF('Inputs Fixture Fittings'!$D25<>"Default",'Inputs Fixture Fittings'!$E25*$M25,0.5*$M25),0),"") | O25: =IF($M25<>"",IFERROR(IF('Inputs Fixture Fittings'!$D25<>"Default",'Inputs Fixture Fittings'!$F25*$M25,0.5*$M25),0),"") | P25: =IFERROR(IF(INDEX(inputsgrp_otstud,MATCH(Logic!$A25,inputsgrp_no,0))<>"",INDEX(inputsgrp_otstud,MATCH(Logic!$A25,inputsgrp_no,0)),""),"") | Q25: =IF($P25<>"",IFERROR(IF('Inputs Fixture Fittings'!$D25<>"Default",'Inputs Fixture Fittings'!$E25*$P25,0.5*$P25),0),"") | R25: =IF($P25<>"",IFERROR(IF('Inputs Fixture Fittings'!$D25<>"Default",'Inputs Fixture Fittings'!$F25*$P25,0.5*$P25),0),"") | S25: =IFERROR(IF(INDEX(inputsgrp_otres,MATCH(Logic!$A25,inputsgrp_no,0))<>"",INDEX(inputsgrp_otres,MATCH(Logic!$A25,inputsgrp_no,0)),""),"") | T25: =IF($S25<>"",IFERROR(IF('Inputs Fixture Fittings'!$D25<>"Default",'Inputs Fixture Fittings'!$E25*$S25,0.5*$S25),0),"") | U25: =IF($S25<>"",IFERROR(IF('Inputs Fixture Fittings'!$D25<>"Default",'Inputs Fixture Fittings'!$F25*$S25,0.5*$S25),0),"") | V25: =IFERROR(IF(INDEX(inputsgrp_otot,MATCH(Logic!$A25,inputsgrp_no,0))<>"",INDEX(inputsgrp_otot,MATCH(Logic!$A25,inputsgrp_no,0)),""),"") | W25: =IF($V25<>"",IFERROR(IF('Inputs Fixture Fittings'!$D25<>"Default",'Inputs Fixture Fittings'!$E25*$V25,0.5*$V25),0),"") | X25: =IF($V25<>"",IFERROR(IF('Inputs Fixture Fittings'!$D25<>"Default",'Inputs Fixture Fittings'!$F25*$V25,0.5*$V25),0),"")
A26: 11 | B26: =IFERROR(IF(INDEX(inputsgrp_gn,MATCH(Logic!$A26,inputsgrp_no,0))<>"",INDEX(inputsgrp_gn,MATCH(Logic!$A26,inputsgrp_no,0)),""),"") | D26: =IFERROR(IF(INDEX(inputsgrp_ada,MATCH(Logic!$A26,inputsgrp_no,0))<>"",INDEX(inputsgrp_ada,MATCH(Logic!$A26,inputsgrp_no,0)),""),"") | E26: =IFERROR(IF(INDEX(inputsgrp_urinal,MATCH(Logic!$A26,inputsgrp_no,0))<>"",INDEX(inputsgrp_urinal,MATCH(Logic!$A26,inputsgrp_no,0)),""),"") | F26: =IFERROR(IF(INDEX(inputsgrp_an,MATCH(Logic!$A26,inputsgrp_no,0))<>"",INDEX(inputsgrp_an,MATCH(Logic!$A26,inputsgrp_no,0)),""),"") | G26: =IFERROR(IF(INDEX(inputsgrp_otefte,MATCH(Logic!$A26,inputsgrp_no,0))<>"",INDEX(inputsgrp_otefte,MATCH(Logic!$A26,inputsgrp_no,0)),""),"") | H26: =IF($G26<>"",IFERROR(IF('Inputs Fixture Fittings'!$D26<>"Default",'Inputs Fixture Fittings'!$E26*$G26,0.5*$G26),0),"") | I26: =IF($G26<>"",IFERROR(IF('Inputs Fixture Fittings'!$D26<>"Default",'Inputs Fixture Fittings'!$F26*$G26,0.5*$G26),0),"") | J26: =IFERROR(IF(INDEX(inputsgrp_otv,MATCH(Logic!$A26,inputsgrp_no,0))<>"",INDEX(inputsgrp_otv,MATCH(Logic!$A26,inputsgrp_no,0)),""),"") | K26: =IF($J26<>"",IFERROR(IF('Inputs Fixture Fittings'!$D26<>"Default",'Inputs Fixture Fittings'!$E26*$J26,0.5*$J26),0),"") | L26: =IF($J26<>"",IFERROR(IF('Inputs Fixture Fittings'!$D26<>"Default",'Inputs Fixture Fittings'!$F26*$J26,0.5*$J26),0),"") | M26: =IFERROR(IF(INDEX(inputsgrp_otrc,MATCH(Logic!$A26,inputsgrp_no,0))<>"",INDEX(inputsgrp_otrc,MATCH(Logic!$A26,inputsgrp_no,0)),""),"") | N26: =IF($M26<>"",IFERROR(IF('Inputs Fixture Fittings'!$D26<>"Default",'Inputs Fixture Fittings'!$E26*$M26,0.5*$M26),0),"") | O26: =IF($M26<>"",IFERROR(IF('Inputs Fixture Fittings'!$D26<>"Default",'Inputs Fixture Fittings'!$F26*$M26,0.5*$M26),0),"") | P26: =IFERROR(IF(INDEX(inputsgrp_otstud,MATCH(Logic!$A26,inputsgrp_no,0))<>"",INDEX(inputsgrp_otstud,MATCH(Logic!$A26,inputsgrp_no,0)),""),"") | Q26: =IF($P26<>"",IFERROR(IF('Inputs Fixture Fittings'!$D26<>"Default",'Inputs Fixture Fittings'!$E26*$P26,0.5*$P26),0),"") | R26: =IF($P26<>"",IFERROR(IF('Inputs Fixture Fittings'!$D26<>"Default",'Inputs Fixture Fittings'!$F26*$P26,0.5*$P26),0),"") | S26: =IFERROR(IF(INDEX(inputsgrp_otres,MATCH(Logic!$A26,inputsgrp_no,0))<>"",INDEX(inputsgrp_otres,MATCH(Logic!$A26,inputsgrp_no,0)),""),"") | T26: =IF($S26<>"",IFERROR(IF('Inputs Fixture Fittings'!$D26<>"Default",'Inputs Fixture Fittings'!$E26*$S26,0.5*$S26),0),"") | U26: =IF($S26<>"",IFERROR(IF('Inputs Fixture Fittings'!$D26<>"Default",'Inputs Fixture Fittings'!$F26*$S26,0.5*$S26),0),"") | V26: =IFERROR(IF(INDEX(inputsgrp_otot,MATCH(Logic!$A26,inputsgrp_no,0))<>"",INDEX(inputsgrp_otot,MATCH(Logic!$A26,inputsgrp_no,0)),""),"") | W26: =IF($V26<>"",IFERROR(IF('Inputs Fixture Fittings'!$D26<>"Default",'Inputs Fixture Fittings'!$E26*$V26,0.5*$V26),0),"") | X26: =IF($V26<>"",IFERROR(IF('Inputs Fixture Fittings'!$D26<>"Default",'Inputs Fixture Fittings'!$F26*$V26,0.5*$V26),0),"")
A27: 12 | B27: =IFERROR(IF(INDEX(inputsgrp_gn,MATCH(Logic!$A27,inputsgrp_no,0))<>"",INDEX(inputsgrp_gn,MATCH(Logic!$A27,inputsgrp_no,0)),""),"") | D27: =IFERROR(IF(INDEX(inputsgrp_ada,MATCH(Logic!$A27,inputsgrp_no,0))<>"",INDEX(inputsgrp_ada,MATCH(Logic!$A27,inputsgrp_no,0)),""),"") | E27: =IFERROR(IF(INDEX(inputsgrp_urinal,MATCH(Logic!$A27,inputsgrp_no,0))<>"",INDEX(inputsgrp_urinal,MATCH(Logic!$A27,inputsgrp_no,0)),""),"") | F27: =IFERROR(IF(INDEX(inputsgrp_an,MATCH(Logic!$A27,inputsgrp_no,0))<>"",INDEX(inputsgrp_an,MATCH(Logic!$A27,inputsgrp_no,0)),""),"") | G27: =IFERROR(IF(INDEX(inputsgrp_otefte,MATCH(Logic!$A27,inputsgrp_no,0))<>"",INDEX(inputsgrp_otefte,MATCH(Logic!$A27,inputsgrp_no,0)),""),"") | H27: =IF($G27<>"",IFERROR(IF('Inputs Fixture Fittings'!$D27<>"Default",'Inputs Fixture Fittings'!$E27*$G27,0.5*$G27),0),"") | I27: =IF($G27<>"",IFERROR(IF('Inputs Fixture Fittings'!$D27<>"Default",'Inputs Fixture Fittings'!$F27*$G27,0.5*$G27),0),"") | J27: =IFERROR(IF(INDEX(inputsgrp_otv,MATCH(Logic!$A27,inputsgrp_no,0))<>"",INDEX(inputsgrp_otv,MATCH(Logic!$A27,inputsgrp_no,0)),""),"") | K27: =IF($J27<>"",IFERROR(IF('Inputs Fixture Fittings'!$D27<>"Default",'Inputs Fixture Fittings'!$E27*$J27,0.5*$J27),0),"") | L27: =IF($J27<>"",IFERROR(IF('Inputs Fixture Fittings'!$D27<>"Default",'Inputs Fixture Fittings'!$F27*$J27,0.5*$J27),0),"") | M27: =IFERROR(IF(INDEX(inputsgrp_otrc,MATCH(Logic!$A27,inputsgrp_no,0))<>"",INDEX(inputsgrp_otrc,MATCH(Logic!$A27,inputsgrp_no,0)),""),"") | N27: =IF($M27<>"",IFERROR(IF('Inputs Fixture Fittings'!$D27<>"Default",'Inputs Fixture Fittings'!$E27*$M27,0.5*$M27),0),"") | O27: =IF($M27<>"",IFERROR(IF('Inputs Fixture Fittings'!$D27<>"Default",'Inputs Fixture Fittings'!$F27*$M27,0.5*$M27),0),"") | P27: =IFERROR(IF(INDEX(inputsgrp_otstud,MATCH(Logic!$A27,inputsgrp_no,0))<>"",INDEX(inputsgrp_otstud,MATCH(Logic!$A27,inputsgrp_no,0)),""),"") | Q27: =IF($P27<>"",IFERROR(IF('Inputs Fixture Fittings'!$D27<>"Default",'Inputs Fixture Fittings'!$E27*$P27,0.5*$P27),0),"") | R27: =IF($P27<>"",IFERROR(IF('Inputs Fixture Fittings'!$D27<>"Default",'Inputs Fixture Fittings'!$F27*$P27,0.5*$P27),0),"") | S27: =IFERROR(IF(INDEX(inputsgrp_otres,MATCH(Logic!$A27,inputsgrp_no,0))<>"",INDEX(inputsgrp_otres,MATCH(Logic!$A27,inputsgrp_no,0)),""),"") | T27: =IF($S27<>"",IFERROR(IF('Inputs Fixture Fittings'!$D27<>"Default",'Inputs Fixture Fittings'!$E27*$S27,0.5*$S27),0),"") | U27: =IF($S27<>"",IFERROR(IF('Inputs Fixture Fittings'!$D27<>"Default",'Inputs Fixture Fittings'!$F27*$S27,0.5*$S27),0),"") | V27: =IFERROR(IF(INDEX(inputsgrp_otot,MATCH(Logic!$A27,inputsgrp_no,0))<>"",INDEX(inputsgrp_otot,MATCH(Logic!$A27,inputsgrp_no,0)),""),"") | W27: =IF($V27<>"",IFERROR(IF('Inputs Fixture Fittings'!$D27<>"Default",'Inputs Fixture Fittings'!$E27*$V27,0.5*$V27),0),"") | X27: =IF($V27<>"",IFERROR(IF('Inputs Fixture Fittings'!$D27<>"Default",'Inputs Fixture Fittings'!$F27*$V27,0.5*$V27),0),"")
... A45: 30 | B45: =IFERROR(IF(INDEX(inputsgrp_gn,MATCH(Logic!$A45,inputsgrp_no,0))<>"",INDEX(inputsgrp_gn,MATCH(Logic!$A45,inputsgrp_no,0)),""),"") | D45: =IFERROR(IF(INDEX(inputsgrp_ada,MATCH(Logic!$A45,inputsgrp_no,0))<>"",INDEX(inputsgrp_ada,MATCH(Logic!$A45,inputsgrp_no,0)),""),"") | E45: =IFERROR(IF(INDEX(inputsgrp_urinal,MATCH(Logic!$A45,inputsgrp_no,0))<>"",INDEX(inputsgrp_urinal,MATCH(Logic!$A45,inputsgrp_no,0)),""),"") | F45: =IFERROR(IF(INDEX(inputsgrp_an,MATCH(Logic!$A45,inputsgrp_no,0))<>"",INDEX(inputsgrp_an,MATCH(Logic!$A45,inputsgrp_no,0)),""),"") | G45: =IFERROR(IF(INDEX(inputsgrp_otefte,MATCH(Logic!$A45,inputsgrp_no,0))<>"",INDEX(inputsgrp_otefte,MATCH(Logic!$A45,inputsgrp_no,0)),""),"") | H45: =IF($G45<>"",IFERROR(IF('Inputs Fixture Fittings'!$D45<>"Default",'Inputs Fixture Fittings'!$E45*$G45,0.5*$G45),0),"") | I45: =IF($G45<>"",IFERROR(IF('Inputs Fixture Fittings'!$D45<>"Default",'Inputs Fixture Fittings'!$F45*$G45,0.5*$G45),0),"") | J45: =IFERROR(IF(INDEX(inputsgrp_otv,MATCH(Logic!$A45,inputsgrp_no,0))<>"",INDEX(inputsgrp_otv,MATCH(Logic!$A45,inputsgrp_no,0)),""),"") | K45: =IF($J45<>"",IFERROR(IF('Inputs Fixture Fittings'!$D45<>"Default",'Inputs Fixture Fittings'!$E45*$J45,0.5*$J45),0),"") | L45: =IF($J45<>"",IFERROR(IF('Inputs Fixture Fittings'!$D45<>"Default",'Inputs Fixture Fittings'!$F45*$J45,0.5*$J45),0),"") | M45: =IFERROR(IF(INDEX(inputsgrp_otrc,MATCH(Logic!$A45,inputsgrp_no,0))<>"",INDEX(inputsgrp_otrc,MATCH(Logic!$A45,inputsgrp_no,0)),""),"") | N45: =IF($M45<>"",IFERROR(IF('Inputs Fixture Fittings'!$D45<>"Default",'Inputs Fixture Fittings'!$E45*$M45,0.5*$M45),0),"") | O45: =IF($M45<>"",IFERROR(IF('Inputs Fixture Fittings'!$D45<>"Default",'Inputs Fixture Fittings'!$F45*$M45,0.5*$M45),0),"") | P45: =IFERROR(IF(INDEX(inputsgrp_otstud,MATCH(Logic!$A45,inputsgrp_no,0))<>"",INDEX(inputsgrp_otstud,MATCH(Logic!$A45,inputsgrp_no,0)),""),"") | Q45: =IF($P45<>"",IFERROR(IF('Inputs Fixture Fittings'!$D45<>"Default",'Inputs Fixture Fittings'!$E45*$P45,0.5*$P45),0),"") | R45: =IF($P45<>"",IFERROR(IF('Inputs Fixture Fittings'!$D45<>"Default",'Inputs Fixture Fittings'!$F45*$P45,0.5*$P45),0),"") | S45: =IFERROR(IF(INDEX(inputsgrp_otres,MATCH(Logic!$A45,inputsgrp_no,0))<>"",INDEX(inputsgrp_otres,MATCH(Logic!$A45,inputsgrp_no,0)),""),"") | T45: =IF($S45<>"",IFERROR(IF('Inputs Fixture Fittings'!$D45<>"Default",'Inputs Fixture Fittings'!$E45*$S45,0.5*$S45),0),"") | U45: =IF($S45<>"",IFERROR(IF('Inputs Fixture Fittings'!$D45<>"Default",'Inputs Fixture Fittings'!$F45*$S45,0.5*$S45),0),"") | V45: =IFERROR(IF(INDEX(inputsgrp_otot,MATCH(Logic!$A45,inputsgrp_no,0))<>"",INDEX(inputsgrp_otot,MATCH(Logic!$A45,inputsgrp_no,0)),""),"") | W45: =IF($V45<>"",IFERROR(IF('Inputs Fixture Fittings'!$D45<>"Default",'Inputs Fixture Fittings'!$E45*$V45,0.5*$V45),0),"") | X45: =IF($V45<>"",IFERROR(IF('Inputs Fixture Fittings'!$D45<>"Default",'Inputs Fixture Fittings'!$F45*$V45,0.5*$V45),0),"")
Y46: Click + to left for additional rows
A47: 31 | B47: =IFERROR(IF(INDEX(inputsgrp_gn,MATCH(Logic!$A47,inputsgrp_no,0))<>"",INDEX(inputsgrp_gn,MATCH(Logic!$A47,inputsgrp_no,0)),""),"") | D47: =IFERROR(IF(INDEX(inputsgrp_ada,MATCH(Logic!$A47,inputsgrp_no,0))<>"",INDEX(inputsgrp_ada,MATCH(Logic!$A47,inputsgrp_no,0)),""),"") | E47: =IFERROR(IF(INDEX(inputsgrp_urinal,MATCH(Logic!$A47,inputsgrp_no,0))<>"",INDEX(inputsgrp_urinal,MATCH(Logic!$A47,inputsgrp_no,0)),""),"") | F47: =IFERROR(IF(INDEX(inputsgrp_an,MATCH(Logic!$A47,inputsgrp_no,0))<>"",INDEX(inputsgrp_an,MATCH(Logic!$A47,inputsgrp_no,0)),""),"") | G47: =IFERROR(IF(INDEX(inputsgrp_otefte,MATCH(Logic!$A47,inputsgrp_no,0))<>"",INDEX(inputsgrp_otefte,MATCH(Logic!$A47,inputsgrp_no,0)),""),"") | H47: =IF($G47<>"",IFERROR(IF('Inputs Fixture Fittings'!$D47<>"Default",'Inputs Fixture Fittings'!$E47*$G47,0.5*$G47),0),"") | I47: =IF($G47<>"",IFERROR(IF('Inputs Fixture Fittings'!$D47<>"Default",'Inputs Fixture Fittings'!$F47*$G47,0.5*$G47),0),"") | J47: =IFERROR(IF(INDEX(inputsgrp_otv,MATCH(Logic!$A47,inputsgrp_no,0))<>"",INDEX(inputsgrp_otv,MATCH(Logic!$A47,inputsgrp_no,0)),""),"") | K47: =IF($J47<>"",IFERROR(IF('Inputs Fixture Fittings'!$D47<>"Default",'Inputs Fixture Fittings'!$E47*$J47,0.5*$J47),0),"") | L47: =IF($J47<>"",IFERROR(IF('Inputs Fixture Fittings'!$D47<>"Default",'Inputs Fixture Fittings'!$F47*$J47,0.5*$J47),0),"") | M47: =IFERROR(IF(INDEX(inputsgrp_otrc,MATCH(Logic!$A47,inputsgrp_no,0))<>"",INDEX(inputsgrp_otrc,MATCH(Logic!$A47,inputsgrp_no,0)),""),"") | N47: =IF($M47<>"",IFERROR(IF('Inputs Fixture Fittings'!$D47<>"Default",'Inputs Fixture Fittings'!$E47*$M47,0.5*$M47),0),"") | O47: =IF($M47<>"",IFERROR(IF('Inputs Fixture Fittings'!$D47<>"Default",'Inputs Fixture Fittings'!$F47*$M47,0.5*$M47),0),"") | P47: =IFERROR(IF(INDEX(inputsgrp_otstud,MATCH(Logic!$A47,inputsgrp_no,0))<>"",INDEX(inputsgrp_otstud,MATCH(Logic!$A47,inputsgrp_no,0)),""),"") | Q47: =IF($P47<>"",IFERROR(IF('Inputs Fixture Fittings'!$D47<>"Default",'Inputs Fixture Fittings'!$E47*$P47,0.5*$P47),0),"") | R47: =IF($P47<>"",IFERROR(IF('Inputs Fixture Fittings'!$D47<>"Default",'Inputs Fixture Fittings'!$F47*$P47,0.5*$P47),0),"") | S47: =IFERROR(IF(INDEX(inputsgrp_otres,MATCH(Logic!$A47,inputsgrp_no,0))<>"",INDEX(inputsgrp_otres,MATCH(Logic!$A47,inputsgrp_no,0)),""),"") | T47: =IF($S47<>"",IFERROR(IF('Inputs Fixture Fittings'!$D47<>"Default",'Inputs Fixture Fittings'!$E47*$S47,0.5*$S47),0),"") | U47: =IF($S47<>"",IFERROR(IF('Inputs Fixture Fittings'!$D47<>"Default",'Inputs Fixture Fittings'!$F47*$S47,0.5*$S47),0),"") | V47: =IFERROR(IF(INDEX(inputsgrp_otot,MATCH(Logic!$A47,inputsgrp_no,0))<>"",INDEX(inputsgrp_otot,MATCH(Logic!$A47,inputsgrp_no,0)),""),"") | W47: =IF($V47<>"",IFERROR(IF('Inputs Fixture Fittings'!$D47<>"Default",'Inputs Fixture Fittings'!$E47*$V47,0.5*$V47),0),"") | X47: =IF($V47<>"",IFERROR(IF('Inputs Fixture Fittings'!$D47<>"Default",'Inputs Fixture Fittings'!$F47*$V47,0.5*$V47),0),"")
