Workbook
Name baseEnvelopeCooling: Inputs!$E$399
Name baselineEnvelopeCooling: Inputs!$E$399
Name baselineEnvelopeHeating: Inputs!$D$399
Name baselineSimCooling: Inputs!$E$417
Name baselineSimHeating: Inputs!$D$417
Name baselineVentCooling: Inputs!$E$408
Name baselineVentHeating: Inputs!$D$408
Name buildingType: Inputs!$E$8
Name cz: Inputs!$E$12
Name envelopeLoadsReduction: Logic!$F$399
Name envelopeTradeOffCredits: Logic!$G$399
Name heatRecoveryRequirement: Logic!$F$140
Name inputs_EquipNo: Inputs!$A$22:$A$136
Name inputs_EquipTag: Inputs!$B$22:$B$136
Name inputs_EquipType: Inputs!$C$22:$C$136
Name inputs_HeatRecReq: Inputs!$G$22:$G$136
Name inputs_optpath: Inputs!$E$6
Name inputs_OutdoorAirFlow: Inputs!$E$22:$E$136
Name inputs_pkclid: Inputs!$B$274:$B$384
Name inputs_pkclno: Inputs!$A$274:$A$384
Name inputs_pkclpl: Inputs!$D$274:$D$384
Name inputs_pkclst: Inputs!$C$274:$C$384
Name inputs_pkclty: Inputs!$E$274:$E$384
Name inputs_pkhtid: Inputs!$B$150:$B$264
Name inputs_pkhtno: Inputs!$A$150:$A$264
Name inputs_pkhtpl: Inputs!$D$150:$D$264
Name inputs_pkhtst: Inputs!$C$150:$C$264
Name inputs_pkhtty: Inputs!$E$150:$E$264
Name inputs_VentEquipQuant: Inputs!$D$22:$D$136
Name logic_EquipNo: Logic!$A$22:$A$136
Name logic_optpath: Logic!$E$6
Name logic_VentFlow: Logic!$F$22:$F$136
Name MPF: Logic!$F$408
Name option4path2credits: Summary!$G$18
Name optpath: Database!$D$7:$D$13
Name performanceIndex: Logic!$F$417
Name proposedEnvelopeCooling: Inputs!$C$399
Name proposedEnvelopeHeating: Inputs!$B$399
Name proposedSimCooling: Inputs!$C$417
Name proposedSimHeating: Inputs!$B$417
Name proposedVentCooling: Inputs!$C$408
Name proposedVentHeating: Inputs!$B$408
Name residential: Logic!$E$8
Name totalCompliantVentAirFlow: Logic!$F$138
Name totalVentAirFlow: Logic!$F$137
Name units: Inputs!$E$10
Name ventLoadsReduction: Logic!$G$408
Name ventNonCompliantPercentage: Logic!$F$139
Name ventTradeOffCredits: Logic!$H$408
Name yesNoList: Database!$D$61:$D$62

Sheet Revision History
A1: Draft Calculator Revision History | H1: TASKS
A3: Date | B3: Party | C3: Tab Edited | D3: Field Edited | E3: Description | F3: Related TASK No. | H3: No. | I3: Date Complete | J3: Tab Edited | K3: Source File
A4: 45881 | B4: WSP | C4: ALL | D4: ALL | E4: Templatized | F4: NA | H4: 1 | J4: Make sure to create named fields (Formulas > Name Manager) and use formulas using named field values (note be sure to delete unused names from the template document)
H5: 2 | J5: Make sure all credit calculation requirements are included
H6: 3 | J6: Make sure formulas work, values correct, validation included where needed (i.e. positive numbers only, etc.)
H7: 4 | J7: Make sure labels are correct (including make explicit where inputs are required or optional)
H8: 5 | J8: QC Cell Formatting (see internal style guide)
H9: 6 | J9: Add Notes where needed
H10: 7 | J10: Add summary "Point calculation" tab
H11: 8 | J11: Update instructions tab
H12: 9 | J12: Add flags as needed (i.e. for CFCs, IDC BDC >700 GWP)
H13: 10 | J13: Allow Add rows without macros, include instructions (NOTE prior calculator drafts have used Groups, welcome other recommendations)
H14: 11 | J14: Update formatting per USGBC (including If required create named fields; If guidance says use tables, convert to tables)
H15: 12 | J15: Spell Check
H16: 13 | J16: Final Lock Settings and QC

Sheet Internal Style Guide
B2: Internal Style Guide
B4: TEMP LOCK PASSWORD | E4: LEED
B5: Workbook Structure | E5: Inputs Tab: User input AND final summary values only, can have some automatic input cells IF important for user data, can have multiple inputs tabs if needed
E6: Logic Tab: Calculations for values needed for LEED Performance, no user input, will be hidden from users
E7: Database Tab: Constants, values for logic calculations, points, limit to static values no formulas where possible, will be hidden from users
E8: Summary Tab: Points, values needed for LEED performance (see Reference Guide Documentation requirements for what needs to be included)
E9: Note calculators must use Formula > Name Manager to name fields and cells that are used for calculations or pulled into other cells. Recommend developing full calculator structure and initial formulas before naming fields and updating formulas.
B10: General Sheet Formating | E10: Turn-off view gridlines
E11: Columns to left and right of boarder to be Width of 3.5 (42 pxl)
E12: Rows above and below boarder to be Height of 20 (34 pxl)
B13: Sheet Background Fill | E13: #F7F8F6; fill up to row 300, 600, or 900 as needed; fill up to column Z
B14: Instructions + Summary Background Fill | E14: #FFFFFF
B15: Title Fill | E15: IP | F15: #952713
E16: LT | F16: #B87400
E17: SS | F17: #536426
E18: WE | F18: #006570
E19: EA | F19: #C75127
E20: MR | F20: #7C4901
E21: EQ | F21: #684659
E22: PR | F22: #7E8AA2
B23: Title Format | E23: Use downloadable PNG logo w and maintain aspect ratio in all cases. Logo must never be more than 1 inch (72 pixels) wide.
E24: Suggest standard header height of 90.0 (150 pxl) with an increase to 95.0 (160 pxl) prerequisite and credit combo.
E25: Note naming convention (see below for example):
F26: USGBC Calculator || LEED for Building Operations and Maintenance [14 point font, bold] LEED v5 EAp4: Fundamental Refigerant Management [12 point font, bold] LEED v5 EAc3: Enhanced Refrigerant Management Performance [12 point font, bold] SHEET NAME (I.E. INPUTS, LOGIC, DATABASE, SUMMARY) [12 point font, bold]
B27: Cell Outline | E27: Automatic, Default Weight
B28: Standard Row Width | E28: 18.0 (30 pxls)
B29: Text Alignment | E29: Left, Vertical Center
B30: Number Formatting | E30: All numbers left justified, text right justified
D31: 1000 | E31: CONFIRM WHICH DATA USES THIS FORMAT
D32: 1.1 | E32: CONFIRM WHICH DATA USES THIS FORMAT
D33: 0.011 | E33: CONFIRM WHICH DATA USES THIS FORMAT
B34: Font | D34: Headings | E34: Arial 11 Bold UPPERCASE
D35: Subheading | E35: Arial 10 Bold
D36: Text | E36: Arial 10
E37: HEADING | F37: FILL HEX #353434, TEXT HEX # F7F8F6
E38: Subheading | F38: FILL FOR SUBHEADING CELLS HEX #B6B7B8 CENTER ALL HEADERS
E39: Manual input | F39: FILL FOR USER INPUT CELLS HEX #000000
E40: Auto input | F40: FILL FOR AUTOMATIC CELLS HEX #F2F2F2
E41: Calculation | F41: FILL FOR AUTOMATIC CELLS HEX #D9D9D9 Database and logic only
E42: Supplemental instructions
...

Sheet Instructions
B2: LEED v5 Reduce Peak Thermal Loads Calculator LEED for Building Design and Construction Instructions
C5: CREDIT INSTRUCTIONS
C7: EAc2 Reduce Peak Thermal Loads
D9: ▪ | E9: For All Options: the building envelope must meet the requirements of ASHRAE 90.1, Section 5.5, Prescriptive Building Envelope Compliance Path or ASHRAE 90.1, Section 5.6, Building Envelope Trade-Off Compliance Path per the version of ASHRAE 90.1 referenced in EAp2 Minimum Energy Efficiency. Building envelope efficiency shall not be traded off with other building systems
D11: ▪ | E11: Option 2. Ventilation Energy Recovery Requirements:
E12: ▪ | F12: Each fan system supplying outdoor air must have an energy or heat recovery system with a minimum 70% enthalpy recovery ratio or a minimum of 75% sensible heat recovery ratio. Provisions must be made to bypass or control the energy recovery system during moderate outside air conditions.
E13: ▪ | F13: In aggregate, fan systems supplying less than 15% of the project’s total outdoor air can be excluded.
E14: ▪ | F14: Fan systems must supply a minimum of 50% of the ventilation air required for the project per ASHRAE Standard 62.1-2022, Ventilation Rate Procedure, to qualify for this option.
D16: ▪ | E16: Option 4. Peak Thermal Load Reductions Requirements:
E17: ▪ | F17: Ventilation loads must be included in the determination of peak coincident loads
E18: ▪ | F18: Measure building envelope air leakage using air leakage testing and use the measured air leakage to calculate the peak loads for Path 2 or Path 3.
E19: ▪ | F19: Demonstrate balanced ventilation meeting the criteria in Option 1 above.
E20: ▪ | F20: For Path 2. ASHRAE 90.1 Trade-off Methods: Calculate the improvement in peak thermal loads due to envelope and/or ventilation changes between the baseline and proposed.
E21: ▪ | F21: For Path 3. Energy Simulation: Calculate the improvement in peak thermal loads over a baseline based on an energy simulation.
C24: INPUT INSTRUCTIONS
E26: User input cell formatting.
E27: Automatic input cell formatting.
E28: Calculation cell formatting.
C30: All input cells are required unless otherwise noted.
C31: Project teams must fill out input cells from top section rows.
D33: 1 | E33: Input General Information for the project, including Credit Option and Pathway, Building Type, and Unit System.
D35: 2 | E35: Fill in ventilation and exhaust equipment tables for Option 2.
E36: Optional fields for this option:
F37: ▪ Equipment Type. Inputs type of ventilation equipment.
E38: Required fields for this option:
F39: ▪ Equipment Tag Name. Unique name for each ventilation equipment based on design documents.
F40: ▪ Equipment Quantity. Number of pieces of this type of equipment are in the project.
F41: ▪ Outdoor Air Flow per Individual Equipment. Design outdoor air flow for the ventilation equipment type.
F42: ▪ Does ventilation equipment have a qualifying heat or energy recovery system? Indicate whether the equipment has a qualifying energy/heat recovery system associated with it (refer to the instructions above).
D44: 3 | E44: List Peak Heating and Cooling Loads by System. (Optional)
E45: This step is optional for those users looking for assistance determining the peak coincident and non-coincident loads based on the individual systems in their project scope. Fields below apply to both Peak Heating By System and Peak Cooling By System tables.
E46: Optional fields:
F47: ▪ System ID. Indicate System ID based on design documents.
F48: ▪ System Type. Indicate System ID based on design documents.
F49: ▪ Peak Load. Indicate peak heating or cooling load for each system.
F50: ▪ Time of year. Indicate day of the year the system's peak loading occurs. Input as MM/YY.
D52: 4 | E52: Enter compliance with Option 4. Peak Thermal Load Reductions.
E53: Included ventilation loads in the determination of peak coincident loads. If during the construction phase, use measured air leakage to calculate the peak loads.
E54: Required fields for this option:
F55: ▪ Proposed Envelope Sum of the System Peak Heating Loads. The peak heating load for the proposed design.
...

Sheet Inputs
B2: LEED v5 Reduce Peak Thermal Loads Calculator LEED for Building Design and Construction Inputs
B4: STEP 1: GENERAL INFORMATION
B6: Credit Option and Pathway
B8: Building Type | G8: Required for Option 4 Path 2 only
B10: Units
B12: ASHRAE Climate Zone
B15: STEP 2: COMPLIANCE WITH OPTION 2. VENTILATION ENERGY RECOVERY SYSTEMS
B17: Click + to the left to add additional rows. Click - to the left to collapse (content will be saved).
B18: Ventilation Equipment Table
B19: Equipment Tag Name | C19: Equipment Type (Optional) | D19: Equipment Quantity | E19: =_xlfn.CONCAT("Outdoor Air Flow per Individual Equipment ",IF(units="SI","(L/s)","(cfm)")) -> Outdoor Air Flow per Individual Equipment (cfm) | F19: =_xlfn.CONCAT("Total Outdoor Air Flow ",IF(units="SI","(L/s)","(cfm)")) -> Total Outdoor Air Flow (cfm) | G19: Does ventilation equipment have a qualifying heat or energy recovery system?
A22: 1 | F22: =INDEX(logic_VentFlow,MATCH($A22,logic_EquipNo,0))
A23: 2 | F23: =INDEX(logic_VentFlow,MATCH($A23,logic_EquipNo,0))
A24: 3 | F24: =INDEX(logic_VentFlow,MATCH($A24,logic_EquipNo,0))
A25: 4 | F25: =INDEX(logic_VentFlow,MATCH($A25,logic_EquipNo,0))
A26: 5 | F26: =INDEX(logic_VentFlow,MATCH($A26,logic_EquipNo,0))
A27: 6 | F27: =INDEX(logic_VentFlow,MATCH($A27,logic_EquipNo,0))
A28: 7 | F28: =INDEX(logic_VentFlow,MATCH($A28,logic_EquipNo,0))
A29: 8 | F29: =INDEX(logic_VentFlow,MATCH($A29,logic_EquipNo,0))
A30: 9 | F30: =INDEX(logic_VentFlow,MATCH($A30,logic_EquipNo,0))
A31: 10 | F31: =INDEX(logic_VentFlow,MATCH($A31,logic_EquipNo,0)) | I31: Click + to left for additional rows
A32: 11 | F32: =INDEX(logic_VentFlow,MATCH($A32,logic_EquipNo,0))
A33: 12 | F33: =INDEX(logic_VentFlow,MATCH($A33,logic_EquipNo,0))
A34: 13 | F34: =INDEX(logic_VentFlow,MATCH($A34,logic_EquipNo,0))
A35: 14 | F35: =INDEX(logic_VentFlow,MATCH($A35,logic_EquipNo,0))
A36: 15 | F36: =INDEX(logic_VentFlow,MATCH($A36,logic_EquipNo,0))
A37: 16 | F37: =INDEX(logic_VentFlow,MATCH($A37,logic_EquipNo,0))
A38: 17 | F38: =INDEX(logic_VentFlow,MATCH($A38,logic_EquipNo,0))
A39: 18 | F39: =INDEX(logic_VentFlow,MATCH($A39,logic_EquipNo,0))
A40: 19 | F40: =INDEX(logic_VentFlow,MATCH($A40,logic_EquipNo,0))
A41: 20 | F41: =INDEX(logic_VentFlow,MATCH($A41,logic_EquipNo,0))
A42: 21 | F42: =INDEX(logic_VentFlow,MATCH($A42,logic_EquipNo,0))
A43: 22 | F43: =INDEX(logic_VentFlow,MATCH($A43,logic_EquipNo,0))
... A51: 30 | F51: =INDEX(logic_VentFlow,MATCH($A51,logic_EquipNo,0))
A52: 31 | F52: =INDEX(logic_VentFlow,MATCH($A52,logic_EquipNo,0)) | I52: Click + to left for additional rows
A53: 32 | F53: =INDEX(logic_VentFlow,MATCH($A53,logic_EquipNo,0))
A54: 33 | F54: =INDEX(logic_VentFlow,MATCH($A54,logic_EquipNo,0))
A55: 34 | F55: =INDEX(logic_VentFlow,MATCH($A55,logic_EquipNo,0))
A56: 35 | F56: =INDEX(logic_VentFlow,MATCH($A56,logic_EquipNo,0))
A57: 36 | F57: =INDEX(logic_VentFlow,MATCH($A57,logic_EquipNo,0))
A58: 37 | F58: =INDEX(logic_VentFlow,MATCH($A58,logic_EquipNo,0))
...

Sheet Logic
B2: LEED v5 Reduce Peak Thermal Loads Calculator BD+C LEED for Building Design and Construction Logic
B4: LOGIC 1: GENERAL INFORMATION
B6: Credit Option and Pathway | E6: =IF(inputs_optpath<>"",inputs_optpath,"")
B8: Residential Building? | E8: =IF(OR(buildingType="Hotel/Motel", buildingType="Apartment/Dormitory"),TRUE,FALSE) -> FALSE
B10: Units | E10: =units -> 0
B12: ASHRAE Climate Zone | E12: =cz -> 0
B15: LOGIC 2: COMPLIANCE WITH OPTION 2. VENTILATION ENERGY RECOVERY SYSTEMS
B17: Click + to the left to add additional rows. Click - to the left to collapse (content will be saved).
B18: Ventilation Equipment Table
B19: Equipment Tag Name | C19: Equipment Type (Optional) | D19: Equipment Quantity | E19: =_xlfn.CONCAT("Outdoor Air Flow per individual equipment ",IF(units="SI","(L/s)","(cfm)")) -> Outdoor Air Flow per individual equipment (cfm) | F19: =_xlfn.CONCAT("Total Outdoor Air Flow ",IF(units="SI","(L/s)","(cfm)")) -> Total Outdoor Air Flow (cfm) | G19: Does ventilation equipment have a qualifying heat or energy recovery system?
A22: 1 | B22: =IF(INDEX(inputs_EquipTag,MATCH(Logic!$A22,inputs_EquipNo,0))<>"",INDEX(inputs_EquipTag,MATCH(Logic!$A22,inputs_EquipNo,0)),"") | C22: =IF(INDEX(inputs_EquipType,MATCH(Logic!$A22,inputs_EquipNo,0))<>"",INDEX(inputs_EquipType,MATCH(Logic!$A22,inputs_EquipNo,0)),"") | D22: =IF(INDEX(inputs_VentEquipQuant,MATCH(Logic!$A22,inputs_EquipNo,0))<>"",INDEX(inputs_VentEquipQuant,MATCH(Logic!$A22,inputs_EquipNo,0)),"") | E22: =IF(INDEX(inputs_OutdoorAirFlow,MATCH(Logic!$A22,inputs_EquipNo,0))<>"",INDEX(inputs_OutdoorAirFlow,MATCH(Logic!$A22,inputs_EquipNo,0)),"") | F22: =IFERROR(IF(ISBLANK(B22),"",D22*E22),"") | G22: =IF(INDEX(inputs_HeatRecReq,MATCH(Logic!$A22,inputs_EquipNo,0))<>"",INDEX(inputs_HeatRecReq,MATCH(Logic!$A22,inputs_EquipNo,0)),"")
A23: 2 | B23: =IF(INDEX(inputs_EquipTag,MATCH(Logic!$A23,inputs_EquipNo,0))<>"",INDEX(inputs_EquipTag,MATCH(Logic!$A23,inputs_EquipNo,0)),"") | C23: =IF(INDEX(inputs_EquipType,MATCH(Logic!$A23,inputs_EquipNo,0))<>"",INDEX(inputs_EquipType,MATCH(Logic!$A23,inputs_EquipNo,0)),"") | D23: =IF(INDEX(inputs_VentEquipQuant,MATCH(Logic!$A23,inputs_EquipNo,0))<>"",INDEX(inputs_VentEquipQuant,MATCH(Logic!$A23,inputs_EquipNo,0)),"") | E23: =IF(INDEX(inputs_OutdoorAirFlow,MATCH(Logic!$A23,inputs_EquipNo,0))<>"",INDEX(inputs_OutdoorAirFlow,MATCH(Logic!$A23,inputs_EquipNo,0)),"") | F23: =IFERROR(IF(ISBLANK(B23),"",D23*E23),"") | G23: =IF(INDEX(inputs_HeatRecReq,MATCH(Logic!$A23,inputs_EquipNo,0))<>"",INDEX(inputs_HeatRecReq,MATCH(Logic!$A23,inputs_EquipNo,0)),"")
A24: 3 | B24: =IF(INDEX(inputs_EquipTag,MATCH(Logic!$A24,inputs_EquipNo,0))<>"",INDEX(inputs_EquipTag,MATCH(Logic!$A24,inputs_EquipNo,0)),"") | C24: =IF(INDEX(inputs_EquipType,MATCH(Logic!$A24,inputs_EquipNo,0))<>"",INDEX(inputs_EquipType,MATCH(Logic!$A24,inputs_EquipNo,0)),"") | D24: =IF(INDEX(inputs_VentEquipQuant,MATCH(Logic!$A24,inputs_EquipNo,0))<>"",INDEX(inputs_VentEquipQuant,MATCH(Logic!$A24,inputs_EquipNo,0)),"") | E24: =IF(INDEX(inputs_OutdoorAirFlow,MATCH(Logic!$A24,inputs_EquipNo,0))<>"",INDEX(inputs_OutdoorAirFlow,MATCH(Logic!$A24,inputs_EquipNo,0)),"") | F24: =IFERROR(IF(ISBLANK(B24),"",D24*E24),"") | G24: =IF(INDEX(inputs_HeatRecReq,MATCH(Logic!$A24,inputs_EquipNo,0))<>"",INDEX(inputs_HeatRecReq,MATCH(Logic!$A24,inputs_EquipNo,0)),"")
A25: 4 | B25: =IF(INDEX(inputs_EquipTag,MATCH(Logic!$A25,inputs_EquipNo,0))<>"",INDEX(inputs_EquipTag,MATCH(Logic!$A25,inputs_EquipNo,0)),"") | C25: =IF(INDEX(inputs_EquipType,MATCH(Logic!$A25,inputs_EquipNo,0))<>"",INDEX(inputs_EquipType,MATCH(Logic!$A25,inputs_EquipNo,0)),"") | D25: =IF(INDEX(inputs_VentEquipQuant,MATCH(Logic!$A25,inputs_EquipNo,0))<>"",INDEX(inputs_VentEquipQuant,MATCH(Logic!$A25,inputs_EquipNo,0)),"") | E25: =IF(INDEX(inputs_OutdoorAirFlow,MATCH(Logic!$A25,inputs_EquipNo,0))<>"",INDEX(inputs_OutdoorAirFlow,MATCH(Logic!$A25,inputs_EquipNo,0)),"") | F25: =IFERROR(IF(ISBLANK(B25),"",D25*E25),"") | G25: =IF(INDEX(inputs_HeatRecReq,MATCH(Logic!$A25,inputs_EquipNo,0))<>"",INDEX(inputs_HeatRecReq,MATCH(Logic!$A25,inputs_EquipNo,0)),"")
A26: 5 | B26: =IF(INDEX(inputs_EquipTag,MATCH(Logic!$A26,inputs_EquipNo,0))<>"",INDEX(inputs_EquipTag,MATCH(Logic!$A26,inputs_EquipNo,0)),"") | C26: =IF(INDEX(inputs_EquipType,MATCH(Logic!$A26,inputs_EquipNo,0))<>"",INDEX(inputs_EquipType,MATCH(Logic!$A26,inputs_EquipNo,0)),"") | D26: =IF(INDEX(inputs_VentEquipQuant,MATCH(Logic!$A26,inputs_EquipNo,0))<>"",INDEX(inputs_VentEquipQuant,MATCH(Logic!$A26,inputs_EquipNo,0)),"") | E26: =IF(INDEX(inputs_OutdoorAirFlow,MATCH(Logic!$A26,inputs_EquipNo,0))<>"",INDEX(inputs_OutdoorAirFlow,MATCH(Logic!$A26,inputs_EquipNo,0)),"") | F26: =IFERROR(IF(ISBLANK(B26),"",D26*E26),"") | G26: =IF(INDEX(inputs_HeatRecReq,MATCH(Logic!$A26,inputs_EquipNo,0))<>"",INDEX(inputs_HeatRecReq,MATCH(Logic!$A26,inputs_EquipNo,0)),"")
A27: 6 | B27: =IF(INDEX(inputs_EquipTag,MATCH(Logic!$A27,inputs_EquipNo,0))<>"",INDEX(inputs_EquipTag,MATCH(Logic!$A27,inputs_EquipNo,0)),"") | C27: =IF(INDEX(inputs_EquipType,MATCH(Logic!$A27,inputs_EquipNo,0))<>"",INDEX(inputs_EquipType,MATCH(Logic!$A27,inputs_EquipNo,0)),"") | D27: =IF(INDEX(inputs_VentEquipQuant,MATCH(Logic!$A27,inputs_EquipNo,0))<>"",INDEX(inputs_VentEquipQuant,MATCH(Logic!$A27,inputs_EquipNo,0)),"") | E27: =IF(INDEX(inputs_OutdoorAirFlow,MATCH(Logic!$A27,inputs_EquipNo,0))<>"",INDEX(inputs_OutdoorAirFlow,MATCH(Logic!$A27,inputs_EquipNo,0)),"") | F27: =IFERROR(IF(ISBLANK(B27),"",D27*E27),"") | G27: =IF(INDEX(inputs_HeatRecReq,MATCH(Logic!$A27,inputs_EquipNo,0))<>"",INDEX(inputs_HeatRecReq,MATCH(Logic!$A27,inputs_EquipNo,0)),"")
A28: 7 | B28: =IF(INDEX(inputs_EquipTag,MATCH(Logic!$A28,inputs_EquipNo,0))<>"",INDEX(inputs_EquipTag,MATCH(Logic!$A28,inputs_EquipNo,0)),"") | C28: =IF(INDEX(inputs_EquipType,MATCH(Logic!$A28,inputs_EquipNo,0))<>"",INDEX(inputs_EquipType,MATCH(Logic!$A28,inputs_EquipNo,0)),"") | D28: =IF(INDEX(inputs_VentEquipQuant,MATCH(Logic!$A28,inputs_EquipNo,0))<>"",INDEX(inputs_VentEquipQuant,MATCH(Logic!$A28,inputs_EquipNo,0)),"") | E28: =IF(INDEX(inputs_OutdoorAirFlow,MATCH(Logic!$A28,inputs_EquipNo,0))<>"",INDEX(inputs_OutdoorAirFlow,MATCH(Logic!$A28,inputs_EquipNo,0)),"") | F28: =IFERROR(IF(ISBLANK(B28),"",D28*E28),"") | G28: =IF(INDEX(inputs_HeatRecReq,MATCH(Logic!$A28,inputs_EquipNo,0))<>"",INDEX(inputs_HeatRecReq,MATCH(Logic!$A28,inputs_EquipNo,0)),"")
A29: 8 | B29: =IF(INDEX(inputs_EquipTag,MATCH(Logic!$A29,inputs_EquipNo,0))<>"",INDEX(inputs_EquipTag,MATCH(Logic!$A29,inputs_EquipNo,0)),"") | C29: =IF(INDEX(inputs_EquipType,MATCH(Logic!$A29,inputs_EquipNo,0))<>"",INDEX(inputs_EquipType,MATCH(Logic!$A29,inputs_EquipNo,0)),"") | D29: =IF(INDEX(inputs_VentEquipQuant,MATCH(Logic!$A29,inputs_EquipNo,0))<>"",INDEX(inputs_VentEquipQuant,MATCH(Logic!$A29,inputs_EquipNo,0)),"") | E29: =IF(INDEX(inputs_OutdoorAirFlow,MATCH(Logic!$A29,inputs_EquipNo,0))<>"",INDEX(inputs_OutdoorAirFlow,MATCH(Logic!$A29,inputs_EquipNo,0)),"") | F29: =IFERROR(IF(ISBLANK(B29),"",D29*E29),"") | G29: =IF(INDEX(inputs_HeatRecReq,MATCH(Logic!$A29,inputs_EquipNo,0))<>"",INDEX(inputs_HeatRecReq,MATCH(Logic!$A29,inputs_EquipNo,0)),"")
A30: 9 | B30: =IF(INDEX(inputs_EquipTag,MATCH(Logic!$A30,inputs_EquipNo,0))<>"",INDEX(inputs_EquipTag,MATCH(Logic!$A30,inputs_EquipNo,0)),"") | C30: =IF(INDEX(inputs_EquipType,MATCH(Logic!$A30,inputs_EquipNo,0))<>"",INDEX(inputs_EquipType,MATCH(Logic!$A30,inputs_EquipNo,0)),"") | D30: =IF(INDEX(inputs_VentEquipQuant,MATCH(Logic!$A30,inputs_EquipNo,0))<>"",INDEX(inputs_VentEquipQuant,MATCH(Logic!$A30,inputs_EquipNo,0)),"") | E30: =IF(INDEX(inputs_OutdoorAirFlow,MATCH(Logic!$A30,inputs_EquipNo,0))<>"",INDEX(inputs_OutdoorAirFlow,MATCH(Logic!$A30,inputs_EquipNo,0)),"") | F30: =IFERROR(IF(ISBLANK(B30),"",D30*E30),"") | G30: =IF(INDEX(inputs_HeatRecReq,MATCH(Logic!$A30,inputs_EquipNo,0))<>"",INDEX(inputs_HeatRecReq,MATCH(Logic!$A30,inputs_EquipNo,0)),"")
A31: 10 | B31: =IF(INDEX(inputs_EquipTag,MATCH(Logic!$A31,inputs_EquipNo,0))<>"",INDEX(inputs_EquipTag,MATCH(Logic!$A31,inputs_EquipNo,0)),"") | C31: =IF(INDEX(inputs_EquipType,MATCH(Logic!$A31,inputs_EquipNo,0))<>"",INDEX(inputs_EquipType,MATCH(Logic!$A31,inputs_EquipNo,0)),"") | D31: =IF(INDEX(inputs_VentEquipQuant,MATCH(Logic!$A31,inputs_EquipNo,0))<>"",INDEX(inputs_VentEquipQuant,MATCH(Logic!$A31,inputs_EquipNo,0)),"") | E31: =IF(INDEX(inputs_OutdoorAirFlow,MATCH(Logic!$A31,inputs_EquipNo,0))<>"",INDEX(inputs_OutdoorAirFlow,MATCH(Logic!$A31,inputs_EquipNo,0)),"") | F31: =IFERROR(IF(ISBLANK(B31),"",D31*E31),"") | G31: =IF(INDEX(inputs_HeatRecReq,MATCH(Logic!$A31,inputs_EquipNo,0))<>"",INDEX(inputs_HeatRecReq,MATCH(Logic!$A31,inputs_EquipNo,0)),"") | I31: Click + to left for additional rows
A32: 11 | B32: =IF(INDEX(inputs_EquipTag,MATCH(Logic!$A32,inputs_EquipNo,0))<>"",INDEX(inputs_EquipTag,MATCH(Logic!$A32,inputs_EquipNo,0)),"") | C32: =IF(INDEX(inputs_EquipType,MATCH(Logic!$A32,inputs_EquipNo,0))<>"",INDEX(inputs_EquipType,MATCH(Logic!$A32,inputs_EquipNo,0)),"") | D32: =IF(INDEX(inputs_VentEquipQuant,MATCH(Logic!$A32,inputs_EquipNo,0))<>"",INDEX(inputs_VentEquipQuant,MATCH(Logic!$A32,inputs_EquipNo,0)),"") | E32: =IF(INDEX(inputs_OutdoorAirFlow,MATCH(Logic!$A32,inputs_EquipNo,0))<>"",INDEX(inputs_OutdoorAirFlow,MATCH(Logic!$A32,inputs_EquipNo,0)),"") | F32: =IFERROR(IF(ISBLANK(B32),"",D32*E32),"") | G32: =IF(INDEX(inputs_HeatRecReq,MATCH(Logic!$A32,inputs_EquipNo,0))<>"",INDEX(inputs_HeatRecReq,MATCH(Logic!$A32,inputs_EquipNo,0)),"")
A33: 12 | B33: =IF(INDEX(inputs_EquipTag,MATCH(Logic!$A33,inputs_EquipNo,0))<>"",INDEX(inputs_EquipTag,MATCH(Logic!$A33,inputs_EquipNo,0)),"") | C33: =IF(INDEX(inputs_EquipType,MATCH(Logic!$A33,inputs_EquipNo,0))<>"",INDEX(inputs_EquipType,MATCH(Logic!$A33,inputs_EquipNo,0)),"") | D33: =IF(INDEX(inputs_VentEquipQuant,MATCH(Logic!$A33,inputs_EquipNo,0))<>"",INDEX(inputs_VentEquipQuant,MATCH(Logic!$A33,inputs_EquipNo,0)),"") | E33: =IF(INDEX(inputs_OutdoorAirFlow,MATCH(Logic!$A33,inputs_EquipNo,0))<>"",INDEX(inputs_OutdoorAirFlow,MATCH(Logic!$A33,inputs_EquipNo,0)),"") | F33: =IFERROR(IF(ISBLANK(B33),"",D33*E33),"") | G33: =IF(INDEX(inputs_HeatRecReq,MATCH(Logic!$A33,inputs_EquipNo,0))<>"",INDEX(inputs_HeatRecReq,MATCH(Logic!$A33,inputs_EquipNo,0)),"")
A34: 13 | B34: =IF(INDEX(inputs_EquipTag,MATCH(Logic!$A34,inputs_EquipNo,0))<>"",INDEX(inputs_EquipTag,MATCH(Logic!$A34,inputs_EquipNo,0)),"") | C34: =IF(INDEX(inputs_EquipType,MATCH(Logic!$A34,inputs_EquipNo,0))<>"",INDEX(inputs_EquipType,MATCH(Logic!$A34,inputs_EquipNo,0)),"") | D34: =IF(INDEX(inputs_VentEquipQuant,MATCH(Logic!$A34,inputs_EquipNo,0))<>"",INDEX(inputs_VentEquipQuant,MATCH(Logic!$A34,inputs_EquipNo,0)),"") | E34: =IF(INDEX(inputs_OutdoorAirFlow,MATCH(Logic!$A34,inputs_EquipNo,0))<>"",INDEX(inputs_OutdoorAirFlow,MATCH(Logic!$A34,inputs_EquipNo,0)),"") | F34: =IFERROR(IF(ISBLANK(B34),"",D34*E34),"") | G34: =IF(INDEX(inputs_HeatRecReq,MATCH(Logic!$A34,inputs_EquipNo,0))<>"",INDEX(inputs_HeatRecReq,MATCH(Logic!$A34,inputs_EquipNo,0)),"")
A35: 14 | B35: =IF(INDEX(inputs_EquipTag,MATCH(Logic!$A35,inputs_EquipNo,0))<>"",INDEX(inputs_EquipTag,MATCH(Logic!$A35,inputs_EquipNo,0)),"") | C35: =IF(INDEX(inputs_EquipType,MATCH(Logic!$A35,inputs_EquipNo,0))<>"",INDEX(inputs_EquipType,MATCH(Logic!$A35,inputs_EquipNo,0)),"") | D35: =IF(INDEX(inputs_VentEquipQuant,MATCH(Logic!$A35,inputs_EquipNo,0))<>"",INDEX(inputs_VentEquipQuant,MATCH(Logic!$A35,inputs_EquipNo,0)),"") | E35: =IF(INDEX(inputs_OutdoorAirFlow,MATCH(Logic!$A35,inputs_EquipNo,0))<>"",INDEX(inputs_OutdoorAirFlow,MATCH(Logic!$A35,inputs_EquipNo,0)),"") | F35: =IFERROR(IF(ISBLANK(B35),"",D35*E35),"") | G35: =IF(INDEX(inputs_HeatRecReq,MATCH(Logic!$A35,inputs_EquipNo,0))<>"",INDEX(inputs_HeatRecReq,MATCH(Logic!$A35,inputs_EquipNo,0)),"")
A36: 15 | B36: =IF(INDEX(inputs_EquipTag,MATCH(Logic!$A36,inputs_EquipNo,0))<>"",INDEX(inputs_EquipTag,MATCH(Logic!$A36,inputs_EquipNo,0)),"") | C36: =IF(INDEX(inputs_EquipType,MATCH(Logic!$A36,inputs_EquipNo,0))<>"",INDEX(inputs_EquipType,MATCH(Logic!$A36,inputs_EquipNo,0)),"") | D36: =IF(INDEX(inputs_VentEquipQuant,MATCH(Logic!$A36,inputs_EquipNo,0))<>"",INDEX(inputs_VentEquipQuant,MATCH(Logic!$A36,inputs_EquipNo,0)),"") | E36: =IF(INDEX(inputs_OutdoorAirFlow,MATCH(Logic!$A36,inputs_EquipNo,0))<>"",INDEX(inputs_OutdoorAirFlow,MATCH(Logic!$A36,inputs_EquipNo,0)),"") | F36: =IFERROR(IF(ISBLANK(B36),"",D36*E36),"") | G36: =IF(INDEX(inputs_HeatRecReq,MATCH(Logic!$A36,inputs_EquipNo,0))<>"",INDEX(inputs_HeatRecReq,MATCH(Logic!$A36,inputs_EquipNo,0)),"")
A37: 16 | B37: =IF(INDEX(inputs_EquipTag,MATCH(Logic!$A37,inputs_EquipNo,0))<>"",INDEX(inputs_EquipTag,MATCH(Logic!$A37,inputs_EquipNo,0)),"") | C37: =IF(INDEX(inputs_EquipType,MATCH(Logic!$A37,inputs_EquipNo,0))<>"",INDEX(inputs_EquipType,MATCH(Logic!$A37,inputs_EquipNo,0)),"") | D37: =IF(INDEX(inputs_VentEquipQuant,MATCH(Logic!$A37,inputs_EquipNo,0))<>"",INDEX(inputs_VentEquipQuant,MATCH(Logic!$A37,inputs_EquipNo,0)),"") | E37: =IF(INDEX(inputs_OutdoorAirFlow,MATCH(Logic!$A37,inputs_EquipNo,0))<>"",INDEX(inputs_OutdoorAirFlow,MATCH(Logic!$A37,inputs_EquipNo,0)),"") | F37: =IFERROR(IF(ISBLANK(B37),"",D37*E37),"") | G37: =IF(INDEX(inputs_HeatRecReq,MATCH(Logic!$A37,inputs_EquipNo,0))<>"",INDEX(inputs_HeatRecReq,MATCH(Logic!$A37,inputs_EquipNo,0)),"")
A38: 17 | B38: =IF(INDEX(inputs_EquipTag,MATCH(Logic!$A38,inputs_EquipNo,0))<>"",INDEX(inputs_EquipTag,MATCH(Logic!$A38,inputs_EquipNo,0)),"") | C38: =IF(INDEX(inputs_EquipType,MATCH(Logic!$A38,inputs_EquipNo,0))<>"",INDEX(inputs_EquipType,MATCH(Logic!$A38,inputs_EquipNo,0)),"") | D38: =IF(INDEX(inputs_VentEquipQuant,MATCH(Logic!$A38,inputs_EquipNo,0))<>"",INDEX(inputs_VentEquipQuant,MATCH(Logic!$A38,inputs_EquipNo,0)),"") | E38: =IF(INDEX(inputs_OutdoorAirFlow,MATCH(Logic!$A38,inputs_EquipNo,0))<>"",INDEX(inputs_OutdoorAirFlow,MATCH(Logic!$A38,inputs_EquipNo,0)),"") | F38: =IFERROR(IF(ISBLANK(B38),"",D38*E38),"") | G38: =IF(INDEX(inputs_HeatRecReq,MATCH(Logic!$A38,inputs_EquipNo,0))<>"",INDEX(inputs_HeatRecReq,MATCH(Logic!$A38,inputs_EquipNo,0)),"")
A39: 18 | B39: =IF(INDEX(inputs_EquipTag,MATCH(Logic!$A39,inputs_EquipNo,0))<>"",INDEX(inputs_EquipTag,MATCH(Logic!$A39,inputs_EquipNo,0)),"") | C39: =IF(INDEX(inputs_EquipType,MATCH(Logic!$A39,inputs_EquipNo,0))<>"",INDEX(inputs_EquipType,MATCH(Logic!$A39,inputs_EquipNo,0)),"") | D39: =IF(INDEX(inputs_VentEquipQuant,MATCH(Logic!$A39,inputs_EquipNo,0))<>"",INDEX(inputs_VentEquipQuant,MATCH(Logic!$A39,inputs_EquipNo,0)),"") | E39: =IF(INDEX(inputs_OutdoorAirFlow,MATCH(Logic!$A39,inputs_EquipNo,0))<>"",INDEX(inputs_OutdoorAirFlow,MATCH(Logic!$A39,inputs_EquipNo,0)),"") | F39: =IFERROR(IF(ISBLANK(B39),"",D39*E39),"") | G39: =IF(INDEX(inputs_HeatRecReq,MATCH(Logic!$A39,inputs_EquipNo,0))<>"",INDEX(inputs_HeatRecReq,MATCH(Logic!$A39,inputs_EquipNo,0)),"")
A40: 19 | B40: =IF(INDEX(inputs_EquipTag,MATCH(Logic!$A40,inputs_EquipNo,0))<>"",INDEX(inputs_EquipTag,MATCH(Logic!$A40,inputs_EquipNo,0)),"") | C40: =IF(INDEX(inputs_EquipType,MATCH(Logic!$A40,inputs_EquipNo,0))<>"",INDEX(inputs_EquipType,MATCH(Logic!$A40,inputs_EquipNo,0)),"") | D40: =IF(INDEX(inputs_VentEquipQuant,MATCH(Logic!$A40,inputs_EquipNo,0))<>"",INDEX(inputs_VentEquipQuant,MATCH(Logic!$A40,inputs_EquipNo,0)),"") | E40: =IF(INDEX(inputs_OutdoorAirFlow,MATCH(Logic!$A40,inputs_EquipNo,0))<>"",INDEX(inputs_OutdoorAirFlow,MATCH(Logic!$A40,inputs_EquipNo,0)),"") | F40: =IFERROR(IF(ISBLANK(B40),"",D40*E40),"") | G40: =IF(INDEX(inputs_HeatRecReq,MATCH(Logic!$A40,inputs_EquipNo,0))<>"",INDEX(inputs_HeatRecReq,MATCH(Logic!$A40,inputs_EquipNo,0)),"")
A41: 20 | B41: =IF(INDEX(inputs_EquipTag,MATCH(Logic!$A41,inputs_EquipNo,0))<>"",INDEX(inputs_EquipTag,MATCH(Logic!$A41,inputs_EquipNo,0)),"") | C41: =IF(INDEX(inputs_EquipType,MATCH(Logic!$A41,inputs_EquipNo,0))<>"",INDEX(inputs_EquipType,MATCH(Logic!$A41,inputs_EquipNo,0)),"") | D41: =IF(INDEX(inputs_VentEquipQuant,MATCH(Logic!$A41,inputs_EquipNo,0))<>"",INDEX(inputs_VentEquipQuant,MATCH(Logic!$A41,inputs_EquipNo,0)),"") | E41: =IF(INDEX(inputs_OutdoorAirFlow,MATCH(Logic!$A41,inputs_EquipNo,0))<>"",INDEX(inputs_OutdoorAirFlow,MATCH(Logic!$A41,inputs_EquipNo,0)),"") | F41: =IFERROR(IF(ISBLANK(B41),"",D41*E41),"") | G41: =IF(INDEX(inputs_HeatRecReq,MATCH(Logic!$A41,inputs_EquipNo,0))<>"",INDEX(inputs_HeatRecReq,MATCH(Logic!$A41,inputs_EquipNo,0)),"")
A42: 21 | B42: =IF(INDEX(inputs_EquipTag,MATCH(Logic!$A42,inputs_EquipNo,0))<>"",INDEX(inputs_EquipTag,MATCH(Logic!$A42,inputs_EquipNo,0)),"") | C42: =IF(INDEX(inputs_EquipType,MATCH(Logic!$A42,inputs_EquipNo,0))<>"",INDEX(inputs_EquipType,MATCH(Logic!$A42,inputs_EquipNo,0)),"") | D42: =IF(INDEX(inputs_VentEquipQuant,MATCH(Logic!$A42,inputs_EquipNo,0))<>"",INDEX(inputs_VentEquipQuant,MATCH(Logic!$A42,inputs_EquipNo,0)),"") | E42: =IF(INDEX(inputs_OutdoorAirFlow,MATCH(Logic!$A42,inputs_EquipNo,0))<>"",INDEX(inputs_OutdoorAirFlow,MATCH(Logic!$A42,inputs_EquipNo,0)),"") | F42: =IFERROR(IF(ISBLANK(B42),"",D42*E42),"") | G42: =IF(INDEX(inputs_HeatRecReq,MATCH(Logic!$A42,inputs_EquipNo,0))<>"",INDEX(inputs_HeatRecReq,MATCH(Logic!$A42,inputs_EquipNo,0)),"")
A43: 22 | B43: =IF(INDEX(inputs_EquipTag,MATCH(Logic!$A43,inputs_EquipNo,0))<>"",INDEX(inputs_EquipTag,MATCH(Logic!$A43,inputs_EquipNo,0)),"") | C43: =IF(INDEX(inputs_EquipType,MATCH(Logic!$A43,inputs_EquipNo,0))<>"",INDEX(inputs_EquipType,MATCH(Logic!$A43,inputs_EquipNo,0)),"") | D43: =IF(INDEX(inputs_VentEquipQuant,MATCH(Logic!$A43,inputs_EquipNo,0))<>"",INDEX(inputs_VentEquipQuant,MATCH(Logic!$A43,inputs_EquipNo,0)),"") | E43: =IF(INDEX(inputs_OutdoorAirFlow,MATCH(Logic!$A43,inputs_EquipNo,0))<>"",INDEX(inputs_OutdoorAirFlow,MATCH(Logic!$A43,inputs_EquipNo,0)),"") | F43: =IFERROR(IF(ISBLANK(B43),"",D43*E43),"") | G43: =IF(INDEX(inputs_HeatRecReq,MATCH(Logic!$A43,inputs_EquipNo,0))<>"",INDEX(inputs_HeatRecReq,MATCH(Logic!$A43,inputs_EquipNo,0)),"")
... A51: 30 | B51: =IF(INDEX(inputs_EquipTag,MATCH(Logic!$A51,inputs_EquipNo,0))<>"",INDEX(inputs_EquipTag,MATCH(Logic!$A51,inputs_EquipNo,0)),"") | C51: =IF(INDEX(inputs_EquipType,MATCH(Logic!$A51,inputs_EquipNo,0))<>"",INDEX(inputs_EquipType,MATCH(Logic!$A51,inputs_EquipNo,0)),"") | D51: =IF(INDEX(inputs_VentEquipQuant,MATCH(Logic!$A51,inputs_EquipNo,0))<>"",INDEX(inputs_VentEquipQuant,MATCH(Logic!$A51,inputs_EquipNo,0)),"") | E51: =IF(INDEX(inputs_OutdoorAirFlow,MATCH(Logic!$A51,inputs_EquipNo,0))<>"",INDEX(inputs_OutdoorAirFlow,MATCH(Logic!$A51,inputs_EquipNo,0)),"") | F51: =IFERROR(IF(ISBLANK(B51),"",D51*E51),"") | G51: =IF(INDEX(inputs_HeatRecReq,MATCH(Logic!$A51,inputs_EquipNo,0))<>"",INDEX(inputs_HeatRecReq,MATCH(Logic!$A51,inputs_EquipNo,0)),"")
A52: 31 | B52: =IF(INDEX(inputs_EquipTag,MATCH(Logic!$A52,inputs_EquipNo,0))<>"",INDEX(inputs_EquipTag,MATCH(Logic!$A52,inputs_EquipNo,0)),"") | C52: =IF(INDEX(inputs_EquipType,MATCH(Logic!$A52,inputs_EquipNo,0))<>"",INDEX(inputs_EquipType,MATCH(Logic!$A52,inputs_EquipNo,0)),"") | D52: =IF(INDEX(inputs_VentEquipQuant,MATCH(Logic!$A52,inputs_EquipNo,0))<>"",INDEX(inputs_VentEquipQuant,MATCH(Logic!$A52,inputs_EquipNo,0)),"") | E52: =IF(INDEX(inputs_OutdoorAirFlow,MATCH(Logic!$A52,inputs_EquipNo,0))<>"",INDEX(inputs_OutdoorAirFlow,MATCH(Logic!$A52,inputs_EquipNo,0)),"") | F52: =IFERROR(IF(ISBLANK(B52),"",D52*E52),"") | G52: =IF(INDEX(inputs_HeatRecReq,MATCH(Logic!$A52,inputs_EquipNo,0))<>"",INDEX(inputs_HeatRecReq,MATCH(Logic!$A52,inputs_EquipNo,0)),"") | I52: Click + to left for additional rows
A53: 32 | B53: =IF(INDEX(inputs_EquipTag,MATCH(Logic!$A53,inputs_EquipNo,0))<>"",INDEX(inputs_EquipTag,MATCH(Logic!$A53,inputs_EquipNo,0)),"") | C53: =IF(INDEX(inputs_EquipType,MATCH(Logic!$A53,inputs_EquipNo,0))<>"",INDEX(inputs_EquipType,MATCH(Logic!$A53,inputs_EquipNo,0)),"") | D53: =IF(INDEX(inputs_VentEquipQuant,MATCH(Logic!$A53,inputs_EquipNo,0))<>"",INDEX(inputs_VentEquipQuant,MATCH(Logic!$A53,inputs_EquipNo,0)),"") | E53: =IF(INDEX(inputs_OutdoorAirFlow,MATCH(Logic!$A53,inputs_EquipNo,0))<>"",INDEX(inputs_OutdoorAirFlow,MATCH(Logic!$A53,inputs_EquipNo,0)),"") | F53: =IFERROR(IF(ISBLANK(B53),"",D53*E53),"") | G53: =IF(INDEX(inputs_HeatRecReq,MATCH(Logic!$A53,inputs_EquipNo,0))<>"",INDEX(inputs_HeatRecReq,MATCH(Logic!$A53,inputs_EquipNo,0)),"")
A54: 33 | B54: =IF(INDEX(inputs_EquipTag,MATCH(Logic!$A54,inputs_EquipNo,0))<>"",INDEX(inputs_EquipTag,MATCH(Logic!$A54,inputs_EquipNo,0)),"") | C54: =IF(INDEX(inputs_EquipType,MATCH(Logic!$A54,inputs_EquipNo,0))<>"",INDEX(inputs_EquipType,MATCH(Logic!$A54,inputs_EquipNo,0)),"") | D54: =IF(INDEX(inputs_VentEquipQuant,MATCH(Logic!$A54,inputs_EquipNo,0))<>"",INDEX(inputs_VentEquipQuant,MATCH(Logic!$A54,inputs_EquipNo,0)),"") | E54: =IF(INDEX(inputs_OutdoorAirFlow,MATCH(Logic!$A54,inputs_EquipNo,0))<>"",INDEX(inputs_OutdoorAirFlow,MATCH(Logic!$A54,inputs_EquipNo,0)),"") | F54: =IFERROR(IF(ISBLANK(B54),"",D54*E54),"") | G54: =IF(INDEX(inputs_HeatRecReq,MATCH(Logic!$A54,inputs_EquipNo,0))<>"",INDEX(inputs_HeatRecReq,MATCH(Logic!$A54,inputs_EquipNo,0)),"")
A55: 34 | B55: =IF(INDEX(inputs_EquipTag,MATCH(Logic!$A55,inputs_EquipNo,0))<>"",INDEX(inputs_EquipTag,MATCH(Logic!$A55,inputs_EquipNo,0)),"") | C55: =IF(INDEX(inputs_EquipType,MATCH(Logic!$A55,inputs_EquipNo,0))<>"",INDEX(inputs_EquipType,MATCH(Logic!$A55,inputs_EquipNo,0)),"") | D55: =IF(INDEX(inputs_VentEquipQuant,MATCH(Logic!$A55,inputs_EquipNo,0))<>"",INDEX(inputs_VentEquipQuant,MATCH(Logic!$A55,inputs_EquipNo,0)),"") | E55: =IF(INDEX(inputs_OutdoorAirFlow,MATCH(Logic!$A55,inputs_EquipNo,0))<>"",INDEX(inputs_OutdoorAirFlow,MATCH(Logic!$A55,inputs_EquipNo,0)),"") | F55: =IFERROR(IF(ISBLANK(B55),"",D55*E55),"") | G55: =IF(INDEX(inputs_HeatRecReq,MATCH(Logic!$A55,inputs_EquipNo,0))<>"",INDEX(inputs_HeatRecReq,MATCH(Logic!$A55,inputs_EquipNo,0)),"")
A56: 35 | B56: =IF(INDEX(inputs_EquipTag,MATCH(Logic!$A56,inputs_EquipNo,0))<>"",INDEX(inputs_EquipTag,MATCH(Logic!$A56,inputs_EquipNo,0)),"") | C56: =IF(INDEX(inputs_EquipType,MATCH(Logic!$A56,inputs_EquipNo,0))<>"",INDEX(inputs_EquipType,MATCH(Logic!$A56,inputs_EquipNo,0)),"") | D56: =IF(INDEX(inputs_VentEquipQuant,MATCH(Logic!$A56,inputs_EquipNo,0))<>"",INDEX(inputs_VentEquipQuant,MATCH(Logic!$A56,inputs_EquipNo,0)),"") | E56: =IF(INDEX(inputs_OutdoorAirFlow,MATCH(Logic!$A56,inputs_EquipNo,0))<>"",INDEX(inputs_OutdoorAirFlow,MATCH(Logic!$A56,inputs_EquipNo,0)),"") | F56: =IFERROR(IF(ISBLANK(B56),"",D56*E56),"") | G56: =IF(INDEX(inputs_HeatRecReq,MATCH(Logic!$A56,inputs_EquipNo,0))<>"",INDEX(inputs_HeatRecReq,MATCH(Logic!$A56,inputs_EquipNo,0)),"")
A57: 36 | B57: =IF(INDEX(inputs_EquipTag,MATCH(Logic!$A57,inputs_EquipNo,0))<>"",INDEX(inputs_EquipTag,MATCH(Logic!$A57,inputs_EquipNo,0)),"") | C57: =IF(INDEX(inputs_EquipType,MATCH(Logic!$A57,inputs_EquipNo,0))<>"",INDEX(inputs_EquipType,MATCH(Logic!$A57,inputs_EquipNo,0)),"") | D57: =IF(INDEX(inputs_VentEquipQuant,MATCH(Logic!$A57,inputs_EquipNo,0))<>"",INDEX(inputs_VentEquipQuant,MATCH(Logic!$A57,inputs_EquipNo,0)),"") | E57: =IF(INDEX(inputs_OutdoorAirFlow,MATCH(Logic!$A57,inputs_EquipNo,0))<>"",INDEX(inputs_OutdoorAirFlow,MATCH(Logic!$A57,inputs_EquipNo,0)),"") | F57: =IFERROR(IF(ISBLANK(B57),"",D57*E57),"") | G57: =IF(INDEX(inputs_HeatRecReq,MATCH(Logic!$A57,inputs_EquipNo,0))<>"",INDEX(inputs_HeatRecReq,MATCH(Logic!$A57,inputs_EquipNo,0)),"")
A58: 37 | B58: =IF(INDEX(inputs_EquipTag,MATCH(Logic!$A58,inputs_EquipNo,0))<>"",INDEX(inputs_EquipTag,MATCH(Logic!$A58,inputs_EquipNo,0)),"") | C58: =IF(INDEX(inputs_EquipType,MATCH(Logic!$A58,inputs_EquipNo,0))<>"",INDEX(inputs_EquipType,MATCH(Logic!$A58,inputs_EquipNo,0)),"") | D58: =IF(INDEX(inputs_VentEquipQuant,MATCH(Logic!$A58,inputs_EquipNo,0))<>"",INDEX(inputs_VentEquipQuant,MATCH(Logic!$A58,inputs_EquipNo,0)),"") | E58: =IF(INDEX(inputs_OutdoorAirFlow,MATCH(Logic!$A58,inputs_EquipNo,0))<>"",INDEX(inputs_OutdoorAirFlow,MATCH(Logic!$A58,inputs_EquipNo,0)),"") | F58: =IFERROR(IF(ISBLANK(B58),"",D58*E58),"") | G58: =IF(INDEX(inputs_HeatRecReq,MATCH(Logic!$A58,inputs_EquipNo,0))<>"",INDEX(inputs_HeatRecReq,MATCH(Logic!$A58,inputs_EquipNo,0)),"")
...

Sheet Database
B2: LEED v5 Reduce Peak Thermal Loads Calculator BD+C LEED for Building Design and Construction Database
B4: GENERAL INFORMATION
B6: Option and Path | C6: Options | D6: Select
D7: Option 2.
D8: Option 4. Path 2
D9: Option 4. Path 3
D10: Option 2. + Option 4. Path 2
D11: Option 2. + Option 4. Path 3
D12: Option 2. + Option 4. Path 2 + 3
D13: Option 4. Path 2 + 3
B15: Building Type | C15: Options | D15: Select
D16: Office (Small/Med)
D17: Office (Large)
D18: Retail
D19: Hotel/Motel
D20: Apartment/Dormitory
D21: School/Education
D22: Other
B24: Units | C24: Options | D24: Select
D25: IP
D26: SI
B28: Select Project Climate Zone | C28: Options | D28: Select
D29: 0A
D30: 0B
D31: 1A
D32: 1B
D33: 2A
D34: 2B
D35: 3A
D36: 3B
D37: 3C
D38: 4A
D39: 4B
D40: 4C
... D45: 6B
D46: 7
D47: 8
B49: Ventilation Equipment | C49: Options | D49: Select
D50: AHU
D51: SF
...

Sheet Summary
B2: LEED v5 Reduce Peak Thermal Loads Calculator LEED for Building Design and Construction Summary
C5: Credit Option and Pathway | F5: =IF(logic_optpath<>"",logic_optpath,"")
C7: OPTION 2: VENTILATION ENERGY RECOVERY (1 POINT)
C9: Ventilation Energy Recovery | G9: Associated Points
C10: Minimum 70% enthalpy recovery ratio or Minimum of 75% Sensible Heat Recovery Ratio | G10: 1
C12: Ventilation Energy Recovery Met | G12: =IF(heatRecoveryRequirement="Yes", "Yes", "Not Compliant") -> Not Compliant
C14: AND/OR
C16: OPTION 4: PATH 2. ASHRAE 90.1 TRADE-OFF METHODS (1 - 3 POINTS)
C18: Option 4. Path 2. ASHRAE 90.1 Trade-off Methods - Envelope Loads | G18: Associated Points
C19: < 10% | G19: 0
C20: => 10% | G20: 1
C21: => 20% | G21: 2
C23: ASHRAE 90.1 Envelope Loads Trade-off | G23: =envelopeLoadsReduction -> 0
C25: AND/OR
C27: Option 4. Path 2. ASHRAE 90.1 Trade-off Methods - Ventilation Loads | G27: Associated Points
C28: < 10% | G28: 0
C29: => 10% | G29: 1
C31: ASHRAE 90.1 Ventilation Loads Trade-off | G31: =ventLoadsReduction -> 0
C33: OR
C35: OPTION 4: PATH 3. ENERGY SIMULATION (1 - 3 POINTS)
C37: Energy Simulation Performance Index | G37: Associated Points
C38: > 0.5 | G38: 0
C39: >= 0.5 | G39: 1
C40: >= 0.4 | G40: 2
C41: >= 0.3 | G41: 3
C43: Energy Simulation Performance Index | G43: =performanceIndex -> 0
H46: V01
H47: Copyright © 2025
H48: U.S. Green Building Council
H49: All Rights Reserved
H50: Last Updated: 10/31/2025
