Workbook
Name data_dumip: Database!$E$27:$E$73
Name data_dumipother: Database!$E$69:$E$73
Name data_dumsi: Database!$F$27:$F$73
Name data_dumsiother: Database!$F$69:$F$73
Name data_genaw: Database!$E$16:$E$17
Name data_genct: Database!$E$20:$E$21
Name data_genpt: Database!$E$7:$E$9
Name data_genunits: Database!$E$12:$E$13
Name data_genunitsval: Database!$F$12:$F$13
Name data_genunitsvol: Database!$G$12:$G$13
Name data_pntsnmbdccs: Database!$B$94
Name data_pntsnmbdccsdrp: Database!$D$94
Name data_pntsnmbdcnc: Database!$B$83
Name data_pntsnmbdcncdrp: Database!$D$83
Name data_pntsnmidc: Database!$B$105
Name data_pntsnmidcdrp: Database!$D$105
Name data_ptsdrp: Database!$D$78:$D$81
Name data_ptslkaw: Database!$G$116:$G$148
Name data_ptslkpnts: Database!$F$116:$F$148
Name data_ptslkpr: Database!$E$116:$E$148
Name data_ptslkpt: Database!$B$116:$B$148
Name data_ptspr: Database!$B$78:$B$81
Name data_unittyp: [1]Database!$E$12:$E$13
Name data_unitvol: [1]Database!$F$12:$F$13
Name data_wateruseapp: Database!$C$28:$C$32
Name data_waterusehvac: Database!$C$59:$C$67
Name data_waterusekitch: Database!$C$34:$C$49
Name data_wateruselabmed: Database!$C$51:$C$57
Name data_waterusetypes: Database!$C$27:$C$73
Name data_wurip: Database!$G$27:$G$73
Name data_wuripother: Database!$G$69:$G$73
Name data_wursi: Database!$H$27:$H$73
Name data_wursiother: Database!$H$69:$H$73
Name inputs_appawu: 'Inputs Whole-Project Water Use'!$Q$26:$Q$139
Name inputs_appdumv: 'Inputs Whole-Project Water Use'!$H$26:$H$139
Name inputs_appiid: 'Inputs Whole-Project Water Use'!$B$26:$B$139
Name inputs_appiqty: 'Inputs Whole-Project Water Use'!$C$26:$C$139
Name inputs_appiwut: 'Inputs Whole-Project Water Use'!$D$26:$D$139
Name inputs_appno: 'Inputs Whole-Project Water Use'!$A$29:$A$139
Name inputs_apppiado: 'Inputs Whole-Project Water Use'!$F$26:$F$139
Name inputs_apppicpd: 'Inputs Whole-Project Water Use'!$G$26:$G$139
Name inputs_apptotas: 'Inputs Whole-Project Water Use'!$T$26:$T$139
Name inputs_appwurb: 'Inputs Whole-Project Water Use'!$K$26:$K$139
Name inputs_appwurd: 'Inputs Whole-Project Water Use'!$L$26:$L$139
Name inputs_bdffwub: 'Inputs Whole-Project Water Use'!$D$15
Name inputs_bdffwud: 'Inputs Whole-Project Water Use'!$F$15
Name inputs_bdffwuwa: 'Inputs Whole-Project Water Use'!$E$15
Name inputs_bdoutwub: 'Inputs Whole-Project Water Use'!$D$19
Name inputs_bdoutwud: 'Inputs Whole-Project Water Use'!$F$19
Name inputs_bdoutwuwa: 'Inputs Whole-Project Water Use'!$E$19
Name inputs_hvacno: 'Inputs Whole-Project Water Use'!$A$392:$A$502
Name inputs_kitchiid: 'Inputs Whole-Project Water Use'!$B$147:$B$255
Name inputs_kitchiqty: 'Inputs Whole-Project Water Use'!$C$147:$C$255
Name inputs_kitchium: 'Inputs Whole-Project Water Use'!$H$148:$H$255
Name inputs_kitchiwut: 'Inputs Whole-Project Water Use'!$D$147:$D$255
Name inputs_kitchno: 'Inputs Whole-Project Water Use'!$A$150:$A$260
Name inputs_kitchtotas: 'Inputs Whole-Project Water Use'!$T$147:$T$255
Name inputs_kitchtotb: 'Inputs Whole-Project Water Use'!$O$147:$O$255
Name inputs_kitchtots: 'Inputs Whole-Project Water Use'!$S$147:$S$255
Name inputs_kitchwuau: 'Inputs Whole-Project Water Use'!$J$148:$J$255

Sheet Revision History
A1: Draft Calculator Revision History | H1: TASKS
A3: Date | B3: Party | C3: Tab Edited | D3: Field Edited | E3: Description | F3: Related TASK No. | H3: No. | I3: Date Complete | J3: Tab Edited | K3: Source File
A4: 45881 | B4: WSP | C4: ALL | D4: ALL | E4: Templatized | F4: NA | H4: 1 | J4: Make sure to create named fields (Formulas > Name Manager) and use formulas using named field values (note be sure to delete unused names from the template document)
A5: 45888 | B5: WSP | C5: ALL | D5: ALL | E5: Created calculator. Note formulas only built out in Logic up until Appliance Water. Instructions not developed yet. Ready for preliminary review. Need to confirm: - confirm appliance water use baselines (USGBC?) - see comments in Database CONFIRMED WITH GINA 8/26/25 NEED TO ASK USGBC 1) NEED TO MEET MINIMUMS FROM DIFFERENT CREDITS? BASED ON REFERENCE GUIDE, ANTICIPATE NO, BUT WOULD LIKE TO CONFIRM. 2) BASELINE VALUES DETERMINED BY CREDIT TABLES? BASED ON REFERENCE GUIDE, ANTICIPATE YES, BUT WOULD LIKE TO CONFIRM. 3) HOW TO TREAT EQUIPMENT THAT ONLY HAVE PERFORMANCE VALUES IN THE PREREQ? SHOULD PREREQ VALUES BE USED AS BASELINE? SHOULD UNIT TYPES BE EXCLUDED FROM CALCULATOR? SHOULD OTHER VALUE BE USED AS BASELINE? 4) IF CREDIT TABLES ARE THE BASELINE, CONFIRM IF EQUIPMENT THAT ONLY LISTS ENERGY STAR REQUIREMENTS USE THE MAXIMUM ALLOWED VALUES LISTED IN ENERGY STAR AS BASELINE? - confirm if water use reduction is only a value of appliance capacity or if it is actual volume (currently calc is built out for the later) CONFIRMED WITH GINA ACTUAL VOLUME 8/26/25 - confirm if savings should be represented as a positive or negative number (currently calc is built out for the former) CONFIRMED WITH GINA POSITIVE 8/26/25 NOTE SHOULD BE CONFIRMED ACROSS THE BOARD WITH USGBC - confirm and coordinate structure with other water calculators (fixtures, outdoor) NOTE COORDINATE WITH AMY JYOTI - note formatting not reviewed or updated, many will need to be made bigger for visibility | F5: NA | H5: 2 | J5: Make sure all credit calculation requirements are included
A6: 45898 | B6: WSP | C6: ALL | D6: ALL | E6: Updated formatting, completed formulas, updated database tab for WEc values Ready for preliminary LEED review, note the following - Still need to confirm baseline values for Database from USGBC - Remains unclear to me IF can only have heavy commercial use to use this pathway, and how residential relates to it. Langauge has dishwasher and laundry limits for credit table value usage, but instructions also state that all water sources need to be included, confirm how to address - Recommend reviewer also see if any of these tables can be used to contribute to appliance pathway (Option 3) - Recommend LEED Reviewer think through if it would be helpful to combine this calculator with Fixtures and Outdoor (though note at this time still in progress) - Potential for conditional formatting for laundry volume, but would like to confirm general calculator from LEED Reviewer First | F6: NA | H6: 3 | J6: Make sure formulas work, values correct, validation included where needed (i.e. positive numbers only, etc.)
A7: 45903 | B7: WSP | C7: ALL | D7: ALL | E7: Updated based on WSP internal review comments. | F7: NA | H7: 4 | J7: Make sure labels are correct (including make explicit where inputs are required or optional)
A8: 45905 | B8: WSP | C8: ALL | D8: ALL | E8: Updated based on WSP internal review comments. | F8: NA | H8: 5 | J8: QC Cell Formatting (see internal style guide)
H9: 6 | J9: Add Notes where needed
H10: 7 | J10: Add summary "Point calculation" tab
H11: 8 | J11: Update instructions tab
H12: 9 | J12: Add flags as needed (i.e. for CFCs, IDC BDC >700 GWP)
H13: 10 | J13: Allow Add rows without macros, include instructions (NOTE prior calculator drafts have used Groups, welcome other recommendations)
H14: 11 | J14: Update formatting per USGBC (including If required create named fields; If guidance says use tables, convert to tables)
H15: 12 | J15: Spell Check
H16: 13 | J16: Final Lock Settings and QC
J18: PAT LINDO SCOPING NOTE We need 3 distinct calculators: 1.) “LEED v5 Whole Project Water Use calculator” 2.) “LEED v5 Fixture and Fittings Efficiency calculator” and 3.) “LEED v5 Outdoor Water Use Efficiency calculator” -(remove ‘minimum’ from the #3 title). These can combined into one single tool or as individual tools. Within these calculators we need an input (deduct) line item for alternative water. The deduct will reduce water demand and provide an 'extra' point for the project. | K18: https://wsponlinenam.sharepoint.com/:x:/r/sites/US-BuiltEcology/BE%20Drive/01_Projects/2025/US0046386.5310---LEED%20v5%20Calculators%20and%20Tech%20Dev/11_LEED%20Calculator%20Development/01_LEED%20V5.0%20Calculators%20Scoping%20and%20Methodology/LEED%20v5_%20Calculator%20Scoping%20for%20Review%20USGBC%20Comments.xlsx?d=w012339cd8b03415185c90d63478e1f76&csf=1&web=1&e=wm5D2j
J19: PAT LINDO SCOPING NOTE We need 3 distinct calculators: 1.) “LEED v5 Whole Project Water Use calculator” 2.) “LEED v5 Fixture and Fittings Efficiency calculator” and 3.) “LEED v5 Outdoor Water Use Efficiency calculator” -(remove ‘minimum’ from the #3 title). Under WEp2 A project can choose either a prescriptive path as a standalone or a performance path, which links these calculators together. Then under WEc2 the project can choose option 1 “Whole water use” or option 2 Fixtures & Fittings which adds up the individual fixture flows. All of these of approaches use input values from third party calculators for process water (cooling) and alternative water. Note: These calculators can combined into one single tool or as individual tools. Within these calculators we need an input (deduct) line item for alternative water. The deduct will reduce water demand and provide an 'extra' point for the project. | K19: https://wsponlinenam.sharepoint.com/:x:/r/sites/US-BuiltEcology/BE%20Drive/01_Projects/2025/US0046386.5310---LEED%20v5%20Calculators%20and%20Tech%20Dev/11_LEED%20Calculator%20Development/01_LEED%20V5.0%20Calculators%20Scoping%20and%20Methodology/LEED%20v5_%20Calculator%20Scoping%20for%20Review%20USGBC%20Comments.xlsx?d=w012339cd8b03415185c90d63478e1f76&csf=1&web=1&e=wm5D2j
J20: PAT LINDO SCOPING NOTE The baseline calculations for process water (including cooling towers) is generated by a third party calculator and included in the LEED calculator as a simple “input” (value / number). | K20: https://wsponlinenam.sharepoint.com/:x:/r/sites/US-BuiltEcology/BE%20Drive/01_Projects/2025/US0046386.5310---LEED%20v5%20Calculators%20and%20Tech%20Dev/11_LEED%20Calculator%20Development/01_LEED%20V5.0%20Calculators%20Scoping%20and%20Methodology/LEED%20v5_%20Calculator%20Scoping%20for%20Review%20USGBC%20Comments.xlsx?d=w012339cd8b03415185c90d63478e1f76&csf=1&web=1&e=wm5D2j
J21: PAT LINDO SCOPING NOTE This calculator includes an update with additional savings from irrigation scheduling technologies” per pages 31-34 of EPA TIR. refer to calculator as "outdoor water efficiency" | K21: https://wsponlinenam.sharepoint.com/:x:/r/sites/US-BuiltEcology/BE%20Drive/01_Projects/2025/US0046386.5310---LEED%20v5%20Calculators%20and%20Tech%20Dev/11_LEED%20Calculator%20Development/01_LEED%20V5.0%20Calculators%20Scoping%20and%20Methodology/LEED%20v5_%20Calculator%20Scoping%20for%20Review%20USGBC%20Comments.xlsx?d=w012339cd8b03415185c90d63478e1f76&csf=1&web=1&e=wm5D2j

Sheet Internal Style Guide
B2: Internal Style Guide
B4: TEMP LOCK PASSWORD | E4: LEEDv5
B5: Workbook Structure | D5: Tabs | E5: Inputs Tab: User input AND final summary values only, can have some automatic input cells IF important for user data, can have multiple inputs tabs if needed
E6: Logic Tab: Calculations for values needed for LEED Performance, no user input, will be hidden from users
E7: Database Tab: Constants, values for logic calculations, points, limit to static values no formulas where possible, will be hidden from users
E8: Summary Tab: Points, values needed for LEED performance (see Reference Guide Documentation requirements for what needs to be included)
D9: Formulas | E9: Note calculators must use Formula > Name Manager to name fields and cells that are used for calculations or pulled into other cells.
E10: Recommend developing full calculator structure and initial formulas before naming fields and updating formulas.
D11: Settings | E11: Prior to sharing with users, ensure that the File > Options > Advanced > Enable fill handle and cell "drag-and-drop" is turned OFF
E12: This importantly prevents users from being able to drag unprotected input cells across fields, which could distrupt calculator function
B13: General Sheet Formating | E13: Turn-off view gridlines
E14: Columns to left and right of boarder to be Width of 3.5 (42 pxl)
E15: Rows above and below boarder to be Height of 20 (34 pxl)
E16: Lock all sheets EXCEPT for Inputs for all functions EXCEPT for "Select"
E17: Lock all Inputs sheets for all functions EXCEPT for "Select" AND "Format Columns, "Format Rows" to allow for using additional row functions
B18: Sheet Background Fill | E18: #F7F8F6; fill up to row 300, 600, or 900 as needed; fill up to column Z
B19: Instructions + Summary Background Fill | E19: #FFFFFF
B20: Title Fill | E20: IP | F20: #952713
E21: LT | F21: #B87400
E22: SS | F22: #536426
E23: WE | F23: #006570
E24: EA | F24: #C75127
E25: MR | F25: #7C4901
E26: EQ | F26: #684659
E27: PR | F27: #7E8AA2
B28: Title Format | E28: Use downloadable PNG logo w and maintain aspect ratio in all cases. Logo must never be more than 1 inch (72 pixels) wide.
E29: Suggest standard header height of 90.0 (150 pxl) with an increase to 95.0 (160 pxl) prerequisite and credit combo.
E30: Note naming convention (see below for example):
F31: USGBC Calculator || LEED for Building Operations and Maintenance [14 point font, bold] LEED v5 EAp4: Fundamental Refigerant Management [12 point font, bold] LEED v5 EAc3: Enhanced Refrigerant Management Performance [12 point font, bold] Sheet Name (I.E. Inputs, Logic, Database, Summary) [12 point font, bold]
B32: Cell Outline | E32: Automatic, Default Weight
B33: Standard Row Width | E33: 18.0 (30 pxls)
B34: Text Alignment | D34: Subheadings | E34: Center justified, Vertical Center
D35: Text | E35: Left justified, Vertical Center
D36: Numbers | E36: Right justified, Vertical Center
B37: Number Formatting | D37: 1000 | E37: Qty
E38: GWP of refrigerant
E39: Total GWP
E40: Refrigerant Leakage Emissions Ratio (RLER) - Note Ref Guide includes 1 decimal place in some sample calculations, confirm if calculator should as well.
E41: Sum Refrigerant at Full Charge (Rc)
D42: 1000.1 | E42: Refrigerant at Full Charge (Rc)
...

Sheet Instructions
B2: LEED v5 Whole Project Water Use Calculator LEED for Building Design and Construction | Interior Design and Construction Instructions
C5: CREDIT INSTRUCTIONS
D7: WEc2: Enhanced Water Efficiency | Option 1. Whole-Project Water Use
D8: ▪ | E8: This calculator serves as a water balance model by calculating the building's total water demand and provides a comparison of a baseline and design case water model.
E9: ▪ | F9: The baseline case water model must reflect the minimum requirements and typical water use for the project type without any additional water-savings measures.
E10: ▪ | F10: The design case water model must use fixtures and fittings, appliances, kitchen equipment, and laboratory and medical equipment as specified within the contract documents. For outdoor water use, determine the actual water used on-site.
D11: ▪ | E11: Model must account for all end uses for the project, including fixtures and fittings, domestic hot water, appliances, commercial kitchen and laundry equipment, laboratory and medical equipment, process water, HVAC systems, and landscape irrigation.
D12: ▪ | E12: Projects must include the fixtures and fittings necessary to meet the occupants’ needs, whether they will be installed as part of the project’s scope of work or not. Include at a minimum all necessary restroom fixtures (toilets, urinals, and lavatories) to meet the project occupants’ needs, and showers when seeking LT Credit Transportation Demand Management. Upload separate calculations for the credit, as applicable.
D13: ▪ | E13: Projects must demonstrate a minimum of 30% reduction from the project’s baseline to earn points. Using alternative water sources earns additional points for the calculated reductions.
D14: ▪ | E14: Teams should always prioritize water efficiency first in the prerequisite to reduce consumption and demand before applying alternative water solutions in the credit. For any seasonally dependent sources, such as rainwater, calculations must reflect annual, seasonal totals to confirm the available quantity of the alternative water source.
E15: ▪ | F15: If the alternative water is used for multiple applications in the project – for example, flush fixtures, irrigation, and/or process water – or is shared by multiple buildings, teams must provide supply and demand calculations to confirm the available quantity of alternative water and demonstrate that a sufficient quantity is available to meet the demands of all uses. Monthly supply and demand calculations are typically provided for seasonally dependent sources of alternative water, such as harvested rainwater, and for projects with seasonal occupancy variations, such as schools.
E16: ▪ | F16: Alternative water sources include on-site reclaimed water, off-site supplied reclaimed wastewater, graywater, rainwater, stormwater, treated seawater, condensate, nuisance water, treated blowdown from process water, reject water from reverse osmosis, and other recycled water sources.
E17: ▪ | F17: Potable water sources include municipally supplied potable water, well water, groundwater, and water from naturally occurring surface bodies of water (such as streams, lakes, or rivers), even if not treated to potable drinking water standards.
C20: INPUT INSTRUCTIONS
E22: User input cell formatting.
E23: Automatic input cell formatting.
E24: Calculation cell formatting.
C26: All input cells are required unless otherwise noted.
C28: 1 | D28: Input general information for the project, including project type and units.
C30: 2 | D30: Input baseline case and design case model values from other calculators.
D31: ▪ | E31: For fixtures and fittings, determine the baseline using a USGBC-approved calculator, as described in WEc2: Enhanced Water Efficiency, Option 2. Fixture and Fittings - Calculated Reduction.
D32: ▪ | E32: For outdoor water use, determine the baseline water consumption by calculating the project’s TIR, as outlined in WEc2: Enhanced Water Efficiency, Option 4. Outdoor Water Use, Path 2. Efficient Irrigation.
E33: Required fields for each category:
E34: ▪ | F34: Water Use Baseline. Must be a positive number. From external calculator.
E35: ▪ | F35: Total Annual Water Use Design (including alternative water). Must be a positive number. From external calculator.
E36: Optional fields for each category:
E37: ▪ | F37: Total Annual Alternative Water Use. Must be a positive number. From external calculator.
C39: 3 | D39: Input appliance baseline case and design case model values.
D40: ▪ | E40: See additional instructions below.
C42: 4 | D42: Input kitchen equipment baseline case and design case model values.
D43: ▪ | E43: See additional instructions below.
C45: 5 | D45: Input lab and medical baseline case and design case model values.
D46: ▪ | E46: See additional instructions below.
C48: 6 | D48: Input HVAC water use baseline case and design case model values.
D49: ▪ | E49: Input all HVAC water consumption, including cooling towers, evaporative condensers, evaporative coolers, boilers, humidification, etc.
D50: ▪ | E50: Water used by these systems must be included in the baseline if applicable for the project’s ASHRAE 90.1 Appendix G baseline system type according to ASHRAE 90.1-2019 or 2022 Table G3.1.1-3.
D51: ▪ | E51: For cooling system water use:
E52: ▪ | F52: The baseline system must be a 100% water-cooled chiller system with axial variable-speed fan cooling towers having a maximum drift of 0.002% of recirculated water volume and three cooling tower cycles.
E53: ▪ | F53: Baseline performance shall be calculated based on proposed case cooling loads for spaces served by systems 7, 8, 11, 12, or 13 in the baseline energy model.
E54: ▪ | F54: Cooling tower water usage calculations may be performed within the energy simulation software or using the cooling tower or evaporative condenser manufacturer's water usage program based on hourly design conditions, building loads and water chemistry.
...

Sheet Inputs Whole-Project Water Use
B2: LEED v5 Whole Project Water Use Calculator LEED for Building Design and Construction | Interior Design and Construction Inputs Whole-Project Water Use
B4: STEP 1: GENERAL INFORMATION
B6: Project Type
B8: Unit of Measurement
B11: STEP 2: BASELINE AND DESIGN MODELS FROM OTHER CALCULATORS
B13: Fixtures and Fittings Water Use
B14: Unit | D14: Total Annual Water Use Baseline | E14: Total Annual Alternative Water Use (Optional) | F14: Total Annual Water Use Design (including alternative water) | H14: Total Annual Savings | J14: Total Annual Savings %
B15: =IF(inputs_units<>"",INDEX(data_genunitsval,MATCH(inputs_units,data_genunits,0)),"") | H15: =logic_bdffwuasam -> 0 | J15: =logic_bdffwuasprc -> 0
B17: Outdoor Water Use (BD+C only)
B18: Unit | D18: Total Annual Water Use Baseline | E18: Total Annual Alternative Water Use (Optional) | F18: Total Annual Water Use Design (including alternative water) | H18: Total Annual Savings | J18: Total Annual Savings %
B19: =IF(inputs_units<>"",INDEX(data_genunitsval,MATCH(inputs_units,data_genunits,0)),"") | H19: =logic_bdoutwuasam -> 0 | J19: =logic_bdoutwuasprc -> 0
B22: STEP 3: APPLIANCE WATER USE BASELINE AND DESIGN MODEL
B24: Click + to the left to add additional rows. Click - to the left to collapse (content will be saved).
B25: Project Equipment Information | H25: Baseline and Design Water Use Information | O25: Water Consumption
A26: - | B26: Appliance ID (Optional) | C26: Quantity (Optional) | D26: Water Use Type | F26: Annual Days of Operation | G26: Cycles per Day | H26: Daily Usage Multiplier | K26: Water Use Rate | O26: =CONCATENATE("Annual Water Use Baseline (",(IF(inputs_units<>"",INDEX(data_genunitsvol,MATCH(inputs_units,data_genunits,0)),"unit")),")") -> Annual Water Use Baseline (unit) | P26: =CONCATENATE("Annual Water Use Design w/o Alt. Water (",(IF(inputs_units<>"",INDEX(data_genunitsvol,MATCH(inputs_units,data_genunits,0)),"unit")),")") -> Annual Water Use Design w/o Alt. Water (unit) | Q26: =CONCATENATE("Annual Alternative Water Use (",(IF(inputs_units<>"",INDEX(data_genunitsvol,MATCH(inputs_units,data_genunits,0)),"unit")),")") -> Annual Alternative Water Use (unit) | R26: =CONCATENATE("Annual Water Use Design (",(IF(inputs_units<>"",INDEX(data_genunitsvol,MATCH(inputs_units,data_genunits,0)),"unit")),")") -> Annual Water Use Design (unit) | S26: =CONCATENATE("Annual Water Use Savings (",(IF(inputs_units<>"",INDEX(data_genunitsvol,MATCH(inputs_units,data_genunits,0)),"unit")),")") -> Annual Water Use Savings (unit) | T26: AnnualWater Use Savings (%)
H27: Value | I27: Unit | K27: Equipment Baseline Water Use | L27: Equipment Design Water Use | M27: Unit
Q28: (Optional)
A29: 1 | I29: =INDEX(logic_dumuapp,MATCH($A29,logic_appno,0)) | M29: =INDEX(logic_wuruapp,MATCH($A29,logic_appno,0)) | O29: =INDEX(logic_appawub,MATCH($A29,logic_appno,0)) | P29: =INDEX(logic_appawudwoaw,MATCH($A29,logic_appno,0)) | R29: =INDEX(logic_appawud,MATCH($A29,logic_appno,0)) | S29: =INDEX(logic_appawusa,MATCH($A29,logic_appno,0)) | T29: =INDEX(logic_appawusp,MATCH($A29,logic_appno,0))
A30: 2 | I30: =INDEX(logic_dumuapp,MATCH($A30,logic_appno,0)) | M30: =INDEX(logic_wuruapp,MATCH($A30,logic_appno,0)) | O30: =INDEX(logic_appawub,MATCH($A30,logic_appno,0)) | P30: =INDEX(logic_appawudwoaw,MATCH($A30,logic_appno,0)) | R30: =INDEX(logic_appawud,MATCH($A30,logic_appno,0)) | S30: =INDEX(logic_appawusa,MATCH($A30,logic_appno,0)) | T30: =INDEX(logic_appawusp,MATCH($A30,logic_appno,0))
A31: 3 | I31: =INDEX(logic_dumuapp,MATCH($A31,logic_appno,0)) | M31: =INDEX(logic_wuruapp,MATCH($A31,logic_appno,0)) | O31: =INDEX(logic_appawub,MATCH($A31,logic_appno,0)) | P31: =INDEX(logic_appawudwoaw,MATCH($A31,logic_appno,0)) | R31: =INDEX(logic_appawud,MATCH($A31,logic_appno,0)) | S31: =INDEX(logic_appawusa,MATCH($A31,logic_appno,0)) | T31: =INDEX(logic_appawusp,MATCH($A31,logic_appno,0))
A32: 4 | I32: =INDEX(logic_dumuapp,MATCH($A32,logic_appno,0)) | M32: =INDEX(logic_wuruapp,MATCH($A32,logic_appno,0)) | O32: =INDEX(logic_appawub,MATCH($A32,logic_appno,0)) | P32: =INDEX(logic_appawudwoaw,MATCH($A32,logic_appno,0)) | R32: =INDEX(logic_appawud,MATCH($A32,logic_appno,0)) | S32: =INDEX(logic_appawusa,MATCH($A32,logic_appno,0)) | T32: =INDEX(logic_appawusp,MATCH($A32,logic_appno,0))
A33: 5 | I33: =INDEX(logic_dumuapp,MATCH($A33,logic_appno,0)) | M33: =INDEX(logic_wuruapp,MATCH($A33,logic_appno,0)) | O33: =INDEX(logic_appawub,MATCH($A33,logic_appno,0)) | P33: =INDEX(logic_appawudwoaw,MATCH($A33,logic_appno,0)) | R33: =INDEX(logic_appawud,MATCH($A33,logic_appno,0)) | S33: =INDEX(logic_appawusa,MATCH($A33,logic_appno,0)) | T33: =INDEX(logic_appawusp,MATCH($A33,logic_appno,0))
A34: 6 | I34: =INDEX(logic_dumuapp,MATCH($A34,logic_appno,0)) | M34: =INDEX(logic_wuruapp,MATCH($A34,logic_appno,0)) | O34: =INDEX(logic_appawub,MATCH($A34,logic_appno,0)) | P34: =INDEX(logic_appawudwoaw,MATCH($A34,logic_appno,0)) | R34: =INDEX(logic_appawud,MATCH($A34,logic_appno,0)) | S34: =INDEX(logic_appawusa,MATCH($A34,logic_appno,0)) | T34: =INDEX(logic_appawusp,MATCH($A34,logic_appno,0))
A35: 7 | I35: =INDEX(logic_dumuapp,MATCH($A35,logic_appno,0)) | M35: =INDEX(logic_wuruapp,MATCH($A35,logic_appno,0)) | O35: =INDEX(logic_appawub,MATCH($A35,logic_appno,0)) | P35: =INDEX(logic_appawudwoaw,MATCH($A35,logic_appno,0)) | R35: =INDEX(logic_appawud,MATCH($A35,logic_appno,0)) | S35: =INDEX(logic_appawusa,MATCH($A35,logic_appno,0)) | T35: =INDEX(logic_appawusp,MATCH($A35,logic_appno,0))
A36: 8 | I36: =INDEX(logic_dumuapp,MATCH($A36,logic_appno,0)) | M36: =INDEX(logic_wuruapp,MATCH($A36,logic_appno,0)) | O36: =INDEX(logic_appawub,MATCH($A36,logic_appno,0)) | P36: =INDEX(logic_appawudwoaw,MATCH($A36,logic_appno,0)) | R36: =INDEX(logic_appawud,MATCH($A36,logic_appno,0)) | S36: =INDEX(logic_appawusa,MATCH($A36,logic_appno,0)) | T36: =INDEX(logic_appawusp,MATCH($A36,logic_appno,0))
A37: 9 | I37: =INDEX(logic_dumuapp,MATCH($A37,logic_appno,0)) | M37: =INDEX(logic_wuruapp,MATCH($A37,logic_appno,0)) | O37: =INDEX(logic_appawub,MATCH($A37,logic_appno,0)) | P37: =INDEX(logic_appawudwoaw,MATCH($A37,logic_appno,0)) | R37: =INDEX(logic_appawud,MATCH($A37,logic_appno,0)) | S37: =INDEX(logic_appawusa,MATCH($A37,logic_appno,0)) | T37: =INDEX(logic_appawusp,MATCH($A37,logic_appno,0))
A38: 10 | I38: =INDEX(logic_dumuapp,MATCH($A38,logic_appno,0)) | M38: =INDEX(logic_wuruapp,MATCH($A38,logic_appno,0)) | O38: =INDEX(logic_appawub,MATCH($A38,logic_appno,0)) | P38: =INDEX(logic_appawudwoaw,MATCH($A38,logic_appno,0)) | R38: =INDEX(logic_appawud,MATCH($A38,logic_appno,0)) | S38: =INDEX(logic_appawusa,MATCH($A38,logic_appno,0)) | T38: =INDEX(logic_appawusp,MATCH($A38,logic_appno,0)) | U38: Click + to left for additional rows
A39: 11 | I39: =INDEX(logic_dumuapp,MATCH($A39,logic_appno,0)) | M39: =INDEX(logic_wuruapp,MATCH($A39,logic_appno,0)) | O39: =INDEX(logic_appawub,MATCH($A39,logic_appno,0)) | P39: =INDEX(logic_appawudwoaw,MATCH($A39,logic_appno,0)) | R39: =INDEX(logic_appawud,MATCH($A39,logic_appno,0)) | S39: =INDEX(logic_appawusa,MATCH($A39,logic_appno,0)) | T39: =INDEX(logic_appawusp,MATCH($A39,logic_appno,0))
A40: 12 | I40: =INDEX(logic_dumuapp,MATCH($A40,logic_appno,0)) | M40: =INDEX(logic_wuruapp,MATCH($A40,logic_appno,0)) | O40: =INDEX(logic_appawub,MATCH($A40,logic_appno,0)) | P40: =INDEX(logic_appawudwoaw,MATCH($A40,logic_appno,0)) | R40: =INDEX(logic_appawud,MATCH($A40,logic_appno,0)) | S40: =INDEX(logic_appawusa,MATCH($A40,logic_appno,0)) | T40: =INDEX(logic_appawusp,MATCH($A40,logic_appno,0))
A41: 13 | I41: =INDEX(logic_dumuapp,MATCH($A41,logic_appno,0)) | M41: =INDEX(logic_wuruapp,MATCH($A41,logic_appno,0)) | O41: =INDEX(logic_appawub,MATCH($A41,logic_appno,0)) | P41: =INDEX(logic_appawudwoaw,MATCH($A41,logic_appno,0)) | R41: =INDEX(logic_appawud,MATCH($A41,logic_appno,0)) | S41: =INDEX(logic_appawusa,MATCH($A41,logic_appno,0)) | T41: =INDEX(logic_appawusp,MATCH($A41,logic_appno,0))
A42: 14 | I42: =INDEX(logic_dumuapp,MATCH($A42,logic_appno,0)) | M42: =INDEX(logic_wuruapp,MATCH($A42,logic_appno,0)) | O42: =INDEX(logic_appawub,MATCH($A42,logic_appno,0)) | P42: =INDEX(logic_appawudwoaw,MATCH($A42,logic_appno,0)) | R42: =INDEX(logic_appawud,MATCH($A42,logic_appno,0)) | S42: =INDEX(logic_appawusa,MATCH($A42,logic_appno,0)) | T42: =INDEX(logic_appawusp,MATCH($A42,logic_appno,0))
A43: 15 | I43: =INDEX(logic_dumuapp,MATCH($A43,logic_appno,0)) | M43: =INDEX(logic_wuruapp,MATCH($A43,logic_appno,0)) | O43: =INDEX(logic_appawub,MATCH($A43,logic_appno,0)) | P43: =INDEX(logic_appawudwoaw,MATCH($A43,logic_appno,0)) | R43: =INDEX(logic_appawud,MATCH($A43,logic_appno,0)) | S43: =INDEX(logic_appawusa,MATCH($A43,logic_appno,0)) | T43: =INDEX(logic_appawusp,MATCH($A43,logic_appno,0))
A44: 16 | I44: =INDEX(logic_dumuapp,MATCH($A44,logic_appno,0)) | M44: =INDEX(logic_wuruapp,MATCH($A44,logic_appno,0)) | O44: =INDEX(logic_appawub,MATCH($A44,logic_appno,0)) | P44: =INDEX(logic_appawudwoaw,MATCH($A44,logic_appno,0)) | R44: =INDEX(logic_appawud,MATCH($A44,logic_appno,0)) | S44: =INDEX(logic_appawusa,MATCH($A44,logic_appno,0)) | T44: =INDEX(logic_appawusp,MATCH($A44,logic_appno,0))
A45: 17 | I45: =INDEX(logic_dumuapp,MATCH($A45,logic_appno,0)) | M45: =INDEX(logic_wuruapp,MATCH($A45,logic_appno,0)) | O45: =INDEX(logic_appawub,MATCH($A45,logic_appno,0)) | P45: =INDEX(logic_appawudwoaw,MATCH($A45,logic_appno,0)) | R45: =INDEX(logic_appawud,MATCH($A45,logic_appno,0)) | S45: =INDEX(logic_appawusa,MATCH($A45,logic_appno,0)) | T45: =INDEX(logic_appawusp,MATCH($A45,logic_appno,0))
A46: 18 | I46: =INDEX(logic_dumuapp,MATCH($A46,logic_appno,0)) | M46: =INDEX(logic_wuruapp,MATCH($A46,logic_appno,0)) | O46: =INDEX(logic_appawub,MATCH($A46,logic_appno,0)) | P46: =INDEX(logic_appawudwoaw,MATCH($A46,logic_appno,0)) | R46: =INDEX(logic_appawud,MATCH($A46,logic_appno,0)) | S46: =INDEX(logic_appawusa,MATCH($A46,logic_appno,0)) | T46: =INDEX(logic_appawusp,MATCH($A46,logic_appno,0))
A47: 19 | I47: =INDEX(logic_dumuapp,MATCH($A47,logic_appno,0)) | M47: =INDEX(logic_wuruapp,MATCH($A47,logic_appno,0)) | O47: =INDEX(logic_appawub,MATCH($A47,logic_appno,0)) | P47: =INDEX(logic_appawudwoaw,MATCH($A47,logic_appno,0)) | R47: =INDEX(logic_appawud,MATCH($A47,logic_appno,0)) | S47: =INDEX(logic_appawusa,MATCH($A47,logic_appno,0)) | T47: =INDEX(logic_appawusp,MATCH($A47,logic_appno,0))
A48: 20 | I48: =INDEX(logic_dumuapp,MATCH($A48,logic_appno,0)) | M48: =INDEX(logic_wuruapp,MATCH($A48,logic_appno,0)) | O48: =INDEX(logic_appawub,MATCH($A48,logic_appno,0)) | P48: =INDEX(logic_appawudwoaw,MATCH($A48,logic_appno,0)) | R48: =INDEX(logic_appawud,MATCH($A48,logic_appno,0)) | S48: =INDEX(logic_appawusa,MATCH($A48,logic_appno,0)) | T48: =INDEX(logic_appawusp,MATCH($A48,logic_appno,0))
A49: 21 | I49: =INDEX(logic_dumuapp,MATCH($A49,logic_appno,0)) | M49: =INDEX(logic_wuruapp,MATCH($A49,logic_appno,0)) | O49: =INDEX(logic_appawub,MATCH($A49,logic_appno,0)) | P49: =INDEX(logic_appawudwoaw,MATCH($A49,logic_appno,0)) | R49: =INDEX(logic_appawud,MATCH($A49,logic_appno,0)) | S49: =INDEX(logic_appawusa,MATCH($A49,logic_appno,0)) | T49: =INDEX(logic_appawusp,MATCH($A49,logic_appno,0))
A50: 22 | I50: =INDEX(logic_dumuapp,MATCH($A50,logic_appno,0)) | M50: =INDEX(logic_wuruapp,MATCH($A50,logic_appno,0)) | O50: =INDEX(logic_appawub,MATCH($A50,logic_appno,0)) | P50: =INDEX(logic_appawudwoaw,MATCH($A50,logic_appno,0)) | R50: =INDEX(logic_appawud,MATCH($A50,logic_appno,0)) | S50: =INDEX(logic_appawusa,MATCH($A50,logic_appno,0)) | T50: =INDEX(logic_appawusp,MATCH($A50,logic_appno,0))
... A58: 30 | I58: =INDEX(logic_dumuapp,MATCH($A58,logic_appno,0)) | M58: =INDEX(logic_wuruapp,MATCH($A58,logic_appno,0)) | O58: =INDEX(logic_appawub,MATCH($A58,logic_appno,0)) | P58: =INDEX(logic_appawudwoaw,MATCH($A58,logic_appno,0)) | R58: =INDEX(logic_appawud,MATCH($A58,logic_appno,0)) | S58: =INDEX(logic_appawusa,MATCH($A58,logic_appno,0)) | T58: =INDEX(logic_appawusp,MATCH($A58,logic_appno,0))
...

Sheet Logic
B2: LEED v5 Whole Project Water Use Calculator LEED for Building Design and Construction | Interior Design and Construction Logic
B4: LOGIC 1 GENERAL INFORMATION
B6: Project Type | G6: =IF(inputs_prjtyp<>"",inputs_prjtyp,"")
B8: Unit of Measurement | G8: =IF(inputs_units<>"",inputs_units,"")
B11: LOGIC 2 BASELINE AND DESIGN MODELS FROM OTHER CALCULATORS
B13: Fixtures and Fittings Water Use
B14: Unit | D14: Total Annual Water Use Baseline | E14: Total Annual Alternative Water Use (Optional) | F14: Total Annual Water Use Design (including alternative water) | H14: Total Annual Savings | J14: Total Annual Savings %
B15: =IF(logic_units<>"",INDEX(data_genunitsval,MATCH(logic_units,data_genunits,0)),"") | D15: =inputs_bdffwub -> 0 | E15: =inputs_bdffwuwa -> 0 | F15: =inputs_bdffwud -> 0 | H15: =IFERROR(IF(OR($D15<>"",$F15<>""),$D15-($F15),0),0) -> 0 | J15: =IFERROR($H15/$D15,0) -> 0
B17: Outdoor Water Use (BD+C only)
B18: Unit | D18: Total Annual Water Use Baseline | E18: Total Annual Alternative Water Use (Optional) | F18: Total Annual Water Use Design (including alternative water) | H18: Total Annual Savings | J18: Total Annual Savings %
B19: =IF(logic_units<>"",INDEX(data_genunitsval,MATCH(logic_units,data_genunits,0)),"") | D19: =inputs_bdoutwub -> 0 | E19: =inputs_bdoutwuwa -> 0 | F19: =inputs_bdoutwud -> 0 | H19: =IFERROR(IF(OR($D19<>"",$F19<>""),$D19-($F19),0),0) -> 0 | J19: =IFERROR($H19/$D19,0) -> 0
B22: LOGIC 3 APPLIANCE WATER USE BASELINE AND DESIGN MODEL
B24: Click + to the left to add additional rows. Click - to the left to collapse (content will be saved).
B25: Project Equipment Information | H25: Baseline and Design Water Use Information | O25: Water Consumption
A26: - | B26: Appliance ID (Optional) | C26: Quantity (Optional) | D26: Water Use Type | F26: Annual Days of Operation | G26: Cycles per Day | H26: Daily Usage Multiplier | K26: Water Use Rate | O26: =CONCATENATE("Annual Water Use Baseline (",(IF(inputs_units<>"",INDEX(data_genunitsvol,MATCH(inputs_units,data_genunits,0)),"unit")),")") -> Annual Water Use Baseline (unit) | P26: =CONCATENATE("Annual Water Use Design w/o Alt. Water (",(IF(inputs_units<>"",INDEX(data_genunitsvol,MATCH(inputs_units,data_genunits,0)),"unit")),")") -> Annual Water Use Design w/o Alt. Water (unit) | Q26: =CONCATENATE("Annual Alternative Water Use (",(IF(inputs_units<>"",INDEX(data_genunitsvol,MATCH(inputs_units,data_genunits,0)),"unit")),")") -> Annual Alternative Water Use (unit) | R26: =CONCATENATE("Annual Water Use Design (",(IF(inputs_units<>"",INDEX(data_genunitsvol,MATCH(inputs_units,data_genunits,0)),"unit")),")") -> Annual Water Use Design (unit) | S26: =CONCATENATE("Annual Water Use Savings (",(IF(inputs_units<>"",INDEX(data_genunitsvol,MATCH(inputs_units,data_genunits,0)),"unit")),")") -> Annual Water Use Savings (unit) | T26: AnnualWater Use Savings (%)
H27: Value | I27: Unit | K27: Equipment Baseline Water Use | L27: Equipment Design Water Use | M27: Unit
Q28: (Optional)
A29: 1 | B29: =(IF('Inputs Whole-Project Water Use'!B29<>"",'Inputs Whole-Project Water Use'!B29,"")) | C29: =IF(AND(D29<>"",'Inputs Whole-Project Water Use'!C29=""),1,IF('Inputs Whole-Project Water Use'!C29<>"",'Inputs Whole-Project Water Use'!C29,"")) | D29: =IF('Inputs Whole-Project Water Use'!D29<>"",'Inputs Whole-Project Water Use'!D29,"") | F29: =IF('Inputs Whole-Project Water Use'!F29<>"",'Inputs Whole-Project Water Use'!F29,"") | G29: =IF('Inputs Whole-Project Water Use'!G29<>"",'Inputs Whole-Project Water Use'!G29,"") | H29: =IF('Inputs Whole-Project Water Use'!H29<>"",'Inputs Whole-Project Water Use'!H29,"") | I29: =IFERROR(IF(logic_units<>"SI Units",INDEX(data_dumip,MATCH($D29,data_waterusetypes,0)),INDEX(data_dumsi,MATCH($D29,data_waterusetypes,0))),"") | K29: =IF('Inputs Whole-Project Water Use'!K29<>"",'Inputs Whole-Project Water Use'!K29,"") | L29: =IF('Inputs Whole-Project Water Use'!L29<>"",'Inputs Whole-Project Water Use'!L29,"") | M29: =IFERROR(IF(logic_units<>"SI Units",INDEX(data_wurip,MATCH($D29,data_waterusetypes,0)),INDEX(data_wursi,MATCH($D29,data_waterusetypes,0))),"") | O29: =IFERROR(IF(OR($F29<>"",$G29<>"",$H29<>"",K29<>""),$C29*$F29*$G29*$H29*K29,""),"") | P29: =IFERROR(IF(OR($F29<>"",$G29<>"",$H29<>"",L29<>""),$C29*$F29*$G29*$H29*L29,""),"") | Q29: =IF(AND(D29<>"",'Inputs Whole-Project Water Use'!Q29=""),0,IF('Inputs Whole-Project Water Use'!Q29<>"",'Inputs Whole-Project Water Use'!Q29,"")) | R29: =IFERROR(IF(P29<>"",(P29-Q29),""),"") | S29: =IFERROR(IF(OR(O29<>"",P29<>""),O29-R29,""),"") | T29: =IFERROR(S29/O29,"")
A30: 2 | B30: =(IF('Inputs Whole-Project Water Use'!B30<>"",'Inputs Whole-Project Water Use'!B30,"")) | C30: =IF(AND(D30<>"",'Inputs Whole-Project Water Use'!C30=""),1,IF('Inputs Whole-Project Water Use'!C30<>"",'Inputs Whole-Project Water Use'!C30,"")) | D30: =IF('Inputs Whole-Project Water Use'!D30<>"",'Inputs Whole-Project Water Use'!D30,"") | F30: =IF('Inputs Whole-Project Water Use'!F30<>"",'Inputs Whole-Project Water Use'!F30,"") | G30: =IF('Inputs Whole-Project Water Use'!G30<>"",'Inputs Whole-Project Water Use'!G30,"") | H30: =IF('Inputs Whole-Project Water Use'!H30<>"",'Inputs Whole-Project Water Use'!H30,"") | I30: =IFERROR(IF(logic_units<>"SI Units",INDEX(data_dumip,MATCH($D30,data_waterusetypes,0)),INDEX(data_dumsi,MATCH($D30,data_waterusetypes,0))),"") | K30: =IF('Inputs Whole-Project Water Use'!K30<>"",'Inputs Whole-Project Water Use'!K30,"") | L30: =IF('Inputs Whole-Project Water Use'!L30<>"",'Inputs Whole-Project Water Use'!L30,"") | M30: =IFERROR(IF(logic_units<>"SI Units",INDEX(data_wurip,MATCH($D30,data_waterusetypes,0)),INDEX(data_wursi,MATCH($D30,data_waterusetypes,0))),"") | O30: =IFERROR(IF(OR($F30<>"",$G30<>"",$H30<>"",K30<>""),$C30*$F30*$G30*$H30*K30,""),"") | P30: =IFERROR(IF(OR($F30<>"",$G30<>"",$H30<>"",L30<>""),$C30*$F30*$G30*$H30*L30,""),"") | Q30: =IF(AND(D30<>"",'Inputs Whole-Project Water Use'!Q30=""),0,IF('Inputs Whole-Project Water Use'!Q30<>"",'Inputs Whole-Project Water Use'!Q30,"")) | R30: =IFERROR(IF(P30<>"",(P30-Q30),""),"") | S30: =IFERROR(IF(OR(O30<>"",P30<>""),O30-R30,""),"") | T30: =IFERROR(S30/O30,"")
A31: 3 | B31: =(IF('Inputs Whole-Project Water Use'!B31<>"",'Inputs Whole-Project Water Use'!B31,"")) | C31: =IF(AND(D31<>"",'Inputs Whole-Project Water Use'!C31=""),1,IF('Inputs Whole-Project Water Use'!C31<>"",'Inputs Whole-Project Water Use'!C31,"")) | D31: =IF('Inputs Whole-Project Water Use'!D31<>"",'Inputs Whole-Project Water Use'!D31,"") | F31: =IF('Inputs Whole-Project Water Use'!F31<>"",'Inputs Whole-Project Water Use'!F31,"") | G31: =IF('Inputs Whole-Project Water Use'!G31<>"",'Inputs Whole-Project Water Use'!G31,"") | H31: =IF('Inputs Whole-Project Water Use'!H31<>"",'Inputs Whole-Project Water Use'!H31,"") | I31: =IFERROR(IF(logic_units<>"SI Units",INDEX(data_dumip,MATCH($D31,data_waterusetypes,0)),INDEX(data_dumsi,MATCH($D31,data_waterusetypes,0))),"") | K31: =IF('Inputs Whole-Project Water Use'!K31<>"",'Inputs Whole-Project Water Use'!K31,"") | L31: =IF('Inputs Whole-Project Water Use'!L31<>"",'Inputs Whole-Project Water Use'!L31,"") | M31: =IFERROR(IF(logic_units<>"SI Units",INDEX(data_wurip,MATCH($D31,data_waterusetypes,0)),INDEX(data_wursi,MATCH($D31,data_waterusetypes,0))),"") | O31: =IFERROR(IF(OR($F31<>"",$G31<>"",$H31<>"",K31<>""),$C31*$F31*$G31*$H31*K31,""),"") | P31: =IFERROR(IF(OR($F31<>"",$G31<>"",$H31<>"",L31<>""),$C31*$F31*$G31*$H31*L31,""),"") | Q31: =IF(AND(D31<>"",'Inputs Whole-Project Water Use'!Q31=""),0,IF('Inputs Whole-Project Water Use'!Q31<>"",'Inputs Whole-Project Water Use'!Q31,"")) | R31: =IFERROR(IF(P31<>"",(P31-Q31),""),"") | S31: =IFERROR(IF(OR(O31<>"",P31<>""),O31-R31,""),"") | T31: =IFERROR(S31/O31,"")
A32: 4 | B32: =(IF('Inputs Whole-Project Water Use'!B32<>"",'Inputs Whole-Project Water Use'!B32,"")) | C32: =IF(AND(D32<>"",'Inputs Whole-Project Water Use'!C32=""),1,IF('Inputs Whole-Project Water Use'!C32<>"",'Inputs Whole-Project Water Use'!C32,"")) | D32: =IF('Inputs Whole-Project Water Use'!D32<>"",'Inputs Whole-Project Water Use'!D32,"") | F32: =IF('Inputs Whole-Project Water Use'!F32<>"",'Inputs Whole-Project Water Use'!F32,"") | G32: =IF('Inputs Whole-Project Water Use'!G32<>"",'Inputs Whole-Project Water Use'!G32,"") | H32: =IF('Inputs Whole-Project Water Use'!H32<>"",'Inputs Whole-Project Water Use'!H32,"") | I32: =IFERROR(IF(logic_units<>"SI Units",INDEX(data_dumip,MATCH($D32,data_waterusetypes,0)),INDEX(data_dumsi,MATCH($D32,data_waterusetypes,0))),"") | K32: =IF('Inputs Whole-Project Water Use'!K32<>"",'Inputs Whole-Project Water Use'!K32,"") | L32: =IF('Inputs Whole-Project Water Use'!L32<>"",'Inputs Whole-Project Water Use'!L32,"") | M32: =IFERROR(IF(logic_units<>"SI Units",INDEX(data_wurip,MATCH($D32,data_waterusetypes,0)),INDEX(data_wursi,MATCH($D32,data_waterusetypes,0))),"") | O32: =IFERROR(IF(OR($F32<>"",$G32<>"",$H32<>"",K32<>""),$C32*$F32*$G32*$H32*K32,""),"") | P32: =IFERROR(IF(OR($F32<>"",$G32<>"",$H32<>"",L32<>""),$C32*$F32*$G32*$H32*L32,""),"") | Q32: =IF(AND(D32<>"",'Inputs Whole-Project Water Use'!Q32=""),0,IF('Inputs Whole-Project Water Use'!Q32<>"",'Inputs Whole-Project Water Use'!Q32,"")) | R32: =IFERROR(IF(P32<>"",(P32-Q32),""),"") | S32: =IFERROR(IF(OR(O32<>"",P32<>""),O32-R32,""),"") | T32: =IFERROR(S32/O32,"")
A33: 5 | B33: =(IF('Inputs Whole-Project Water Use'!B33<>"",'Inputs Whole-Project Water Use'!B33,"")) | C33: =IF(AND(D33<>"",'Inputs Whole-Project Water Use'!C33=""),1,IF('Inputs Whole-Project Water Use'!C33<>"",'Inputs Whole-Project Water Use'!C33,"")) | D33: =IF('Inputs Whole-Project Water Use'!D33<>"",'Inputs Whole-Project Water Use'!D33,"") | F33: =IF('Inputs Whole-Project Water Use'!F33<>"",'Inputs Whole-Project Water Use'!F33,"") | G33: =IF('Inputs Whole-Project Water Use'!G33<>"",'Inputs Whole-Project Water Use'!G33,"") | H33: =IF('Inputs Whole-Project Water Use'!H33<>"",'Inputs Whole-Project Water Use'!H33,"") | I33: =IFERROR(IF(logic_units<>"SI Units",INDEX(data_dumip,MATCH($D33,data_waterusetypes,0)),INDEX(data_dumsi,MATCH($D33,data_waterusetypes,0))),"") | K33: =IF('Inputs Whole-Project Water Use'!K33<>"",'Inputs Whole-Project Water Use'!K33,"") | L33: =IF('Inputs Whole-Project Water Use'!L33<>"",'Inputs Whole-Project Water Use'!L33,"") | M33: =IFERROR(IF(logic_units<>"SI Units",INDEX(data_wurip,MATCH($D33,data_waterusetypes,0)),INDEX(data_wursi,MATCH($D33,data_waterusetypes,0))),"") | O33: =IFERROR(IF(OR($F33<>"",$G33<>"",$H33<>"",K33<>""),$C33*$F33*$G33*$H33*K33,""),"") | P33: =IFERROR(IF(OR($F33<>"",$G33<>"",$H33<>"",L33<>""),$C33*$F33*$G33*$H33*L33,""),"") | Q33: =IF(AND(D33<>"",'Inputs Whole-Project Water Use'!Q33=""),0,IF('Inputs Whole-Project Water Use'!Q33<>"",'Inputs Whole-Project Water Use'!Q33,"")) | R33: =IFERROR(IF(P33<>"",(P33-Q33),""),"") | S33: =IFERROR(IF(OR(O33<>"",P33<>""),O33-R33,""),"") | T33: =IFERROR(S33/O33,"")
A34: 6 | B34: =(IF('Inputs Whole-Project Water Use'!B34<>"",'Inputs Whole-Project Water Use'!B34,"")) | C34: =IF(AND(D34<>"",'Inputs Whole-Project Water Use'!C34=""),1,IF('Inputs Whole-Project Water Use'!C34<>"",'Inputs Whole-Project Water Use'!C34,"")) | D34: =IF('Inputs Whole-Project Water Use'!D34<>"",'Inputs Whole-Project Water Use'!D34,"") | F34: =IF('Inputs Whole-Project Water Use'!F34<>"",'Inputs Whole-Project Water Use'!F34,"") | G34: =IF('Inputs Whole-Project Water Use'!G34<>"",'Inputs Whole-Project Water Use'!G34,"") | H34: =IF('Inputs Whole-Project Water Use'!H34<>"",'Inputs Whole-Project Water Use'!H34,"") | I34: =IFERROR(IF(logic_units<>"SI Units",INDEX(data_dumip,MATCH($D34,data_waterusetypes,0)),INDEX(data_dumsi,MATCH($D34,data_waterusetypes,0))),"") | K34: =IF('Inputs Whole-Project Water Use'!K34<>"",'Inputs Whole-Project Water Use'!K34,"") | L34: =IF('Inputs Whole-Project Water Use'!L34<>"",'Inputs Whole-Project Water Use'!L34,"") | M34: =IFERROR(IF(logic_units<>"SI Units",INDEX(data_wurip,MATCH($D34,data_waterusetypes,0)),INDEX(data_wursi,MATCH($D34,data_waterusetypes,0))),"") | O34: =IFERROR(IF(OR($F34<>"",$G34<>"",$H34<>"",K34<>""),$C34*$F34*$G34*$H34*K34,""),"") | P34: =IFERROR(IF(OR($F34<>"",$G34<>"",$H34<>"",L34<>""),$C34*$F34*$G34*$H34*L34,""),"") | Q34: =IF(AND(D34<>"",'Inputs Whole-Project Water Use'!Q34=""),0,IF('Inputs Whole-Project Water Use'!Q34<>"",'Inputs Whole-Project Water Use'!Q34,"")) | R34: =IFERROR(IF(P34<>"",(P34-Q34),""),"") | S34: =IFERROR(IF(OR(O34<>"",P34<>""),O34-R34,""),"") | T34: =IFERROR(S34/O34,"")
A35: 7 | B35: =(IF('Inputs Whole-Project Water Use'!B35<>"",'Inputs Whole-Project Water Use'!B35,"")) | C35: =IF(AND(D35<>"",'Inputs Whole-Project Water Use'!C35=""),1,IF('Inputs Whole-Project Water Use'!C35<>"",'Inputs Whole-Project Water Use'!C35,"")) | D35: =IF('Inputs Whole-Project Water Use'!D35<>"",'Inputs Whole-Project Water Use'!D35,"") | F35: =IF('Inputs Whole-Project Water Use'!F35<>"",'Inputs Whole-Project Water Use'!F35,"") | G35: =IF('Inputs Whole-Project Water Use'!G35<>"",'Inputs Whole-Project Water Use'!G35,"") | H35: =IF('Inputs Whole-Project Water Use'!H35<>"",'Inputs Whole-Project Water Use'!H35,"") | I35: =IFERROR(IF(logic_units<>"SI Units",INDEX(data_dumip,MATCH($D35,data_waterusetypes,0)),INDEX(data_dumsi,MATCH($D35,data_waterusetypes,0))),"") | K35: =IF('Inputs Whole-Project Water Use'!K35<>"",'Inputs Whole-Project Water Use'!K35,"") | L35: =IF('Inputs Whole-Project Water Use'!L35<>"",'Inputs Whole-Project Water Use'!L35,"") | M35: =IFERROR(IF(logic_units<>"SI Units",INDEX(data_wurip,MATCH($D35,data_waterusetypes,0)),INDEX(data_wursi,MATCH($D35,data_waterusetypes,0))),"") | O35: =IFERROR(IF(OR($F35<>"",$G35<>"",$H35<>"",K35<>""),$C35*$F35*$G35*$H35*K35,""),"") | P35: =IFERROR(IF(OR($F35<>"",$G35<>"",$H35<>"",L35<>""),$C35*$F35*$G35*$H35*L35,""),"") | Q35: =IF(AND(D35<>"",'Inputs Whole-Project Water Use'!Q35=""),0,IF('Inputs Whole-Project Water Use'!Q35<>"",'Inputs Whole-Project Water Use'!Q35,"")) | R35: =IFERROR(IF(P35<>"",(P35-Q35),""),"") | S35: =IFERROR(IF(OR(O35<>"",P35<>""),O35-R35,""),"") | T35: =IFERROR(S35/O35,"")
A36: 8 | B36: =(IF('Inputs Whole-Project Water Use'!B36<>"",'Inputs Whole-Project Water Use'!B36,"")) | C36: =IF(AND(D36<>"",'Inputs Whole-Project Water Use'!C36=""),1,IF('Inputs Whole-Project Water Use'!C36<>"",'Inputs Whole-Project Water Use'!C36,"")) | D36: =IF('Inputs Whole-Project Water Use'!D36<>"",'Inputs Whole-Project Water Use'!D36,"") | F36: =IF('Inputs Whole-Project Water Use'!F36<>"",'Inputs Whole-Project Water Use'!F36,"") | G36: =IF('Inputs Whole-Project Water Use'!G36<>"",'Inputs Whole-Project Water Use'!G36,"") | H36: =IF('Inputs Whole-Project Water Use'!H36<>"",'Inputs Whole-Project Water Use'!H36,"") | I36: =IFERROR(IF(logic_units<>"SI Units",INDEX(data_dumip,MATCH($D36,data_waterusetypes,0)),INDEX(data_dumsi,MATCH($D36,data_waterusetypes,0))),"") | K36: =IF('Inputs Whole-Project Water Use'!K36<>"",'Inputs Whole-Project Water Use'!K36,"") | L36: =IF('Inputs Whole-Project Water Use'!L36<>"",'Inputs Whole-Project Water Use'!L36,"") | M36: =IFERROR(IF(logic_units<>"SI Units",INDEX(data_wurip,MATCH($D36,data_waterusetypes,0)),INDEX(data_wursi,MATCH($D36,data_waterusetypes,0))),"") | O36: =IFERROR(IF(OR($F36<>"",$G36<>"",$H36<>"",K36<>""),$C36*$F36*$G36*$H36*K36,""),"") | P36: =IFERROR(IF(OR($F36<>"",$G36<>"",$H36<>"",L36<>""),$C36*$F36*$G36*$H36*L36,""),"") | Q36: =IF(AND(D36<>"",'Inputs Whole-Project Water Use'!Q36=""),0,IF('Inputs Whole-Project Water Use'!Q36<>"",'Inputs Whole-Project Water Use'!Q36,"")) | R36: =IFERROR(IF(P36<>"",(P36-Q36),""),"") | S36: =IFERROR(IF(OR(O36<>"",P36<>""),O36-R36,""),"") | T36: =IFERROR(S36/O36,"")
A37: 9 | B37: =(IF('Inputs Whole-Project Water Use'!B37<>"",'Inputs Whole-Project Water Use'!B37,"")) | C37: =IF(AND(D37<>"",'Inputs Whole-Project Water Use'!C37=""),1,IF('Inputs Whole-Project Water Use'!C37<>"",'Inputs Whole-Project Water Use'!C37,"")) | D37: =IF('Inputs Whole-Project Water Use'!D37<>"",'Inputs Whole-Project Water Use'!D37,"") | F37: =IF('Inputs Whole-Project Water Use'!F37<>"",'Inputs Whole-Project Water Use'!F37,"") | G37: =IF('Inputs Whole-Project Water Use'!G37<>"",'Inputs Whole-Project Water Use'!G37,"") | H37: =IF('Inputs Whole-Project Water Use'!H37<>"",'Inputs Whole-Project Water Use'!H37,"") | I37: =IFERROR(IF(logic_units<>"SI Units",INDEX(data_dumip,MATCH($D37,data_waterusetypes,0)),INDEX(data_dumsi,MATCH($D37,data_waterusetypes,0))),"") | K37: =IF('Inputs Whole-Project Water Use'!K37<>"",'Inputs Whole-Project Water Use'!K37,"") | L37: =IF('Inputs Whole-Project Water Use'!L37<>"",'Inputs Whole-Project Water Use'!L37,"") | M37: =IFERROR(IF(logic_units<>"SI Units",INDEX(data_wurip,MATCH($D37,data_waterusetypes,0)),INDEX(data_wursi,MATCH($D37,data_waterusetypes,0))),"") | O37: =IFERROR(IF(OR($F37<>"",$G37<>"",$H37<>"",K37<>""),$C37*$F37*$G37*$H37*K37,""),"") | P37: =IFERROR(IF(OR($F37<>"",$G37<>"",$H37<>"",L37<>""),$C37*$F37*$G37*$H37*L37,""),"") | Q37: =IF(AND(D37<>"",'Inputs Whole-Project Water Use'!Q37=""),0,IF('Inputs Whole-Project Water Use'!Q37<>"",'Inputs Whole-Project Water Use'!Q37,"")) | R37: =IFERROR(IF(P37<>"",(P37-Q37),""),"") | S37: =IFERROR(IF(OR(O37<>"",P37<>""),O37-R37,""),"") | T37: =IFERROR(S37/O37,"")
A38: 10 | B38: =(IF('Inputs Whole-Project Water Use'!B38<>"",'Inputs Whole-Project Water Use'!B38,"")) | C38: =IF(AND(D38<>"",'Inputs Whole-Project Water Use'!C38=""),1,IF('Inputs Whole-Project Water Use'!C38<>"",'Inputs Whole-Project Water Use'!C38,"")) | D38: =IF('Inputs Whole-Project Water Use'!D38<>"",'Inputs Whole-Project Water Use'!D38,"") | F38: =IF('Inputs Whole-Project Water Use'!F38<>"",'Inputs Whole-Project Water Use'!F38,"") | G38: =IF('Inputs Whole-Project Water Use'!G38<>"",'Inputs Whole-Project Water Use'!G38,"") | H38: =IF('Inputs Whole-Project Water Use'!H38<>"",'Inputs Whole-Project Water Use'!H38,"") | I38: =IFERROR(IF(logic_units<>"SI Units",INDEX(data_dumip,MATCH($D38,data_waterusetypes,0)),INDEX(data_dumsi,MATCH($D38,data_waterusetypes,0))),"") | K38: =IF('Inputs Whole-Project Water Use'!K38<>"",'Inputs Whole-Project Water Use'!K38,"") | L38: =IF('Inputs Whole-Project Water Use'!L38<>"",'Inputs Whole-Project Water Use'!L38,"") | M38: =IFERROR(IF(logic_units<>"SI Units",INDEX(data_wurip,MATCH($D38,data_waterusetypes,0)),INDEX(data_wursi,MATCH($D38,data_waterusetypes,0))),"") | O38: =IFERROR(IF(OR($F38<>"",$G38<>"",$H38<>"",K38<>""),$C38*$F38*$G38*$H38*K38,""),"") | P38: =IFERROR(IF(OR($F38<>"",$G38<>"",$H38<>"",L38<>""),$C38*$F38*$G38*$H38*L38,""),"") | Q38: =IF(AND(D38<>"",'Inputs Whole-Project Water Use'!Q38=""),0,IF('Inputs Whole-Project Water Use'!Q38<>"",'Inputs Whole-Project Water Use'!Q38,"")) | R38: =IFERROR(IF(P38<>"",(P38-Q38),""),"") | S38: =IFERROR(IF(OR(O38<>"",P38<>""),O38-R38,""),"") | T38: =IFERROR(S38/O38,"") | U38: Click + to left for additional rows
A39: 11 | B39: =(IF('Inputs Whole-Project Water Use'!B39<>"",'Inputs Whole-Project Water Use'!B39,"")) | C39: =IF(AND(D39<>"",'Inputs Whole-Project Water Use'!C39=""),1,IF('Inputs Whole-Project Water Use'!C39<>"",'Inputs Whole-Project Water Use'!C39,"")) | D39: =IF('Inputs Whole-Project Water Use'!D39<>"",'Inputs Whole-Project Water Use'!D39,"") | F39: =IF('Inputs Whole-Project Water Use'!F39<>"",'Inputs Whole-Project Water Use'!F39,"") | G39: =IF('Inputs Whole-Project Water Use'!G39<>"",'Inputs Whole-Project Water Use'!G39,"") | H39: =IF('Inputs Whole-Project Water Use'!H39<>"",'Inputs Whole-Project Water Use'!H39,"") | I39: =IFERROR(IF(logic_units<>"SI Units",INDEX(data_dumip,MATCH($D39,data_waterusetypes,0)),INDEX(data_dumsi,MATCH($D39,data_waterusetypes,0))),"") | K39: =IF('Inputs Whole-Project Water Use'!K39<>"",'Inputs Whole-Project Water Use'!K39,"") | L39: =IF('Inputs Whole-Project Water Use'!L39<>"",'Inputs Whole-Project Water Use'!L39,"") | M39: =IFERROR(IF(logic_units<>"SI Units",INDEX(data_wurip,MATCH($D39,data_waterusetypes,0)),INDEX(data_wursi,MATCH($D39,data_waterusetypes,0))),"") | O39: =IFERROR(IF(OR($F39<>"",$G39<>"",$H39<>"",K39<>""),$C39*$F39*$G39*$H39*K39,""),"") | P39: =IFERROR(IF(OR($F39<>"",$G39<>"",$H39<>"",L39<>""),$C39*$F39*$G39*$H39*L39,""),"") | Q39: =IF(AND(D39<>"",'Inputs Whole-Project Water Use'!Q39=""),0,IF('Inputs Whole-Project Water Use'!Q39<>"",'Inputs Whole-Project Water Use'!Q39,"")) | R39: =IFERROR(IF(P39<>"",(P39-Q39),""),"") | S39: =IFERROR(IF(OR(O39<>"",P39<>""),O39-R39,""),"") | T39: =IFERROR(S39/O39,"")
A40: 12 | B40: =(IF('Inputs Whole-Project Water Use'!B40<>"",'Inputs Whole-Project Water Use'!B40,"")) | C40: =IF(AND(D40<>"",'Inputs Whole-Project Water Use'!C40=""),1,IF('Inputs Whole-Project Water Use'!C40<>"",'Inputs Whole-Project Water Use'!C40,"")) | D40: =IF('Inputs Whole-Project Water Use'!D40<>"",'Inputs Whole-Project Water Use'!D40,"") | F40: =IF('Inputs Whole-Project Water Use'!F40<>"",'Inputs Whole-Project Water Use'!F40,"") | G40: =IF('Inputs Whole-Project Water Use'!G40<>"",'Inputs Whole-Project Water Use'!G40,"") | H40: =IF('Inputs Whole-Project Water Use'!H40<>"",'Inputs Whole-Project Water Use'!H40,"") | I40: =IFERROR(IF(logic_units<>"SI Units",INDEX(data_dumip,MATCH($D40,data_waterusetypes,0)),INDEX(data_dumsi,MATCH($D40,data_waterusetypes,0))),"") | K40: =IF('Inputs Whole-Project Water Use'!K40<>"",'Inputs Whole-Project Water Use'!K40,"") | L40: =IF('Inputs Whole-Project Water Use'!L40<>"",'Inputs Whole-Project Water Use'!L40,"") | M40: =IFERROR(IF(logic_units<>"SI Units",INDEX(data_wurip,MATCH($D40,data_waterusetypes,0)),INDEX(data_wursi,MATCH($D40,data_waterusetypes,0))),"") | O40: =IFERROR(IF(OR($F40<>"",$G40<>"",$H40<>"",K40<>""),$C40*$F40*$G40*$H40*K40,""),"") | P40: =IFERROR(IF(OR($F40<>"",$G40<>"",$H40<>"",L40<>""),$C40*$F40*$G40*$H40*L40,""),"") | Q40: =IF(AND(D40<>"",'Inputs Whole-Project Water Use'!Q40=""),0,IF('Inputs Whole-Project Water Use'!Q40<>"",'Inputs Whole-Project Water Use'!Q40,"")) | R40: =IFERROR(IF(P40<>"",(P40-Q40),""),"") | S40: =IFERROR(IF(OR(O40<>"",P40<>""),O40-R40,""),"") | T40: =IFERROR(S40/O40,"")
A41: 13 | B41: =(IF('Inputs Whole-Project Water Use'!B41<>"",'Inputs Whole-Project Water Use'!B41,"")) | C41: =IF(AND(D41<>"",'Inputs Whole-Project Water Use'!C41=""),1,IF('Inputs Whole-Project Water Use'!C41<>"",'Inputs Whole-Project Water Use'!C41,"")) | D41: =IF('Inputs Whole-Project Water Use'!D41<>"",'Inputs Whole-Project Water Use'!D41,"") | F41: =IF('Inputs Whole-Project Water Use'!F41<>"",'Inputs Whole-Project Water Use'!F41,"") | G41: =IF('Inputs Whole-Project Water Use'!G41<>"",'Inputs Whole-Project Water Use'!G41,"") | H41: =IF('Inputs Whole-Project Water Use'!H41<>"",'Inputs Whole-Project Water Use'!H41,"") | I41: =IFERROR(IF(logic_units<>"SI Units",INDEX(data_dumip,MATCH($D41,data_waterusetypes,0)),INDEX(data_dumsi,MATCH($D41,data_waterusetypes,0))),"") | K41: =IF('Inputs Whole-Project Water Use'!K41<>"",'Inputs Whole-Project Water Use'!K41,"") | L41: =IF('Inputs Whole-Project Water Use'!L41<>"",'Inputs Whole-Project Water Use'!L41,"") | M41: =IFERROR(IF(logic_units<>"SI Units",INDEX(data_wurip,MATCH($D41,data_waterusetypes,0)),INDEX(data_wursi,MATCH($D41,data_waterusetypes,0))),"") | O41: =IFERROR(IF(OR($F41<>"",$G41<>"",$H41<>"",K41<>""),$C41*$F41*$G41*$H41*K41,""),"") | P41: =IFERROR(IF(OR($F41<>"",$G41<>"",$H41<>"",L41<>""),$C41*$F41*$G41*$H41*L41,""),"") | Q41: =IF(AND(D41<>"",'Inputs Whole-Project Water Use'!Q41=""),0,IF('Inputs Whole-Project Water Use'!Q41<>"",'Inputs Whole-Project Water Use'!Q41,"")) | R41: =IFERROR(IF(P41<>"",(P41-Q41),""),"") | S41: =IFERROR(IF(OR(O41<>"",P41<>""),O41-R41,""),"") | T41: =IFERROR(S41/O41,"")
A42: 14 | B42: =(IF('Inputs Whole-Project Water Use'!B42<>"",'Inputs Whole-Project Water Use'!B42,"")) | C42: =IF(AND(D42<>"",'Inputs Whole-Project Water Use'!C42=""),1,IF('Inputs Whole-Project Water Use'!C42<>"",'Inputs Whole-Project Water Use'!C42,"")) | D42: =IF('Inputs Whole-Project Water Use'!D42<>"",'Inputs Whole-Project Water Use'!D42,"") | F42: =IF('Inputs Whole-Project Water Use'!F42<>"",'Inputs Whole-Project Water Use'!F42,"") | G42: =IF('Inputs Whole-Project Water Use'!G42<>"",'Inputs Whole-Project Water Use'!G42,"") | H42: =IF('Inputs Whole-Project Water Use'!H42<>"",'Inputs Whole-Project Water Use'!H42,"") | I42: =IFERROR(IF(logic_units<>"SI Units",INDEX(data_dumip,MATCH($D42,data_waterusetypes,0)),INDEX(data_dumsi,MATCH($D42,data_waterusetypes,0))),"") | K42: =IF('Inputs Whole-Project Water Use'!K42<>"",'Inputs Whole-Project Water Use'!K42,"") | L42: =IF('Inputs Whole-Project Water Use'!L42<>"",'Inputs Whole-Project Water Use'!L42,"") | M42: =IFERROR(IF(logic_units<>"SI Units",INDEX(data_wurip,MATCH($D42,data_waterusetypes,0)),INDEX(data_wursi,MATCH($D42,data_waterusetypes,0))),"") | O42: =IFERROR(IF(OR($F42<>"",$G42<>"",$H42<>"",K42<>""),$C42*$F42*$G42*$H42*K42,""),"") | P42: =IFERROR(IF(OR($F42<>"",$G42<>"",$H42<>"",L42<>""),$C42*$F42*$G42*$H42*L42,""),"") | Q42: =IF(AND(D42<>"",'Inputs Whole-Project Water Use'!Q42=""),0,IF('Inputs Whole-Project Water Use'!Q42<>"",'Inputs Whole-Project Water Use'!Q42,"")) | R42: =IFERROR(IF(P42<>"",(P42-Q42),""),"") | S42: =IFERROR(IF(OR(O42<>"",P42<>""),O42-R42,""),"") | T42: =IFERROR(S42/O42,"")
A43: 15 | B43: =(IF('Inputs Whole-Project Water Use'!B43<>"",'Inputs Whole-Project Water Use'!B43,"")) | C43: =IF(AND(D43<>"",'Inputs Whole-Project Water Use'!C43=""),1,IF('Inputs Whole-Project Water Use'!C43<>"",'Inputs Whole-Project Water Use'!C43,"")) | D43: =IF('Inputs Whole-Project Water Use'!D43<>"",'Inputs Whole-Project Water Use'!D43,"") | F43: =IF('Inputs Whole-Project Water Use'!F43<>"",'Inputs Whole-Project Water Use'!F43,"") | G43: =IF('Inputs Whole-Project Water Use'!G43<>"",'Inputs Whole-Project Water Use'!G43,"") | H43: =IF('Inputs Whole-Project Water Use'!H43<>"",'Inputs Whole-Project Water Use'!H43,"") | I43: =IFERROR(IF(logic_units<>"SI Units",INDEX(data_dumip,MATCH($D43,data_waterusetypes,0)),INDEX(data_dumsi,MATCH($D43,data_waterusetypes,0))),"") | K43: =IF('Inputs Whole-Project Water Use'!K43<>"",'Inputs Whole-Project Water Use'!K43,"") | L43: =IF('Inputs Whole-Project Water Use'!L43<>"",'Inputs Whole-Project Water Use'!L43,"") | M43: =IFERROR(IF(logic_units<>"SI Units",INDEX(data_wurip,MATCH($D43,data_waterusetypes,0)),INDEX(data_wursi,MATCH($D43,data_waterusetypes,0))),"") | O43: =IFERROR(IF(OR($F43<>"",$G43<>"",$H43<>"",K43<>""),$C43*$F43*$G43*$H43*K43,""),"") | P43: =IFERROR(IF(OR($F43<>"",$G43<>"",$H43<>"",L43<>""),$C43*$F43*$G43*$H43*L43,""),"") | Q43: =IF(AND(D43<>"",'Inputs Whole-Project Water Use'!Q43=""),0,IF('Inputs Whole-Project Water Use'!Q43<>"",'Inputs Whole-Project Water Use'!Q43,"")) | R43: =IFERROR(IF(P43<>"",(P43-Q43),""),"") | S43: =IFERROR(IF(OR(O43<>"",P43<>""),O43-R43,""),"") | T43: =IFERROR(S43/O43,"")
A44: 16 | B44: =(IF('Inputs Whole-Project Water Use'!B44<>"",'Inputs Whole-Project Water Use'!B44,"")) | C44: =IF(AND(D44<>"",'Inputs Whole-Project Water Use'!C44=""),1,IF('Inputs Whole-Project Water Use'!C44<>"",'Inputs Whole-Project Water Use'!C44,"")) | D44: =IF('Inputs Whole-Project Water Use'!D44<>"",'Inputs Whole-Project Water Use'!D44,"") | F44: =IF('Inputs Whole-Project Water Use'!F44<>"",'Inputs Whole-Project Water Use'!F44,"") | G44: =IF('Inputs Whole-Project Water Use'!G44<>"",'Inputs Whole-Project Water Use'!G44,"") | H44: =IF('Inputs Whole-Project Water Use'!H44<>"",'Inputs Whole-Project Water Use'!H44,"") | I44: =IFERROR(IF(logic_units<>"SI Units",INDEX(data_dumip,MATCH($D44,data_waterusetypes,0)),INDEX(data_dumsi,MATCH($D44,data_waterusetypes,0))),"") | K44: =IF('Inputs Whole-Project Water Use'!K44<>"",'Inputs Whole-Project Water Use'!K44,"") | L44: =IF('Inputs Whole-Project Water Use'!L44<>"",'Inputs Whole-Project Water Use'!L44,"") | M44: =IFERROR(IF(logic_units<>"SI Units",INDEX(data_wurip,MATCH($D44,data_waterusetypes,0)),INDEX(data_wursi,MATCH($D44,data_waterusetypes,0))),"") | O44: =IFERROR(IF(OR($F44<>"",$G44<>"",$H44<>"",K44<>""),$C44*$F44*$G44*$H44*K44,""),"") | P44: =IFERROR(IF(OR($F44<>"",$G44<>"",$H44<>"",L44<>""),$C44*$F44*$G44*$H44*L44,""),"") | Q44: =IF(AND(D44<>"",'Inputs Whole-Project Water Use'!Q44=""),0,IF('Inputs Whole-Project Water Use'!Q44<>"",'Inputs Whole-Project Water Use'!Q44,"")) | R44: =IFERROR(IF(P44<>"",(P44-Q44),""),"") | S44: =IFERROR(IF(OR(O44<>"",P44<>""),O44-R44,""),"") | T44: =IFERROR(S44/O44,"")
