Workbook
Name energy_offset_dropdown: IF(table_renewsummary[[#This Row],[4cat]]="Tier 1",Tier_1,IF(table_renewsummary[[#This Row],[4cat]]="Tier 2",Tier_2,Tier_3))
Name energyCategories: Input!$C$35:$C$144
Name energyTypes: Input!$D$35:$D$144
Name energyUnits: Database!$B$29:$B$37
Name IP_Units: Database!$B$21:$B$26
Name kWhUnits: Database!$C$29:$C$37
Name projectType: Input!$D$7
Name renewableGen: Input!$G$35:$G$144
Name SI_Units: Database!$C$21:$C$24
Name Tier_1: Database!$B$56:$B$57
Name Tier_2: Database!$C$56
Name Tier_3: Database!$D$56:$D$57
Name Tier1_cs: Database!$G$69:$H$73
Name Tier1_cs_min: Database!$G$69:$G$73
Name Tier1_cs_pts: Database!$H$69:$H$73
Name Tier1_nc_idc: Database!$C$69:$D$75
Name Tier1_nc_idc_min: Database!$C$69:$C$75
Name Tier1_nc_idc_pts: Database!$D$69:$D$75
Name Tier2_cs: Database!$G$74:$H$78
Name Tier2_cs_min: Database!$G$74:$G$78
Name Tier2_cs_pts: Database!$H$74:$H$78
Name Tier2_nc_idc: Database!$C$76:$D$81
Name Tier2_nc_idc_min: Database!$C$76:$C$81
Name Tier2_nc_idc_pts: Database!$D$76:$D$81
Name Tier3_cs: Database!$G$79:$H$81
Name Tier3_cs_min: Database!$G$79:$G$81
Name Tier3_cs_pts: Database!$H$79:$H$81
Name Tier3_nc_idc: Database!$C$82:$D$84
Name Tier3_nc_idc_min: Database!$C$82:$C$84
Name Tier3_nc_idc_pts: Database!$D$82:$D$84
Name unitOption: Input!$D$6
Name unitsConverter: Database!$B$29:$B$36
Name unitsTable: Database!$B$29:$C$36

Sheet Instructions
B2: LEED v5 Renewable Energy Calculator LEED for Building Design and Construction | Interior Design and Construction Instructions
C5: CREDIT INSTRUCTIONS
D7: EAc4 Renewable Energy:
D8: ▪ | E8: Included Options. Renewable energy may be supplied or procured from Tier 1 (on-site or social impact project), Tier 2 (new off-site
E9: renewable electricity), and Tier 3 (off-site renewable energy certified Green-e® or equivalent).
D10: ▪ | E10: Points Allocation. Projects earn:
F11: Building Design and Construction - New Construction (between 1–5 points): for supplying or procuring renewable energy
F12: from any combination of Tier 1,Tier 2, and Tier 3.
F13: Points are based on the percentage of annual site energy supplied by renewable sources:
F14: 1 point: 5% (Tier 1), 20% (Tier 2), or 50% (Tier 3) of annual site energy
F15: 2 points: 10% (Tier 1), 40% (Tier 2), or 100% (Tier 3)
F16: 3 points: 20% (Tier 2) or 60% (Tier 3)
F17: 4 points: 35% (Tier 2) or 80% (Tier 3)
F18: 5 points: 100% of annual site energy from Tier 1 and/or Tier 2 renewables
F19: Building Design and Construction - Core & Shell (1–4 points): for supplying or procuring renewable energy from Tier 1, Tier
F20: 2, and Tier 3.
F21: Points are based on the percentage of annual base building site energy use supplied by renewable sources:
F22: 1 point: 15% (Tier 1), 35% (Tier 2), or 100% (Tier 3) of base building energy use
... F27: calculation of project area.
D28: ▪ | E28: Platinum Prerequisite. For LEED Platinum, projects must achieve 100% of annual energy use (Building Desing and Construction
E29: and Interior Design and Construction) or 100% of annual base building energy use (Core & Shell) from Tier 1, Tier 2, and/or Tier 3
E30: renewable energy sources.
D31: ▪ | E31: Contract Requirements. All renewable energy contracts must demonstrate ownership of environmental attributes (EACs/RECs), meet
E32: a minimum 10-year term (or prorated equivalent), and comply with location and vintage requirements.
D33: ▪ | E33: Renewable Energy Readiness (Core & Shell only). Projects may earn 1 point by incorporating solar or equivalent renewable
E34: readiness features in design, including designated solar zones, structural and mounting considerations, interconnection pathways,
E35: and reserved electrical service capacity. Note: This option is not included or evaluated in the calculator inputs.
C37: Option 1. Renewable Energy Supply or Procurement
C38: (1–5 points New Construction, 1–4 points Core and Shell, 1-5 points Interior Design and Construction) Projects earn points by supplying or
C39: procuring renewable energy to offset a percentage of the building's energy use. The credit establishes a three-tier hierarchy that rewards
C40: renewable energy sources based on their direct impact.
C42: Tier 1: On-site Renewable Energy Generation or Social Impact Project
C43: This tier includes energy generated from renewable systems located on the project site, on the campus, or on the site of a qualifying social
C44: impact project.
C45: Points can be earned via two methods, and the calculator will automatically award the highest achievement:
C46: Percent of Annual Site Energy Method: Offsetting a percentage of the building’s annual energy use with on-site generation. This is the
C47: required method for earning more than two points in this tier.
C48: Minimum Rated Capacity Method: Installing a minimum renewable energy system capacity based on the building's floor area. This path is
C49: designed for multi-story buildings or projects with high process loads.
... C96: INPUT INSTRUCTIONS
...

Sheet Input
B2: LEED v5 Renewable Energy Calculator LEED for Building Design and Construction | Interior Design and Construction Inputs
B4: STEP 1: GENERAL INFORMATION
B6: Unit of Measurement System
B7: Project Type
B9: STEP 2: DISTRICT ENERGY SYSTEMS (DES)
B10: Optional for projects with district energy systems (select only one)
B12: DES Multipliers (projects with district cooling)
B13: Apply DES Multipliers to reported project site energy use?
B15: District heating energy reported as fuel(s)
B16: Provide the percentage of total reported fuel(s) associated with the district heating system (determine this value using submetering in the energy simulation). | G16: % | H16: =IF(AND($F$16>0,F$13="Yes"),"This value must be zero if 'Yes' is selected above","")
B18: STEP 3: PROJECT ANNUAL SITE ENERGY USE
B20: All rating systems | G20: Core and Shell Only
B21: Energy Type | C21: =IFERROR(VLOOKUP(projectType,Database!$D$11:$E$13,2,FALSE),Database!$E$11) -> Annual site energy | D21: Units | E21: =CONCATENATE(C21," (kWh)") -> Annual site energy (kWh) | F21: =CONCATENATE(IF(projectType="BD+C: Core and Shell",$J$21,CONCATENATE($C21," (kWh)","")), " with DES adjustments") -> Annual site energy (kWh) with DES adjustments | G21: Base building metered site energy | H21: Units | I21: Base building metered site energy (kWh) | J21: Annual base building site energy (kWh)
B22: Electricity | E22: =IFERROR($C22*VLOOKUP($D22,unitsTable, 2, FALSE),0) -> 0 | F22: =IF(projectType="BD+C: Core and Shell",$J22,$E22) -> 0 | H22: =IF(G22="","",D22) | I22: =IFERROR($G22 * VLOOKUP($D22,unitsTable, 2, FALSE),0) -> 0 | J22: =IF(projectType="BD+C: Core and Shell",IF($I$27>0.25*E$27,I22,E22*0.25),0) -> 0
B23: Fuel(s) | E23: =IFERROR($C23*VLOOKUP($D23,unitsTable, 2, FALSE),0) -> 0 | F23: =IF(projectType="BD+C: Core and Shell",$J23,$E23)*IF(F16>0,100%-F16/100,1) -> 0 | H23: =IF(G23="","",D23) | I23: =IFERROR($G23 * VLOOKUP($D23,unitsTable, 2, FALSE),0) -> 0 | J23: =IF(projectType="BD+C: Core and Shell",IF($I$27>0.25*E$27,I23,E23*0.25),0) -> 0
B24: District cooling | E24: =IFERROR($C24*VLOOKUP($D24,unitsTable, 2, FALSE),0) -> 0 | F24: =IF(projectType="BD+C: Core and Shell",$J24,$E24)*IF($F$13="Yes",0.325,1) -> 0 | H24: =IF(G24="","",D24) | I24: =IFERROR($G24 * VLOOKUP($D24,unitsTable, 2, FALSE),0) -> 0 | J24: =IF(projectType="BD+C: Core and Shell",IF($I$27>0.25*E$27,I24,E24*0.25),0) -> 0
B25: District heating | E25: =IFERROR($C25*VLOOKUP($D25,unitsTable, 2, FALSE),0) -> 0 | F25: =IF(projectType="BD+C: Core and Shell",$J25,$E25)*IF(F16>0,F16/100,IF(F13="Yes",1.2,1)) -> 0 | H25: =IF(G25="","",D25) | I25: =IFERROR($G25 * VLOOKUP($D25,unitsTable, 2, FALSE),0) -> 0 | J25: =IF(projectType="BD+C: Core and Shell",IF($I$27>0.25*E$27,I25,E25*0.25),0) -> 0
B27: Total (kWh) | E27: =(SUM(E$22:E$25)) -> 0 | F27: =(SUM(F$22:F$25)) -> 0 | I27: =(SUM(I$22:I$25)) -> 0 | J27: =(SUM(J$22:J$25)) -> 0
B28: Subtotal: Electricity + District Energy (kWh) | E28: =E22+E24+E25 -> 0 | F28: =F22+F24+F25 -> 0 | I28: =I22+I24+I25 -> 0 | J28: =J22+J24+J25 -> 0
B29: Subtotal: Fuel(s) + District Heating | E29: =E23+E25 -> 0 | F29: =F23+F25 -> 0 | I29: =I23+I25 -> 0 | J29: =J23+J25 -> 0
B31: STEP 4: RENEWABLE ENERGY GENERATION SUMMARY
B33: Name | C33: Renewable Energy Category | D33: Energy Offset Type | E33: Annual Renewable Generation | F33: Units of Energy | G33: Annual Renewable Generation (kWh) | H33: Percent of annual project electricity + district energy | I33: Percent of annual project fuel(s) + district heating + other | J33: =CONCATENATE("Percent of ",IF(projectType="BD+C: Core and Shell",Database!$G$12,Input!$C$21)) -> Percent of Annual site energy
B34: 4name | C34: 4cat | D34: 4offset | E34: 4qty | F34: 4units | G34: 4qty_calc | H34: 4per_elec | I34: 4per_fuel | J34: 4per_site | K34: Column1 | L34: Column2
A35: 1 | G35: =IFERROR(table_renewsummary[[#This Row],[4qty]]*INDEX(unitsTable,MATCH(table_renewsummary[[#This Row],[4units]],INDEX(unitsTable,0,1),0),2),0) -> 0 | H35: =IFERROR(IF(table_renewsummary[[#This Row],[4offset]]="Electricity",(table_renewsummary[[#This Row],[4qty_calc]]/(IF(projectType="BD+C:Core and Shell",$E$28,$F$28))),0),0) -> 0 | I35: =IFERROR(IF(table_renewsummary[[#This Row],[4offset]]="Fuel(s)",(table_renewsummary[[#This Row],[4qty_calc]]/(IF(projectType="BD+C:Core and Shell",$E$29,$F$29))),0),0) -> 0 | J35: =IFERROR(table_renewsummary[[#This Row],[4qty_calc]]/$F$27,0) -> 0
A36: 2 | G36: =IFERROR(table_renewsummary[[#This Row],[4qty]]*INDEX(unitsTable,MATCH(table_renewsummary[[#This Row],[4units]],INDEX(unitsTable,0,1),0),2),0) -> 0 | H36: =IFERROR(IF(table_renewsummary[[#This Row],[4offset]]="Electricity",(table_renewsummary[[#This Row],[4qty_calc]]/(IF(projectType="BD+C:Core and Shell",$E$28,$F$28))),0),0) -> 0 | I36: =IFERROR(IF(table_renewsummary[[#This Row],[4offset]]="Fuel(s)",(table_renewsummary[[#This Row],[4qty_calc]]/(IF(projectType="BD+C:Core and Shell",$E$29,$F$29))),0),0) -> 0 | J36: =IFERROR(table_renewsummary[[#This Row],[4qty_calc]]/$F$27,0) -> 0
A37: 3 | G37: =IFERROR(table_renewsummary[[#This Row],[4qty]]*INDEX(unitsTable,MATCH(table_renewsummary[[#This Row],[4units]],INDEX(unitsTable,0,1),0),2),0) -> 0 | H37: =IFERROR(IF(table_renewsummary[[#This Row],[4offset]]="Electricity",(table_renewsummary[[#This Row],[4qty_calc]]/(IF(projectType="BD+C:Core and Shell",$E$28,$F$28))),0),0) -> 0 | I37: =IFERROR(IF(table_renewsummary[[#This Row],[4offset]]="Fuel(s)",(table_renewsummary[[#This Row],[4qty_calc]]/(IF(projectType="BD+C:Core and Shell",$E$29,$F$29))),0),0) -> 0 | J37: =IFERROR(table_renewsummary[[#This Row],[4qty_calc]]/$F$27,0) -> 0
A38: 4 | G38: =IFERROR(table_renewsummary[[#This Row],[4qty]]*INDEX(unitsTable,MATCH(table_renewsummary[[#This Row],[4units]],INDEX(unitsTable,0,1),0),2),0) -> 0 | H38: =IFERROR(IF(table_renewsummary[[#This Row],[4offset]]="Electricity",(table_renewsummary[[#This Row],[4qty_calc]]/(IF(projectType="BD+C:Core and Shell",$E$28,$F$28))),0),0) -> 0 | I38: =IFERROR(IF(table_renewsummary[[#This Row],[4offset]]="Fuel(s)",(table_renewsummary[[#This Row],[4qty_calc]]/(IF(projectType="BD+C:Core and Shell",$E$29,$F$29))),0),0) -> 0 | J38: =IFERROR(table_renewsummary[[#This Row],[4qty_calc]]/$F$27,0) -> 0
A39: 5 | G39: =IFERROR(table_renewsummary[[#This Row],[4qty]]*INDEX(unitsTable,MATCH(table_renewsummary[[#This Row],[4units]],INDEX(unitsTable,0,1),0),2),0) -> 0 | H39: =IFERROR(IF(table_renewsummary[[#This Row],[4offset]]="Electricity",(table_renewsummary[[#This Row],[4qty_calc]]/(IF(projectType="BD+C:Core and Shell",$E$28,$F$28))),0),0) -> 0 | I39: =IFERROR(IF(table_renewsummary[[#This Row],[4offset]]="Fuel(s)",(table_renewsummary[[#This Row],[4qty_calc]]/(IF(projectType="BD+C:Core and Shell",$E$29,$F$29))),0),0) -> 0 | J39: =IFERROR(table_renewsummary[[#This Row],[4qty_calc]]/$F$27,0) -> 0
A40: 6 | G40: =IFERROR(table_renewsummary[[#This Row],[4qty]]*INDEX(unitsTable,MATCH(table_renewsummary[[#This Row],[4units]],INDEX(unitsTable,0,1),0),2),0) -> 0 | H40: =IFERROR(IF(table_renewsummary[[#This Row],[4offset]]="Electricity",(table_renewsummary[[#This Row],[4qty_calc]]/(IF(projectType="BD+C:Core and Shell",$E$28,$F$28))),0),0) -> 0 | I40: =IFERROR(IF(table_renewsummary[[#This Row],[4offset]]="Fuel(s)",(table_renewsummary[[#This Row],[4qty_calc]]/(IF(projectType="BD+C:Core and Shell",$E$29,$F$29))),0),0) -> 0 | J40: =IFERROR(table_renewsummary[[#This Row],[4qty_calc]]/$F$27,0) -> 0
A41: 7 | G41: =IFERROR(table_renewsummary[[#This Row],[4qty]]*INDEX(unitsTable,MATCH(table_renewsummary[[#This Row],[4units]],INDEX(unitsTable,0,1),0),2),0) -> 0 | H41: =IFERROR(IF(table_renewsummary[[#This Row],[4offset]]="Electricity",(table_renewsummary[[#This Row],[4qty_calc]]/(IF(projectType="BD+C:Core and Shell",$E$28,$F$28))),0),0) -> 0 | I41: =IFERROR(IF(table_renewsummary[[#This Row],[4offset]]="Fuel(s)",(table_renewsummary[[#This Row],[4qty_calc]]/(IF(projectType="BD+C:Core and Shell",$E$29,$F$29))),0),0) -> 0 | J41: =IFERROR(table_renewsummary[[#This Row],[4qty_calc]]/$F$27,0) -> 0
A42: 8 | G42: =IFERROR(table_renewsummary[[#This Row],[4qty]]*INDEX(unitsTable,MATCH(table_renewsummary[[#This Row],[4units]],INDEX(unitsTable,0,1),0),2),0) -> 0 | H42: =IFERROR(IF(table_renewsummary[[#This Row],[4offset]]="Electricity",(table_renewsummary[[#This Row],[4qty_calc]]/(IF(projectType="BD+C:Core and Shell",$E$28,$F$28))),0),0) -> 0 | I42: =IFERROR(IF(table_renewsummary[[#This Row],[4offset]]="Fuel(s)",(table_renewsummary[[#This Row],[4qty_calc]]/(IF(projectType="BD+C:Core and Shell",$E$29,$F$29))),0),0) -> 0 | J42: =IFERROR(table_renewsummary[[#This Row],[4qty_calc]]/$F$27,0) -> 0
A43: 9 | G43: =IFERROR(table_renewsummary[[#This Row],[4qty]]*INDEX(unitsTable,MATCH(table_renewsummary[[#This Row],[4units]],INDEX(unitsTable,0,1),0),2),0) -> 0 | H43: =IFERROR(IF(table_renewsummary[[#This Row],[4offset]]="Electricity",(table_renewsummary[[#This Row],[4qty_calc]]/(IF(projectType="BD+C:Core and Shell",$E$28,$F$28))),0),0) -> 0 | I43: =IFERROR(IF(table_renewsummary[[#This Row],[4offset]]="Fuel(s)",(table_renewsummary[[#This Row],[4qty_calc]]/(IF(projectType="BD+C:Core and Shell",$E$29,$F$29))),0),0) -> 0 | J43: =IFERROR(table_renewsummary[[#This Row],[4qty_calc]]/$F$27,0) -> 0
A44: 10 | G44: =IFERROR(table_renewsummary[[#This Row],[4qty]]*INDEX(unitsTable,MATCH(table_renewsummary[[#This Row],[4units]],INDEX(unitsTable,0,1),0),2),0) -> 0 | H44: =IFERROR(IF(table_renewsummary[[#This Row],[4offset]]="Electricity",(table_renewsummary[[#This Row],[4qty_calc]]/(IF(projectType="BD+C:Core and Shell",$E$28,$F$28))),0),0) -> 0 | I44: =IFERROR(IF(table_renewsummary[[#This Row],[4offset]]="Fuel(s)",(table_renewsummary[[#This Row],[4qty_calc]]/(IF(projectType="BD+C:Core and Shell",$E$29,$F$29))),0),0) -> 0 | J44: =IFERROR(table_renewsummary[[#This Row],[4qty_calc]]/$F$27,0) -> 0
A45: 11 | G45: =IFERROR(table_renewsummary[[#This Row],[4qty]]*INDEX(unitsTable,MATCH(table_renewsummary[[#This Row],[4units]],INDEX(unitsTable,0,1),0),2),0) -> 0 | H45: =IFERROR(IF(table_renewsummary[[#This Row],[4offset]]="Electricity",(table_renewsummary[[#This Row],[4qty_calc]]/(IF(projectType="BD+C:Core and Shell",$E$28,$F$28))),0),0) -> 0 | I45: =IFERROR(IF(table_renewsummary[[#This Row],[4offset]]="Fuel(s)",(table_renewsummary[[#This Row],[4qty_calc]]/(IF(projectType="BD+C:Core and Shell",$E$29,$F$29))),0),0) -> 0 | J45: =IFERROR(table_renewsummary[[#This Row],[4qty_calc]]/$F$27,0) -> 0
A46: 12 | G46: =IFERROR(table_renewsummary[[#This Row],[4qty]]*INDEX(unitsTable,MATCH(table_renewsummary[[#This Row],[4units]],INDEX(unitsTable,0,1),0),2),0) -> 0 | H46: =IFERROR(IF(table_renewsummary[[#This Row],[4offset]]="Electricity",(table_renewsummary[[#This Row],[4qty_calc]]/(IF(projectType="BD+C:Core and Shell",$E$28,$F$28))),0),0) -> 0 | I46: =IFERROR(IF(table_renewsummary[[#This Row],[4offset]]="Fuel(s)",(table_renewsummary[[#This Row],[4qty_calc]]/(IF(projectType="BD+C:Core and Shell",$E$29,$F$29))),0),0) -> 0 | J46: =IFERROR(table_renewsummary[[#This Row],[4qty_calc]]/$F$27,0) -> 0
... A83: 49 | G83: =IFERROR(table_renewsummary[[#This Row],[4qty]]*INDEX(unitsTable,MATCH(table_renewsummary[[#This Row],[4units]],INDEX(unitsTable,0,1),0),2),0) -> 0 | H83: =IFERROR(IF(table_renewsummary[[#This Row],[4offset]]="Electricity",(table_renewsummary[[#This Row],[4qty_calc]]/(IF(projectType="BD+C:Core and Shell",$E$28,$F$28))),0),0) -> 0 | I83: =IFERROR(IF(table_renewsummary[[#This Row],[4offset]]="Fuel(s)",(table_renewsummary[[#This Row],[4qty_calc]]/(IF(projectType="BD+C:Core and Shell",$E$29,$F$29))),0),0) -> 0 | J83: =IFERROR(table_renewsummary[[#This Row],[4qty_calc]]/$F$27,0) -> 0
A84: 50 | G84: =IFERROR(table_renewsummary[[#This Row],[4qty]]*INDEX(unitsTable,MATCH(table_renewsummary[[#This Row],[4units]],INDEX(unitsTable,0,1),0),2),0) -> 0 | H84: =IFERROR(IF(table_renewsummary[[#This Row],[4offset]]="Electricity",(table_renewsummary[[#This Row],[4qty_calc]]/(IF(projectType="BD+C:Core and Shell",$E$28,$F$28))),0),0) -> 0 | I84: =IFERROR(IF(table_renewsummary[[#This Row],[4offset]]="Fuel(s)",(table_renewsummary[[#This Row],[4qty_calc]]/(IF(projectType="BD+C:Core and Shell",$E$29,$F$29))),0),0) -> 0 | J84: =IFERROR(table_renewsummary[[#This Row],[4qty_calc]]/$F$27,0) -> 0 | K84: Click + to left for additional rows
A85: 51 | G85: =IFERROR(table_renewsummary[[#This Row],[4qty]]*INDEX(unitsTable,MATCH(table_renewsummary[[#This Row],[4units]],INDEX(unitsTable,0,1),0),2),0) -> 0 | H85: =IFERROR(IF(table_renewsummary[[#This Row],[4offset]]="Electricity",(table_renewsummary[[#This Row],[4qty_calc]]/(IF(projectType="BD+C:Core and Shell",$E$28,$F$28))),0),0) -> 0 | I85: =IFERROR(IF(table_renewsummary[[#This Row],[4offset]]="Fuel(s)",(table_renewsummary[[#This Row],[4qty_calc]]/(IF(projectType="BD+C:Core and Shell",$E$29,$F$29))),0),0) -> 0 | J85: =IFERROR(table_renewsummary[[#This Row],[4qty_calc]]/$F$27,0) -> 0
A86: 52 | G86: =IFERROR(table_renewsummary[[#This Row],[4qty]]*INDEX(unitsTable,MATCH(table_renewsummary[[#This Row],[4units]],INDEX(unitsTable,0,1),0),2),0) -> 0 | H86: =IFERROR(IF(table_renewsummary[[#This Row],[4offset]]="Electricity",(table_renewsummary[[#This Row],[4qty_calc]]/(IF(projectType="BD+C:Core and Shell",$E$28,$F$28))),0),0) -> 0 | I86: =IFERROR(IF(table_renewsummary[[#This Row],[4offset]]="Fuel(s)",(table_renewsummary[[#This Row],[4qty_calc]]/(IF(projectType="BD+C:Core and Shell",$E$29,$F$29))),0),0) -> 0 | J86: =IFERROR(table_renewsummary[[#This Row],[4qty_calc]]/$F$27,0) -> 0
A87: 53 | G87: =IFERROR(table_renewsummary[[#This Row],[4qty]]*INDEX(unitsTable,MATCH(table_renewsummary[[#This Row],[4units]],INDEX(unitsTable,0,1),0),2),0) -> 0 | H87: =IFERROR(IF(table_renewsummary[[#This Row],[4offset]]="Electricity",(table_renewsummary[[#This Row],[4qty_calc]]/(IF(projectType="BD+C:Core and Shell",$E$28,$F$28))),0),0) -> 0 | I87: =IFERROR(IF(table_renewsummary[[#This Row],[4offset]]="Fuel(s)",(table_renewsummary[[#This Row],[4qty_calc]]/(IF(projectType="BD+C:Core and Shell",$E$29,$F$29))),0),0) -> 0 | J87: =IFERROR(table_renewsummary[[#This Row],[4qty_calc]]/$F$27,0) -> 0
...

Sheet Database
B2: USGBC Calculator || LEED for Building Operations and Maintenance & Interior Design and Construction LEED v5 EAc4: Renewable Energy Database
B4: GENERAL INFORMATION
B6: Unit systems | C6: Options | D6: Select | E6: Area | F6: Energy
D7: SI Units | E7: m2 | F7: W/m2
D8: IP Units | E8: ft2 | F8: W/ft2
B10: Project type | C10: Options | D10: Select | E10: Name of Energy Field
D11: BD+C: New Construction | E11: Annual site energy
D12: BD+C: Core and Shell | E12: Total annual building site energy | F12: Base building metered site energy | G12: Annual base building site energy
D13: ID+C: Interior Design and Construction | E13: Tenant annual site energy
B17: PROJECT SITE ENERGY USE
B20: IP_Units | C20: SI_Units
B21: kBtu | C21: GJ
B22: therms | C22: MJ
B23: MMBtu | C23: kWh
B24: ton Hours | C24: MWh
B25: kWh
B26: MWh
B28: Energy Consumption Units | C28: convert to kWh | D28: Source
B29: GJ | C29: 277.77778 | D29: EPA, 2025. Thermal Energy Conversions. ENERGY STAR Portfolio Manager.
B30: MJ | C30: 0.27777778 | D30: EPA, 2025. Thermal Energy Conversions. ENERGY STAR Portfolio Manager.
B31: kWh | C31: 1 | D31: EPA, 2025. Thermal Energy Conversions. ENERGY STAR Portfolio Manager.
B32: MWh | C32: 1000 | D32: EPA, 2025. Thermal Energy Conversions. ENERGY STAR Portfolio Manager.
B33: kBtu | C33: 0.29308324 | D33: EPA, 2025. Thermal Energy Conversions. ENERGY STAR Portfolio Manager.
B34: therms | C34: 29.308324 | D34: EPA, 2025. Thermal Energy Conversions. ENERGY STAR Portfolio Manager.
B35: MMBtu | C35: 293.08324 | D35: EPA, 2025. Thermal Energy Conversions. ENERGY STAR Portfolio Manager.
B36: ton Hours | C36: 3.5169988 | D36: EPA, 2025. Thermal Energy Conversions. ENERGY STAR Portfolio Manager.
B37: Select
B39: Offset Energy type
B40: Electricity
B41: Fuel(s)
B42: Other
B45: RENEWABLE ENERGY GENERATION
B47: LEED Renewable Category
B48: Tier 1 | C48: 1
B49: Tier 2 | C49: 2
B50: Tier 3 | C50: 3
B51: Select
B54: Tier 1 On-site renewable sources | C54: Tier 2 Renewable Electricity Generation Sources | D54: Tier 3 Renewable Generation Sources | F54: Energy Generation Type
B55: Select | C55: Select | D55: Select | F55: Select
B56: Electricity | C56: Electricity | D56: Electricity | F56: Electricity
...

Sheet Summary
B2: LEED v5 Renewable Energy Calculator LEED for Building Design and Construction | Interior Design and Construction Summary
C5: EA CREDIT RENEWABLE ENERGY
C8: Project Type | D8: =projectType -> 0
C10: Renewable energy summary
C12: Tier 1 renewable capacity per unit area for the three largest floors | D12: =Input!F164 -> 0 | F12: =Input!G164 | H12: =IF(Input!$C$170<Input!$E$170,Input!$E$170,"Not applicable") -> Not applicable | I12: Points
C13: (if applicable)
D15: Annual renewable generation (kWh) | F15: Qualifying Percent of Total Annual Site Energy
C17: Tier 1: On-site renewable energy percent of annual project site energy use | D17: =Input!$G$146 -> 0 | F17: =Input!$J$146 -> 0 | H17: =IF(Input!$C$170<Input!$E$170,"Not applicable",Input!C170) -> 0 | I17: Points
C19: Tier 2. New Off-site renewable electricity percent of annual project site energy use | D19: =Input!$G$147 -> 0 | F19: =Input!$J$147 -> 0 | H19: =Input!C171 -> 0 | I19: Points
C21: Tier 3. Off-site renewable percent of annual project site energy use | D21: =Input!$G$148 -> 0 | F21: =Input!$J$148 -> 0 | H21: =Input!C172 -> 0 | I21: Points
C23: Total (Tier 1 + Tier 2 + Tier 3) | D23: =Input!$G$145 -> 0 | F23: =Input!$J$149 -> 0
C25: Points: | H25: =MIN( IF($D$8="BD+C: Core and Shell", 4, 5), ROUNDDOWN( IF($H$17="Not applicable", $H$12, $H$17) + $H$19 + $H$21, 0 ) ) -> 0 | I25: Points
C26: Calculations refer to the method leading to highest points achievement for Tier 1, and round down to the nearest whole number, up to the maximum available points.
C28: Meets renewable energy thresholds for LEED Platinum eligibility | H28: =IF(Input!$J$149>=1,"Yes","No") -> No
C29: (100% Tier 1 + Tier 2 + Tier 3)
